Workbook

Sheet Burnham Totals
B2: Burnham Internal Project Costs
B4: Burnham Project Management Costs
B5: Capital Team Site Personnel | C5: =SUM('Burnham Project Mgmt Costs-1'!F5:F19) -> 913996.05
B6: RDU/DC Mgmt Expenses | C6: =SUM('Burnham Project Mgmt Costs-1'!F21:F37) -> 187950
B7: Temporary Construction Facilities | C7: ='Burnham Project Mgmt Costs-2'!F20 -> 130730
B8: 3rd Party Engineering Support | C8: ='Burnham Project Mgmt Costs-2'!F33 -> 45000
B9: Construction PPE / First Aid | C9: ='Burnham Project Mgmt Costs-2'!F42 -> 25450
B10: Legal Support | C10: ='Burnham Project Mgmt Costs-2'!F48 -> 60000
B12: Operations During Construction
B13: Operations Staff pre-COD | C13: =SUM('Operations During Construction'!F4:F11) -> 215997.6
B14: Operational Adjustments to site | C14: ='Operations During Construction'!F22 -> 100000
B15: Operations Handtools / devices | C15: ='Operations During Construction'!F20 -> 17500
B16: Gas Sampling for Gas Quality | C16: ='Operations During Construction'!F31 -> 92250
B18: Insurance
B19: Builder's Risk Policy | D19: MULTIPLIER
B21: Fixtures and Furnishings
B22: Permanent Office Furnishings | C22: ='Fixtures and Furnishings'!F15 -> 247150
B24: Spare Parts
B25: Spare Parts | C25: ='Spare Parts breakdown'!E12 -> 653551.9
B27: Utilities
B28: Temp Power | C28: 5000
B29: Permanent | C29: 160000
B30: Nat. Gas | C30: 0
B31: Water | C31: 0
B32: Sewer | C32: 0
B33: IT | C33: 2500
B34: Utilities During Construction | C34: =Utility!F20 -> 77601.88
B36: Ribbon Cutting | C36: 75000
B38: Subtotal | C38: =SUM(C5:C37) -> 3009677.4

Sheet Burnham Project Mgmt Costs-1
B2: Persimmons Burnham Owners Cost Management | E2: 18 | F2: Construction Months
B4: Construction Personnel | C4: Rate | D4: UOM | E4: QTY | F4: Total | G4: Needs update?
B5: C-PM | C5: =72.12*1.55 -> 111.786 | D5: HR | E5: =((E2*4.33)*40) -> 3117.6 | F5: =C5*E5 -> 348504.03 | G5: Yes | H5: Need to confirm burdened rate
B6: C-PM Rental Car | C6: 3500 | D6: MO | E6: =$E$2 -> 18 | F6: =C6*E6 -> 63000 | G6: No
B7: C-PM Hotel | C7: 4000 | D7: MO | E7: =$E$2 -> 18 | F7: =C7*E7 -> 72000 | G7: No
B8: C-PM Flight | C8: 850 | D8: MO | E8: =$E$2 -> 18 | F8: =C8*E8 -> 15300 | G8: No
B9: C-PM Incidental | C9: =68*30 -> 2040 | D9: MO | E9: =$E$2 -> 18 | F9: =C9*E9 -> 36720 | G9: No
B10: C-PM Fuel | C10: 200 | D10: MO | E10: =$E$2 -> 18 | F10: =C10*E10 -> 3600 | G10: No
B11: C-PM Training | C11: 2500 | D11: LS | E11: 2 | F11: =C11*E11 -> 5000 | G11: No
B13: C-PE | C13: =48.08*1.55 -> 74.524 | D13: HR | E13: =((E2*0.75*4.33)*40) -> 2338.2 | F13: =C13*E13 -> 174252.02 | G13: Yes | H13: Need to confirm burdened rate
B14: C-PE Rental Car | C14: 3500 | D14: MO | E14: =$E$2 -> 18 | F14: =C14*E14 -> 63000 | G14: No
B15: C-PE Hotel | C15: 4000 | D15: MO | E15: =$E$2 -> 18 | F15: =C15*E15 -> 72000 | G15: No
B16: C-PE Flight | C16: 850 | D16: MO | E16: =$E$2 -> 18 | F16: =C16*E16 -> 15300 | G16: No
B17: C-PE Incidental | C17: =68*30 -> 2040 | D17: MO | E17: =$E$2 -> 18 | F17: =C17*E17 -> 36720 | G17: No
B18: C-PE Fuel | C18: 200 | D18: MO | E18: =$E$2 -> 18 | F18: =C18*E18 -> 3600 | G18: No
B19: C-PM Training | C19: 2500 | D19: LS | E19: 2 | F19: =C19*E19 -> 5000 | G19: No
B21: CP Team Flights | C21: 850 | D21: EA | E21: =E2*(2+0.5+0.5) -> 54 | F21: =C21*E21 -> 45900 | G21: No | H21: Should be part of Burnham Mgmt fee?
B22: CP Team Hotel | C22: 200 | D22: Day | E22: =E21*3 -> 162 | F22: =C22*E22 -> 32400 | G22: No | H22: Should be part of Burnham Mgmt fee?
B23: CP Team Rental Car | C23: 75 | D23: Day | E23: =E22 -> 162 | F23: =C23*E23 -> 12150 | G23: No | H23: Should be part of Burnham Mgmt fee?
B24: CP Team M&IE | C24: 68 | D24: Day | E24: =E22 -> 162 | F24: =C24*E24 -> 11016 | G24: No | H24: Should be part of Burnham Mgmt fee?
B25: CP Team Fuel | C25: 20 | D25: Day | E25: =E22 -> 162 | F25: =C25*E25 -> 3240 | G25: No | H25: Should be part of Burnham Mgmt fee?
B27: ENG Team Flights | C27: 850 | D27: EA | E27: =15*2 -> 30 | F27: =C27*E27 -> 25500 | G27: No | H27: Should be part of Burnham Mgmt fee?
B28: ENG Team Hotel | C28: 200 | D28: Day | E28: =E27*4 -> 120 | F28: =C28*E28 -> 24000 | G28: No | H28: Should be part of Burnham Mgmt fee?
B29: ENG Team Rental Car | C29: 75 | D29: Day | E29: =E28 -> 120 | F29: =C29*E29 -> 9000 | G29: No | H29: Should be part of Burnham Mgmt fee?
B30: ENG Team M&IE | C30: 68 | D30: Day | E30: =E28 -> 120 | F30: =C30*E30 -> 8160 | G30: No | H30: Should be part of Burnham Mgmt fee?
B31: ENG Team Fuel | C31: 20 | D31: Day | E31: =E28 -> 120 | F31: =C31*E31 -> 2400 | G31: No | H31: Should be part of Burnham Mgmt fee?
B33: DC Team Flights | C33: 850 | D33: EA | E33: =E2/2 -> 9 | F33: =C33*E33 -> 7650 | G33: No | H33: Should be part of Burnham Mgmt fee?
B34: DC Team Hotel | C34: 200 | D34: Day | E34: =E33*2 -> 18 | F34: =C34*E34 -> 3600 | G34: No | H34: Should be part of Burnham Mgmt fee?
B35: DC Team Rental Car | C35: 75 | D35: Day | E35: =E34 -> 18 | F35: =C35*E35 -> 1350 | G35: No | H35: Should be part of Burnham Mgmt fee?
B36: DC Team M&IE | C36: 68 | D36: Day | E36: =E34 -> 18 | F36: =C36*E36 -> 1224 | G36: No | H36: Should be part of Burnham Mgmt fee?
B37: DC Team Fuel | C37: 20 | D37: Day | E37: =E34 -> 18 | F37: =C37*E37 -> 360 | G37: No | H37: Should be part of Burnham Mgmt fee?
B43: Subtotal | F43: =SUM(F5:F42) -> 1101946.1

Sheet Burnham Project Mgmt Costs-2
B2: Persimmons Burnham Owners Cost Management | E2: ='Burnham Project Mgmt Costs-1'!E2 -> 18
B4: Description | C4: Rate | D4: UOM | E4: QTY | F4: Total | G4: Needs update?
B5: Construction Office
B6: Construction Office Trailer | C6: 2600 | D6: MO | E6: =E2 -> 18 | F6: =C6*E6 -> 46800 | G6: No | H6: Office trailer rental
B7: Construction Office Furnishing | C7: 10000 | D7: LS | E7: 1 | F7: =C7*E7 -> 10000 | G7: No | H7: Chairs/tables/fridge
B8: Construction Office Supplies | C8: 60 | D8: MO | E8: =E2 -> 18 | F8: =C8*E8 -> 1080 | G8: No | H8: Monitors/paper/pens
B9: Construction Printer | C9: 400 | D9: LS | E9: 1 | F9: =C9*E9 -> 400 | G9: No | H9: 11x17 printer
B10: Construction Internet | C10: 100 | D10: MO | E10: =E2 -> 18 | F10: =C10*E10 -> 1800 | G10: No | H10: Remote internet
B11: Construction IT Supplies | C11: 2500 | D11: LS | E11: 1 | F11: =C11*E11 -> 2500 | G11: No | H11: Modems etc
B12: Project Drawing Sets | C12: 2000 | D12: LS | E12: 2 | F12: =C12*E12 -> 4000 | G12: No
B13: Construction Software Licenses | C13: 5000 | D13: LS | E13: 2 | F13: =C13*E13 -> 10000 | G13: No | H13: P3, Bluebeam
B14: Storage Container | C14: 500 | D14: Mo | E14: 12 | F14: =C14*E14 -> 6000 | G14: No
B15: Construction Water/tea/coffee | C15: 50 | D15: MO | E15: =E2 -> 18 | F15: =C15*E15 -> 900 | G15: No | H15: Water/coffee/tea for office
B16: Multivista | C16: 3500 | D16: Mo | E16: =E2*0.75 -> 13.5 | F16: =C16*E16 -> 47250 | G16: No
F17: =C17*E17 -> 0 | G17: No
F18: =C18*E18 -> 0 | G18: No
F19: =C19*E19 -> 0 | G19: No
B20: Construction Office Subtotal | F20: =SUM(F6:F19) -> 130730
B21: Engineering Post FID
B22: BOP Engineering Design | C22: 0 | D22: LS | E22: 1 | F22: =C22*E22 -> 0 | H22: Carried elsewhere
B23: BOP Engineering Construction Admin | C23: 94264 | D23: LS | E23: 0 | F23: =C23*E23*1.2 -> 0 | G23: No | H23: inc.20% for anticipated changes
B24: Vendor Engineering (Misc) | C24: 10000 | D24: LS | E24: 1 | F24: =C24*E24 -> 10000 | G24: No | H24: Burnham Equipment Vendor - Additional Design
B25: Geotechnical Engineering Construction Admin | C25: 35000 | D25: LS | E25: 0 | F25: =C25*E25 -> 0 | G25: No
B26: Environmental Permitting Support | C26: 15000 | D26: LS | E26: 1 | F26: =C26*E26 -> 15000 | G26: Yes | H26: Air Permit in Buisness Development Fees
B27: Misc Permit Fees | C27: 25000 | D27: LS | E27: 0 | F27: =C27*E27 -> 0 | G27: Yes
B28: Surveying | C28: 10000 | D28: LS | E28: 2 | F28: =C28*E28 -> 20000 | G28: No
B29: Engineering Commissioning | C29: 45000 | D29: LS | E29: 0 | F29: =C29*E29 -> 0 | G29: No
B30: Lagoon / Liner QC Inspector | C30: 75000 | D30: LS | E30: 0 | F30: =C30*E30 -> 0 | G30: No
F31: =C31*E31 -> 0 | G31: No
F32: =C32*E32 -> 0 | G32: No
B33: Engineering Post FID Subtotal | F33: =SUM(F21:F32) -> 45000
B34: First Aid / PPE
B35: Construction First Aid Kit/AED | C35: 650 | D35: LS | E35: 1 | F35: =C35*E35 -> 650 | G35: No | H35: First aid kit and aed
B36: PPE | C36: 100 | D36: MO | E36: =E2 -> 18 | F36: =C36*E36 -> 1800 | G36: No | H36: Hard Hat, glasses, ear protection, H2S monitors
B37: Site Signage | C37: 2000 | D37: LS | E37: 1 | F37: =C37*E37 -> 2000 | G37: No | H37: Signage for around site
B38: Saftety Training | C38: 500 | D38: LS | E38: 2 | F38: =C38*E38 -> 1000 | G38: Yes
B39: Safety Incentive / Safety Apprectiation | C39: 10000 | D39: LS | E39: 2 | F39: =C39*E39 -> 20000 | G39: Yes
F40: =C40*E40 -> 0 | G40: Yes
F41: =C41*E41 -> 0 | G41: Yes
B42: First Aid / PPE Subtotal | F42: =SUM(F34:F41) -> 25450
...

Sheet Operations During Construction
B2: Description | C2: Rate | D2: UOM | E2: QTY | F2: Total
B3: Ops During Construction
B4: Operator A | C4: 72.12 | D4: HR | E4: =2080/2 -> 1040 | F4: =E4*C4 -> 75004.8
B5: Operator B | C5: 72.12 | D5: HR | E5: =2080/3 -> 693.33333 | F5: =E5*C5 -> 50003.2
B6: Operations Director/Manager | C6: 144.23 | D6: HR | E6: =2080/4 -> 520 | F6: =E6*C6 -> 74999.6
B7: Ops Flights | C7: 850 | D7: EA | E7: 6 | F7: =E7*C7 -> 5100
B8: Ops Hotel | C8: 200 | D8: Day | E8: =5*6 -> 30 | F8: =E8*C8 -> 6000
B9: Ops Rental Car | C9: 75 | D9: Day | E9: 30 | F9: =E9*C9 -> 2250
B10: Ops M&IE | C10: 68 | D10: Day | E10: 30 | F10: =E10*C10 -> 2040
B11: Ops Fuel | C11: 20 | D11: Day | E11: 30 | F11: =E11*C11 -> 600
B13: Ops During Construction Personnel Subtotal | F13: =SUM(F1:F12) -> 215997.6
B14: Ops During Construction Tools
B15: Ops equipment | C15: 7500 | D15: LS | E15: 1 | F15: =C15*E15 -> 7500 | G15: Hand held gas analyzer, Fluke equipment
B16: Ops Hand tools | C16: 10000 | D16: LS | E16: 1 | F16: =C16*E16 -> 10000 | G16: Tool sets for maintenance
C17: 0 | D17: LS | E17: 1 | F17: =C17*E17 -> 0
C18: 0 | D18: LS | E18: 1 | F18: =C18*E18 -> 0
B20: Ops During Construction Tools Subtotal | F20: =SUM(F14:F19) -> 17500
B21: Ops Plant Adjustments
B22: Ops plant adjustments | C22: 50000 | D22: LS | E22: 2 | F22: =C22*E22 -> 100000 | G22: Misc. infrastructure requests by Ops
C23: 0 | D23: LS | E23: 1 | F23: =C23*E23 -> 0
C24: 0 | D24: LS | E24: 1 | F24: =C24*E24 -> 0
B25: Ops Plant Adjustments | F25: =SUM(F22:F24) -> 100000
B26: Pre-Injection Gas Sampling / Comissioning
B27: Gas Samples | C27: 23500 | D27: ea | E27: 3 | F27: =C27*E27 -> 70500
B28: Calibration Gas | C28: 12500 | D28: LS | E28: 1 | F28: =C28*E28 -> 12500
B29: Additional Vendor Trips / Troubles | C29: 9250 | D29: LS | E29: 1 | F29: =C29*E29 -> 9250
F30: =C30*E30 -> 0
B31: Pre-Injection Gas Sampling / Comissioning | F31: =SUM(F26:F30) -> 92250

Sheet Spare Parts breakdown
B2: Equipment | C2: Vendor | D2: Value | E2: Spare Parts Value
B3: Biogas Blower | C3: TBD | D3: 10000 | E3: =D3*0.05 -> 500
B4: H2S Removal | C4: EcoVapor | D4: 710442 | E4: =D4*0.05 -> 35522.1
B5: GUU | C5: Prodeval | D5: 6124498 | E5: =D5*0.05 -> 306224.9
B6: DeOx | C6: EcoVapor | D6: 736595 | E6: =D6*0.05 -> 36829.75
B7: Blending Skid | C7: Standby Systems | D7: 315000 | E7: =D7*0.05 -> 15750
B8: PG Compressor | C8: ACS | D8: 936474 | E8: =D8*0.05 -> 46823.7
B9: Flare | C9: Zeeco | D9: 81500 | E9: =D9*0.05 -> 4075
B10: Misc | C10: Multiple | D10: 100000 | E10: =D10*0.05 -> 5000
D12: Subtotal= | E12: =SUM(E3:E10)*1.45 -> 653551.9

Sheet Fixtures and Furnishings
B2: Description | C2: Rate | D2: UOM | E2: QTY | F2: Total
B3: Owner Fixtures and Furnishings
B4: Operations Office Furnishing | C4: 20000 | D4: LS | E4: 2 | F4: =C4*E4 -> 40000 | G4: Chairs/tables/water cooler/fridge
B5: Operations office Supplies | C5: 3000 | D5: LS | E5: 1 | F5: =C5*E5 -> 3000 | G5: Printer/monitors etc.
B6: Ops First Aid Kit/AED | C6: 650 | D6: LS | E6: 1 | F6: =C6*E6 -> 650 | G6: First aid kit and aed
B7: Operations IT Set-up | C7: 50000 | D7: LS | E7: 1 | F7: =C7*E7 -> 50000
B8: Labeling / Signage | C8: 3500 | D8: LS | E8: 1 | F8: =C8*E8 -> 3500
B9: Monument Sign | C9: 50000 | D9: LS | E9: 2 | F9: =C9*E9 -> 100000
B10: Storage Shelving | C10: 35000 | D10: LS | E10: 1 | F10: =C10*E10 -> 35000
B11: Misc F&F | C11: 15000 | D11: LS | E11: 1 | F11: =C11*E11 -> 15000
C12: 0 | D12: LS | E12: 0 | F12: =C12*E12 -> 0
C13: 0 | D13: LS | E13: 0 | F13: =C13*E13 -> 0
C14: 0 | D14: LS | E14: 0 | F14: =C14*E14 -> 0
B15: Subtotal Owner Fixtures and Furnishings | F15: =SUM(F4:F14) -> 247150

Sheet Utility
B1: Description | C1: Rate | D1: UOM | E1: QTY | F1: Total | G1: Notes
B2: Utility Interconnects
B3: Water | C3: 0 | D3: LS | E3: 1 | F3: =C3*E3 -> 0
B4: Sewer | C4: 0 | D4: LS | E4: 1 | F4: =C4*E4 -> 0
B5: Temp Power | C5: 10000 | D5: LS | E5: 1 | F5: =C5*E5 -> 10000
B6: Perm Power | C6: 160000 | D6: LS | E6: 1 | F6: =C6*E6 -> 160000 | G6: Received ROM from GRDA
B7: Nat. Gas | C7: 0 | D7: LS | E7: 1 | F7: =C7*E7 -> 0 | G7: Wrapped into Interconnect
B8: Internet | C8: 2500 | D8: LS | E8: 1 | F8: =C8*E8 -> 2500
B9: Subtotal Utility Interconnects | F9: =SUM(F3:F8) -> 172500
B11: Utility Usage
B12: Monthly Water | C12: 2.26 | D12: 1000 Gallons | E12: 2 | F12: =C12*E12+50 -> 54.52 | G12: 50$ minimum assumed
B13: Monthly Sewer | C13: 3.91 | D13: 1000 Gallons | E13: 2 | F13: =C13*E13+50 -> 57.82 | G13: 50$ minimum assumed
B14: Water Total | C14: 54.52 | D14: MO | E14: 4 | F14: =C14*E14 -> 218.08
B15: Sewer Total | C15: 85.63 | D15: MO | E15: 4 | F15: =C15*E15 -> 342.52
B16: Temp Power | C16: 0.011 | D16: kWh | E16: 276480 | F16: =C16*E16 -> 3041.28
B17: Perm Power | C17: 0.011 | D17: kWh | E17: =600000*4 -> 2400000 | F17: =E17*C17 -> 26400
B18: Nat. Gas | C18: 3.76 | D18: MMBTU | E18: =3125*4 -> 12500 | F18: =C18*E18 -> 47000
B19: Internet bills | C19: 150 | D19: MO | E19: 4 | F19: =C19*E19 -> 600
B20: Subtotal Utility Usage | F20: =SUM(F14:F19) -> 77601.88
F22: =F20*3 -> 232805.64 | G22: Note -likley high water bill, filling digesters X3

Sheet Sheet1
B2: Persimmon
B3: Project Delivery (Mark's Team)
C4: Annual Cost | D4: Allocation | E4: Duration | F4: Cost | G4: Rate
C5: $K | D5: % | E5: Months | F5: $K | G5: $/hr
B6: SPM | C6: =200*1.5 -> 300 | D6: 0.2 | E6: =12*1.5 -> 18 | F6: =C6/12*E6*D6 -> 90 | G6: =300000/2080 -> 144.23077
B7: C-PM | C7: =165*1.5 -> 247.5 | D7: 1 | E7: 14 | F7: =C7/12*E7*D7 -> 288.75 | G7: =248000/2080 -> 119.23077
B8: C-PE | C8: =125*1.5 -> 187.5 | D8: 1 | E8: 12 | F8: =C8/12*E8*D8 -> 187.5 | G8: =188000/2080 -> 90.384615
B9: Trailer | C9: =5*12 -> 60 | D9: 1 | E9: 14 | F9: =C9/12*E9*D9 -> 70
B10: Other | C10: =5*12 -> 60 | D10: 1 | E10: 14 | F10: =C10/12*E10*D10 -> 70
B11: Total | F11: =SUM(F6:F10) -> 706.25
B13: Ops During Construction
C14: Annual Cost | D14: Allocation | E14: Duration | F14: Cost | G14: Rate
C15: $K | D15: % | E15: Months | F15: $K | G15: $/hr
B16: Person A | C16: 150 | D16: 1 | E16: 6 | F16: =C16/12*E16*D16 -> 75 | G16: =150000/2080 -> 72.115385
B17: Person B | C17: 150 | D17: 1 | E17: 4 | F17: =C17/12*E17*D17 -> 50 | G17: =150000/2080 -> 72.115385
B18: Ops Manager | C18: 300 | D18: 0.25 | E18: 6 | F18: =C18/12*E18*D18 -> 37.5 | G18: =G6 -> 144.23077 | H18: Added by SC, not sure if it needs to be included
B19: Total | F19: =SUM(F16:F18) -> 162.5
B23: 2080 Man-Hours/ Yr
