Workbook
Name EstSumm_DirectsBeforePermit: #REF!
Name EstSumm_PermitAndFeesPct: #REF!
Name GUU_Unit_Size: "TextBox 1"

Sheet 400 SCFM
B2: Burnham RNG CAPEX model | D2: Component | E2: Cost | F2: Notes | H2: Equipment
B3: Unit: 400 SCFM | D3: Construction
D4: General Requirements | E4: 550000 | H4: BU GEN | I4: 65000
D5: Survey/Inspection | E5: 140000 | H5: Flare | I5: 250000
D6: Structural Concrete | E6: 120000 | H6: Sales Gas Compressor | I6: 500000
D7: Structural & Misc metals | E7: 70000
D8: Specialties/Painting | E8: 7500
D9: Signage | E9: 5000
D10: Building Systems | E10: 90000
D11: Fire suppression | E11: 50000 | I11: =SUM(I4:I6) -> 815000
D12: Plumbing | E12: 10000
D13: Electrical System | E13: 1900000 | F13: Including Switchgear, ATS, and all panels
D14: General Civil Work | E14: 130000
D15: Site Utilities | E15: 115000 | F15: Not interconnect
D16: Plant Controls Install | E16: 415000
D17: Process Piping & Plant Equipment (Labor & material) | E17: 1200000 | G17: =E4/E25 -> 0.092056757
D18: Underground obstruction Allowance | E18: 380000
D19: Soil treatment Allowance | E19: 100000
D20: Other allowances | E20: 100000 | F20: Site improvements
D21: Other allowances
D22: Contingency
D23: Overhead | E23: =SUM(E4:E22)*0.03 -> 161475 | F23: 3% of GC costs
D24: Contractor Fee | E24: =SUM(E4:E22)*0.08 -> 430600 | F24: 8% of GC Costs
D25: Construction Subtotal | E25: =SUM(E4:E24) -> 5974575
D26: Interconnections
D27: Natural gas Interconnect | E27: 1600000
D28: Electricity Interconnect | E28: 300000
D29: Permanent Internet | E29: 60000
D30: Interconnections Subtotal | E30: =SUM(E27:E29) -> 1960000
D31: Permitting
D32: Various Permits | E32: 50000
D33: Permitting Subtotal | E33: 50000
D34: Totals
D35: Total Costs for Construction | E35: =SUM(E33,E30,E25,#REF!,#REF!) -> #REF!

Sheet 800 SCFM
B2: Burnham RNG CAPEX model | D2: Component | E2: Cost | F2: Notes | H2: Equipment
B3: Unit: 800 SCFM | D3: Equipment
D4: Owner supplied equipment | E4: 3600000 | F4: GUU | H4: BU GEN | I4: 65000
D5: Contractor Supplied Equipment | E5: =I11*1.06 -> 863900 | F5: Flare, BU generator, product gas compressor (6% mark up) | H5: Flare | I5: 250000
D6: Gas Cromatograph (If required) | F6: 300000 | H6: Sales Gas Compressor | I6: 500000
D7: Other | F7: NRU, Liquids receiving, blending skid, ETC
D8: Other
D9: Other
D10: Other
D11: Equipment subtotals | E11: =SUM(E4:E10) -> 4463900 | I11: =SUM(I4:I6) -> 815000
D12: Engineering
D13: BOP Engineering | E13: =E38*0.05 -> 298728.75 | F13: 5% of GC Cost
D14: Other Engineering
D15: Engineering Subtotal | E15: =SUM(E13:E14) -> 298728.75
D16: Construction
D17: General Requirements | E17: 550000 | G17: =E17/E38 -> 0.092056757
D18: Survey/Inspection | E18: 140000
D19: Structural Concrete | E19: 120000
D20: Structural & Misc metals | E20: 70000
D21: Specialties/Painting | E21: 7500
D22: Signage | E22: 5000
D23: Building Systems | E23: 90000
D24: Fire suppression | E24: 50000
D25: Plumbing | E25: 10000
D26: Electrical System | E26: 1900000 | F26: Including Switchgear, ATS, and all panels
D27: General Civil Work | E27: 130000
D28: Site Utilities | E28: 115000 | F28: Not interconnect
D29: Plant Controls Install | E29: 415000
D30: Process Piping & Plant Equipment (Labor & material) | E30: 1200000
D31: Underground obstruction Allowance | E31: 380000
D32: Soil treatment Allowance | E32: 100000
D33: Other allowances | E33: 100000 | F33: Site improvements
D34: Other allowances
D35: Other allowances
D36: Overhead | E36: =SUM(E17:E35)*0.03 -> 161475 | F36: 3% of GC costs
D37: Contractor Fee | E37: =SUM(E17:E35)*0.08 -> 430600 | F37: 8% of GC Costs
D38: Construction Subtotal | E38: =SUM(E17:E37) -> 5974575
D39: Interconnections
D40: Natural gas Interconnect | E40: 1600000
D41: Electricity Interconnect | E41: 300000
...

Sheet 1200 SCFM

Sheet Instructions
A1: How to Use This Excel File Welcome to Capex Model V2! This Excel file is designed to help you efficiently plan and estimate costs for your gas upgrading unit project. Below are detailed instructions on how to use each section of the file. PFD INPUTS Sheet 1: "Pretty Picture" DO NOT CHANGE OTHER SHEETS This sheet contains a flow diagram with 11 inputs and 7 optional inputs. Follow the steps below to complete the inputs: Date of Model: Go to data and click refresh all - then type out todays date FID Date: Type out the FID date (Final Investment Decision) in the designated cell to calculate escalation assuming a 3.5% inflation rate. Size of Gas Upgrading Unit: Select the appropriate size from the dropdown menu. Gas Chromatograph: Choose whether a gas chromatograph is needed from the dropdown menu. Flare: Indicate if a flare is needed. If yes, select either "Enclosed" or "Candlestick" flare from the dropdown menu. Product Gas Compressor: Specify if a compressor is needed. If yes, input the required PSI (Pounds per Square Inch). Backup Generator: Decide if a backup generator is needed and select the appropriate option from the dropdown menu. Location of the Project: Input the state where the project is located. Tax Exempt Status: Indicate if the project is tax exempt to calculate the sales tax accordingly. SUMMARY OF COSTS To the side of the flow chart, you will find a summary of costs that automatically calculates based on your inputs. TABLE INPUTS Additional Equipment: Input the cost of any additional equipment, including spare parts, freight, and commissioning. Additional Direct Costs: Enter the costs for complete quotes received from vendors. Interconnect: Enter the interconnect facility estimate and the lateral distance in miles. Dev Fee: Enter the Dev Fee NOTES Ensure all dropdown selections and inputs are completed accurately to get precise cost calculations. Review the summary of costs to verify all entries and calculations. Thank you for using this tool. If you have any questions or need further assistance, please reach out to Gage. | C1: Protected Sheets Password: Broncosarebad

Sheet Pretty Picture
T2: Project Estimate
U3: Discipline | V3: Estimate ($) | X3: SCFM DRPDN | AC3: 1 | AD3: 2 | AE3: 3
J4: ='Calculation Sheet'!F10 -> 142425.47 | U4: Major Equipment | V4: =SUM(V5:V7) -> 6747182.2 | X4: 3 | AA4: =U4 -> Major Equipment | AB4: =V4 -> 6747182.2 | AC4: 4129718 | AD4: 6223596.1 | AE4: 6747182.2
J5: FLARE | U5: GUU | V5: ='Calculation Sheet'!F9 -> 6113160.8 | X5: Flare DRPDN | AA5: =U5 -> GUU | AB5: =V5 -> 6113160.8 | AC5: 3495696.6 | AD5: 5589574.8 | AE5: 6113160.8
C6: Date of Model: | E6: 46065 | J6: #VALUE! | U6: Flare | V6: ='Calculation Sheet'!F10 -> 142425.47 | X6: 1 | AA6: =U6 -> Flare | AB6: =V6 -> 142425.47 | AC6: 142425.47 | AD6: 142425.47 | AE6: 142425.47
C7: Expected FID Date: | E7: 46065 | U7: Compressor | V7: ='Calculation Sheet'!F11 -> 491595.89 | X7: GCA DRPDN | AA7: =U7 -> Compressor | AB7: =V7 -> 491595.89 | AC7: 491595.89 | AD7: 491595.89 | AE7: 491595.89
U8: User-Additional Equip | V8: 0 | X8: 1 | AA8: =U8 -> User-Additional Equip | AB8: =V8 -> 0 | AC8: 0 | AD8: 0 | AE8: 0
U9: User-Additional Equip | V9: 0 | X9: BU Generator DRPDN | AA9: =U9 -> User-Additional Equip | AB9: =V9 -> 0 | AC9: 0 | AD9: 0 | AE9: 0
U10: Subtotal Equipment | V10: =SUM(V4,V8:V9) -> 6747182.2 | X10: 1 | AA10: =U10 -> Subtotal Equipment | AB10: =V10 -> 6747182.2 | AC10: 4129718 | AD10: 6223596.1 | AE10: 6747182.2
U11: Engineering | V11: ='Calculation Sheet'!F5 -> 923758.38 | X11: Compressor DRPDN | AA11: =U11 -> Engineering | AB11: =V11 -> 923758.38 | AC11: 672788.49 | AD11: 769258.14 | AE11: 923758.38
C12: #VALUE! | F12: #VALUE! | I12: #VALUE! | L12: #VALUE! | O12: #VALUE! | U12: Civil/Structural | V12: ='Calculation Sheet'!F14 -> 1102429.2 | X12: 1 | AA12: =U12 -> Civil/Structural | AB12: =V12 -> 1102429.2 | AC12: 821871.82 | AD12: 1102429.2 | AE12: 1102429.2
U13: Process Piping / Mechanical | V13: ='Calculation Sheet'!F18 -> 1312220.6 | X13: PSI DRPDN | AA13: =U13 -> Process Piping / Mechanical | AB13: =V13 -> 1312220.6 | AC13: 1002638.4 | AD13: 1312220.6 | AE13: 1312220.6
E14: #VALUE! | H14: #VALUE! | K14: #VALUE! | N14: #VALUE! | U14: Electrical | V14: ='Calculation Sheet'!F20 -> 1274795.3 | X14: 3 | AA14: =U14 -> Electrical | AB14: =V14 -> 1274795.3 | AC14: 925603.97 | AD14: 1238247.3 | AE14: 1274795.3
U15: Instrumentation / Controls / Automation | V15: ='Calculation Sheet'!F26 -> 972528.02 | X15: Escalation Calculator | AA15: =U15 -> Instrumentation / Controls / Automation | AB15: =V15 -> 972528.02 | AC15: 972528.02 | AD15: 972528.02 | AE15: 972528.02
U16: Non-Process Infrastructure | V16: ='Calculation Sheet'!F29 -> 491537.82 | X16: =(1 + 3.5%/12) ^ (X20) -> 1 | AA16: =U16 -> Non-Process Infrastructure | AB16: =V16 -> 491537.82 | AC16: 429706.21 | AD16: 491537.82 | AE16: 491537.82
C17: ANAEROBIC DIGESTER | F17: GAS UPGRADER | I17: CHROMATOGRAPH | L17: RNG COMPRESSOR | O17: INTERCONNECT | U17: General Requirements | V17: ='Calculation Sheet'!F33 -> 1154200.6 | X17: Flare DRPDN 2 | AA17: =U17 -> General Requirements | AB17: =V17 -> 1154200.6 | AC17: 805936.94 | AD17: 1089883.5 | AE17: 1154200.6
F18: ='Calculation Sheet'!F9 -> 6113160.8 | I18: ='Calculation Sheet'!F27 -> 238548.72 | L18: ='Calculation Sheet'!F11 -> 491595.89 | U18: User -Additional Direct Costs | X18: 2 | AA18: =U18 -> User -Additional Direct Costs | AB18: =V18 -> 0 | AC18: 0 | AD18: 0 | AE18: 0
U19: User -Additional Direct Costs | X19: Month Calc | AA19: =U19 -> User -Additional Direct Costs | AB19: =V19 -> 0 | AC19: 0 | AD19: 0 | AE19: 0
U20: Subtotal Construction Directs | V20: =SUM(V11:V19) -> 7231470 | X20: =DATEDIF(E6,E7,"m") -> 0 | AA20: =U20 -> Subtotal Construction Directs | AB20: =V20 -> 7231470 | AC20: 5631073.8 | AD20: 6976104.6 | AE20: 7231470
U21: General Conditions | V21: ='Calculation Sheet'!F39 -> 1481737.1 | AA21: =U21 -> General Conditions | AB21: =V21 -> 1481737.1 | AC21: 1034643.9 | AD21: 1399168.3 | AE21: 1481737.1
U22: Building Permits | V22: ='Calculation Sheet'!F40 -> 69893.261 | AA22: =U22 -> Building Permits | AB22: =V22 -> 69893.261 | AC22: 48803.959 | AD22: 65998.503 | AE22: 69893.261
U23: Insurance / G&A | V23: ='Calculation Sheet'!F41 -> 377423.61 | AA23: =U23 -> Insurance / G&A | AB23: =V23 -> 377423.61 | AC23: 263541.38 | AD23: 356391.92 | AE23: 377423.61
C24: #VALUE! | F24: #VALUE! | I24: #VALUE! | L24: #VALUE! | O24: #VALUE! | U24: EPC Profit | V24: ='Calculation Sheet'!F42 -> 768825.87 | AA24: =U24 -> EPC Profit | AB24: =V24 -> 768825.87 | AC24: 536843.55 | AD24: 725983.54 | AE24: 768825.87
U25: Subtotal: Const Mgmt and Indirects | V25: =SUM(V21:V24) -> 2697879.9 | AA25: =U25 -> Subtotal: Const Mgmt and Indirects | AB25: =V25 -> 2697879.9 | AC25: 1883832.8 | AD25: 2547542.2 | AE25: 2697879.9
E26: #VALUE! | H26: #VALUE! | K26: #VALUE! | U26: User-Interconnect (Base $2,200,000) | V26: 2200000 | AA26: =U26 -> User-Interconnect (Base $2,200,000) | AB26: =V26 -> 2200000 | AC26: 2200000 | AD26: 2200000 | AE26: 2200000
U27: User-Lateral Miles | V27: 2 | X27: =(V31+V36)/V10 -> 3.1080141 | Y27: LANG Factor | AA27: =U27 -> User-Lateral Miles | AB27: =V27 -> 2 | AC27: 2 | AD27: 2 | AE27: 2
U28: Lateral | V28: ='Calculation Sheet'!F44 -> 1846805 | AA28: =U28 -> Lateral | AB28: =V28 -> 1846805 | AC28: 1846805 | AD28: 1846805 | AE28: 1846805
C29: UTILITY COMPANY | F29: TRANSFORMER | I29: SWITCHGEAR | L29: GENERATOR | O29: PROJECT STATE | U29: Subtotal Interconnect | V29: =SUM(V26,V28) -> 4046805 | AA29: =U29 -> Subtotal Interconnect | AB29: =V29 -> 4046805 | AC29: 4046805 | AD29: 4046805 | AE29: 4046805
L30: ='Calculation Sheet'!F23 -> 87642.182 | U30: Sales Tax | V30: ='Calculation Sheet'!F46 -> 0 | AA30: =U30 -> Sales Tax | AB30: =V30 -> 0 | AC30: 0 | AD30: 0 | AE30: 0
T31: Total EPC | V31: =SUM(V10,V20,V25,V30,V29) -> 20723337 | AA31: Total EPC | AB31: =V31 -> 20723337 | AC31: 15691430 | AD31: 19794048 | AE31: 20723337
O32: TAX EXEMPT? | U32: Utility Connection Fee | V32: ='Calculation Sheet'!F50 -> 250000 | AA32: =U32 -> Utility Connection Fee | AB32: =V32 -> 250000 | AC32: 250000 | AD32: 250000 | AE32: 250000
U33: Insurance | V33: ='Calculation Sheet'!F51 -> 310850.06 | AA33: =U33 -> Insurance | AB33: =V33 -> 310850.06 | AC33: 235371.44 | AD33: 296910.72 | AE33: 310850.06
U34: Project Delivery | V34: ='Calculation Sheet'!F52 -> 1360000 | AA34: =U34 -> Project Delivery | AB34: =V34 -> 1360000 | AC34: 1360000 | AD34: 1360000 | AE34: 1360000
U35: Dev Costs | V35: ='Calculation Sheet'!F53 -> 621700.11 | AA35: =U35 -> Dev Costs | AB35: =V35 -> 621700.11 | AC35: 470742.89 | AD35: 593821.44 | AE35: 621700.11
U36: Fixtures and Furnishings | V36: ='Calculation Sheet'!F56 -> 247000 | AA36: =U36 -> Fixtures and Furnishings | AB36: =V36 -> 247000 | AC36: 247000 | AD36: 247000 | AE36: 247000
U37: Ops During Construction | V37: ='Calculation Sheet'!F55 -> 426000 | AA37: =U37 -> Ops During Construction | AB37: =V37 -> 426000 | AC37: 426000 | AD37: 426000 | AE37: 426000
U38: Contingency | V38: ='Calculation Sheet'!F57 -> 1554250.3 | AA38: =U38 -> Contingency | AB38: =V38 -> 1554250.3 | AC38: 1176857.2 | AD38: 1484553.6 | AE38: 1554250.3
U39: Commercial Subtotal | V39: =SUM(V32:V38) -> 4769800.4 | AA39: =U39 -> Commercial Subtotal | AB39: =V39 -> 4769800.4 | AC39: 4165971.6 | AD39: 4658285.7 | AE39: 4769800.4
T40: Total | V40: =SUM(V31,V39) -> 25493137 | AA40: Total | AB40: =V40 -> 25493137 | AC40: 19857401 | AD40: 24452334 | AE40: 25493137
AA41: ITC Eligible | AB41: ='Calculation Sheet'!E62 -> 22551600 | AC41: 16977695 | AD41: 21510796 | AE41: 22551600
...

Sheet Calculation Sheet
B3: Estimate Calculation
C4: Discipline | F4: Estimate | G4: Notes
C5: Engineering | F5: ='Sales Tax and Escalation'!S45*'Pretty Picture'!X16*IF('Pretty Picture'!X4 = 1, Engineering!E12, IF('Pretty Picture'!X4 = 2, Engineering!F12,Engineering!G12)) -> 923758.38
D6: BOP Engineering | F6: ='Sales Tax and Escalation'!S45*'Pretty Picture'!X16*IF('Pretty Picture'!X4 = 1, SUM(Engineering!E7:E8,Engineering!E10), IF('Pretty Picture'!X4 = 2, SUM(Engineering!F7:F8,Engineering!F10),SUM(Engineering!G7:G8,Engineering!G10))) -> 817504.64
D7: 3rd Party Testing | F7: ='Sales Tax and Escalation'!S45*'Pretty Picture'!X16*IF('Pretty Picture'!X4 = 1, Engineering!E9, IF('Pretty Picture'!X4 = 2, Engineering!F9,Engineering!G9)) -> 106253.74
C8: Major Equipment | F8: =SUM(F9:F11) -> 6747182.2
D9: GUU | F9: ='Sales Tax and Escalation'!S46*'Pretty Picture'!X16*'Gas Upgrader'!E14 -> 6113160.8
D10: Flare | F10: ='Sales Tax and Escalation'!S45*'Pretty Picture'!X16*Flare!E24 -> 142425.47
D11: Compressor | F11: ='Sales Tax and Escalation'!S45*'Pretty Picture'!X16*Compressor!E15 -> 491595.89
C12: User Added Equip | F12: ='Pretty Picture'!V8 -> 0
C13: User Added Equip | F13: ='Pretty Picture'!V9 -> 0
C14: Civil/Structural | F14: ='Sales Tax and Escalation'!S45*'Pretty Picture'!X16*IF('Pretty Picture'!X4=1,CivStr!I38,IF('Pretty Picture'!X4=2,CivStr!J38,CivStr!K38)) -> 1102429.2
D15: Earthworks | F15: ='Sales Tax and Escalation'!S45*'Pretty Picture'!X16*IF('Pretty Picture'!X4=1,CivStr!I23,IF('Pretty Picture'!X4=2,CivStr!J23+CivStr!I23,CivStr!J23+CivStr!K23+CivStr!I23)) -> 727938.19
D16: Concrete | F16: ='Sales Tax and Escalation'!S45*'Pretty Picture'!X16*IF('Pretty Picture'!X4=1,CivStr!I31,IF('Pretty Picture'!X4=2,CivStr!J31+CivStr!I31,CivStr!J31+CivStr!K31+CivStr!I31)) -> 299695.41
D17: Process Structural | F17: ='Sales Tax and Escalation'!S45*'Pretty Picture'!X16*IF('Pretty Picture'!X4=1,CivStr!I37,IF('Pretty Picture'!X4=2,CivStr!J37+CivStr!I37,CivStr!J37+CivStr!K37+CivStr!I37)) -> 74795.602
C18: Process Piping / Mechanical | F18: ='Sales Tax and Escalation'!S45*'Pretty Picture'!X16*Piping!E13 -> 1312220.6
D19: Process Piping / Mechanical | F19: ='Sales Tax and Escalation'!S45*'Pretty Picture'!X16*Piping!E13 -> 1312220.6
C20: Electrical | F20: ='Sales Tax and Escalation'!S45*'Pretty Picture'!X16*((IF('Pretty Picture'!X4=1,'Process Electrical'!R123,IF('Pretty Picture'!X4=2,'Process Electrical'!S123,'Process Electrical'!T123)))+Generator!E14) -> 1274795.3
D21: U/G Utilities | F21: ='Sales Tax and Escalation'!S45*'Pretty Picture'!X16*'Process Electrical'!R9 -> 66543.899
D22: Electrical Distribution Equipment | F22: ='Sales Tax and Escalation'!S45*'Pretty Picture'!X16*IF('Pretty Picture'!X4=1,'Process Electrical'!R27,IF('Pretty Picture'!X4=2,'Process Electrical'!S27+'Process Electrical'!R27,'Process Electrical'!S27+'Process Electrical'!R27)) -> 388306.02
D23: Generator | F23: ='Sales Tax and Escalation'!S45*'Pretty Picture'!X16*Generator!E14 -> 87642.182
D24: Cables / Conduits / Terminations | F24: ='Sales Tax and Escalation'!S45*'Pretty Picture'!X16*IF('Pretty Picture'!X4=1,'Process Electrical'!R112,IF('Pretty Picture'!X4=2,'Process Electrical'!S112+'Process Electrical'!R112,'Process Electrical'!S112+'Process Electrical'!R112)) -> 613759.41
D25: Other | F25: ='Sales Tax and Escalation'!S45*'Pretty Picture'!X16*IF('Pretty Picture'!X4=1,('Process Electrical'!R117+'Process Electrical'!R122),IF('Pretty Picture'!X4=2,'Process Electrical'!S117+'Process Electrical'!R117+'Process Electrical'!S122+'Process Electrical'!R122,'Process Electrical'!T117+'Process Electrical'!S117+'Process Electrical'!R117+'Process Electrical'!T122+'Process Electrical'!S122+'Process Electrical'!R122)) -> 118543.8
C26: Instrumentation / Controls / Automation | F26: =SUM(F27:F28) -> 972528.02
D27: Gas Chromatograph | F27: ='Sales Tax and Escalation'!S45*'Pretty Picture'!X16*Chromatograph!E14 -> 238548.72
D28: BOP Controls | F28: ='Sales Tax and Escalation'!S45*'Pretty Picture'!X16*'Inst. & Controls'!K36 -> 733979.29
C29: Non-Process Infrastructure | F29: ='Sales Tax and Escalation'!S45*'Pretty Picture'!X16*IF('Pretty Picture'!X4=1,'Non-Process'!I50,IF('Pretty Picture'!X4=2,'Non-Process'!J50,'Non-Process'!K50)) -> 491537.82
D30: Site Infrastructure | F30: ='Sales Tax and Escalation'!S45*'Pretty Picture'!X16*IF('Pretty Picture'!X4 = 1, 'Non-Process'!I26, IF('Pretty Picture'!X4 = 2, 'Non-Process'!J26+'Non-Process'!I26,'Non-Process'!K26+'Non-Process'!I26)) -> 242512.68
D31: Site Utilities | F31: ='Sales Tax and Escalation'!S45*'Pretty Picture'!X16*IF('Pretty Picture'!X4 = 1, 'Non-Process'!I43, IF('Pretty Picture'!X4 = 2, 'Non-Process'!J43+'Non-Process'!I43,'Non-Process'!K43+'Non-Process'!I43)) -> 147834.17
D32: Site Electrical | F32: ='Sales Tax and Escalation'!S45*'Pretty Picture'!X16*IF('Pretty Picture'!X4 = 1, 'Non-Process'!I49, IF('Pretty Picture'!X4 = 2, 'Non-Process'!J49+'Non-Process'!I49,'Non-Process'!K49+'Non-Process'!I49)) -> 39359.354
C33: General Requirements | E33: 0.09 | F33: =SUM(F5,F8,F14,F18,F20,F26,F29,F35,F34,F12,F13)*E33 -> 1154200.6 | G33: Note - ARCO 8.89% Milton 30% 12.30, Swinerton 12.1% Persimmons ROM 11.25, Swinerton Pasco GMP 7.79%
C34: User Added Direct Cost | F34: ='Pretty Picture'!X16*'Pretty Picture'!V18 -> 0
C35: User Added Direct Cost | F35: ='Pretty Picture'!X16*'Pretty Picture'!V19 -> 0
C36: Direct Costs Subtotal | F36: =SUM(F5,F8,F14,F18,F20,F26,F29,F35,F34,F12,F33) -> 13978652
C38: Construction Management Costs | F38: =SUM(F39:F42) -> 2697879.9
D39: General Conditions | E39: =0.106 -> 0.106 | F39: =F36*E39 -> 1481737.1 | G39: Note - ARCO 6.25% Milton 30% 12.30, Swinerton 27.3% Persimmons ROM 11.25, Swinerton Pasco GMP 1.3%
D40: Building Permits | E40: 0.005 | F40: =F36*E40 -> 69893.261
D41: Insurance / G&A | E41: 0.027 | F41: =F36*E41 -> 377423.61
D42: EPC Profit | E42: 0.055 | F42: =F36*E42 -> 768825.87
C43: Interconnect | F43: ='Pretty Picture'!V26 -> 2200000
...

Sheet Gas Upgrader
C3: GUU
C4: Unit Size | D4: Vlookup | E4: Unit Price ($) | F4: Notes | I4: Domestic Content | L4: Percent Payment | M4: Timeline wks | N4: Term | O4: Yes
C5: 400 SCFM | D5: 1 | E5: 3172596 | I5: Vpack US | J5: Vpack FR | L5: 0.3 | N5: Signing LNTP | O5: No
C6: 800 SCFM | D6: 2 | E6: =E5+2039310 -> 5211906 | I6: 0.44 | J6: 0.38 | L6: 0.2 | N6: Delivery of commencement of Manufacturing Certificate
C7: 1200 SCFM | D7: 3 | E7: =E6+509941 -> 5721847 | I7: 0.43 | J7: 0.37 | L7: 0.5 | N7: Delivery of completion of Manufacturing Certificate
C8: 1754 SCFM | D8: 4 | E8: 7971358 | F8: incl. manual hoist, first charge carbon, domestic content | I8: 0.46 | J8: 0.4 | L8: Total | M8: 53
C9: Chosen Price PFD | D9: ='Pretty Picture'!X4 -> 3 | E9: =VLOOKUP(D9,D5:E8,2,TRUE) -> 5721847
C10: Optional | D10: Needed? | E10: Estimated Cost ($) | F10: Notes | I10: Link to Quote:
C11: Allen Bradley | D11: Yes | E11: 132000 | F11: Default to Yes | I11: Prodeval MPA
C12: Spare Parts | D12: Yes | E12: 100000 | F12: Default to Yes | I12: Allan Bradley
C14: Total | E14: =SUMIF(D11:D13,"yes",E11:E14)+E9 -> 5953847

Sheet Flare
C3: Flare | F3: (Scaled to Feb 2026)
C4: Size | D4: Vlookup | E4: Unit Price ($) | F4: Notes | I4: Percent Payment | J4: Timeline wks | K4: Terms | L4: Yes
C5: 400 SCFM | D5: 1 | E5: =IF('Pretty Picture'!X18=1,279151,67972) -> 67972 | F5: =IF('Pretty Picture'!X18=1,"Per Zeeco Budgetary Pricing", "Persimmon 30' Flare") -> Persimmon 30' Flare | I5: 0.15 | J5: 0 | K5: Acceptance of order | L5: No | O5: Enclosed
C6: 800 SCFM | D6: 2 | E6: =IF('Pretty Picture'!X18=1,297489,67972) -> 67972 | F6: =IF('Pretty Picture'!X18=1,"Per Zeeco Budgetary Pricing", "Persimmon 30' Flare") -> Persimmon 30' Flare | I6: 0.5 | J6: 14 | K6: Issuance of customer submittal package | O6: Candlestick
C7: 1200 SCFM | D7: 3 | E7: =IF('Pretty Picture'!X18=1,319903,67972) -> 67972 | F7: =IF('Pretty Picture'!X18=1,"Per Zeeco Budgetary Pricing", "Persimmon 30' Flare") -> Persimmon 30' Flare | I7: 0.35 | J7: 30 | K7: Notice of availability for shipment
C8: 1750 SCFM | D8: 4 | E8: =IF('Pretty Picture'!X18=1,340279,56600) -> 56600 | F8: =IF('Pretty Picture'!X18=1,"Extrapolated based on budgetary pricing", "Nashville 20' Flare") -> Nashville 20' Flare
C9: Chosen Price PFD | D9: ='Pretty Picture'!X4 -> 3 | E9: =VLOOKUP(D9,D5:E8,2,TRUE) -> 67972 | I9: Total | J9: =SUM(J5:J7) -> 44
C10: Optional | D10: Needed? | E10: Estimated Cost ($) | F10: Notes
C11: Freight | D11: Yes | E11: 15000 | F11: Default to Yes - Mark Swag | I11: Link to Quote:
C12: Field Service | D12: Yes | E12: 10000 | F12: Default to Yes - Mark Swag | I12: Persimmon | J12: Nashville
C13: One Access Ladder | D13: Yes | E13: 10000 | F13: Default to Yes - Mark Swag | I13: Enclosed Flare Quotes
C14: Engineering | D14: Yes | E14: =10665*1.016772 -> 10843.873 | F14: Zeeco 1200 scfm candlestick
C15: Deflagration Arrester | D15: No | E15: =12240*1.016772 -> 12445.289 | F15: Zeeco 1200 scfm candlestick
C16: Candlestick vapor blower skid | D16: No | E16: =E9 -> 67972 | F16: *Only use with Zeeco candlestick pricing
C17: Kockout Drum | D17: No | E17: =14800*1.016772 -> 15048.226 | F17: Zeeco 1200 scfm candlestick
C18: Automated Purge Gas Spool | D18: No | E18: =6900*1.016772 -> 7015.7268 | F18: Zeeco 1200 scfm candlestick
C19: PLC Base Logic Control Panel | D19: No | E19: =10000*1.016772 -> 10167.72 | F19: Zeeco 1200 scfm candlestick
C20: Industrial Surface Finish | D20: No
C21: Extended Warranty - Equip | D21: No
C22: Extended Warranty - Preventative Maintenance | D22: No
C23: Spare parts | D23: Yes | E23: 25000 | F23: Default to Yes - Mark Swag
C24: Total | E24: =IF('Pretty Picture'!X6=2,0,SUMIF(D11:D23,"yes",E11:E24)+E9) -> 138815.87

Sheet Compressor
C3: Product Gas Compressor | G3: (Scaled to Feb 2026)
E4: 0-100 PSI | F4: 100-300 PSI | G4: 300-1000 PSI | P4: DO NOT DELETE
C5: Size | D5: Vlookup | E5: 1 | F5: 2 | G5: 3 | M5: Yes | P5: 0-100 PSI
C6: 400 SCFM | D6: 1 | E6: 0 | F6: 347207 | G6: 459137 | M6: No | P6: 100-300 PSI
C7: 800 SCFM | D7: 2 | E7: 0 | F7: 347207 | G7: 459137 | P7: 300-1000 PSI
C8: 1200 SCFM | D8: 3 | E8: 0 | F8: 347207 | G8: 459137
C9: 1754 SCFM | D9: 4 | E9: 0 | F9: 347207 | G9: 459137
C10: Chosen Compressor | E10: =VLOOKUP('Pretty Picture'!X12,Compressor!D6:G9,IF('Pretty Picture'!X14=2,3,IF('Pretty Picture'!X14=3,4,2)),FALSE) -> 459137
C11: Optional | D11: Needed? | E11: Estimated Cost ($) | F11: Notes
C12: Spare parts | D12: Yes | E12: 20000 | F12: Default to Yes
C15: Total | E15: =IF('Pretty Picture'!X12=2,0,SUMIF(D12:D14,"yes",E12:E14)+E10) -> 479137
C18: Quote
C19: 2.5 Compressors (Ariel)

Sheet Chromatograph
C3: Chromatograph | F3: (Scaled to Feb 2026)
C4: Unit Size | D4: Vlookup | E4: Unit Price ($) | F4: Notes | I4: Yes
C5: 400 SCFM | D5: 1 | E5: 186979 | I5: No
C6: 800 SCFM | D6: 2 | E6: 186979
C7: 1200 SCFM | D7: 3 | E7: 186979
C8: 1754 SCFM | D8: 4 | E8: 186979
C9: Chosen Price PFD | D9: ='Pretty Picture'!X4 -> 3 | E9: =VLOOKUP(D9,D5:E8,2,TRUE) -> 186979
C10: Optional | D10: Needed? | E10: Estimated Cost ($) | F10: Notes
C11: Shipping | D11: Yes | E11: 3500 | F11: Default Yes
C12: Field Commissioning | D12: Yes | E12: 17110 | F12: Default Yes
C13: Spare Parts | D13: Yes | E13: 24914 | F13: Default Yes
C14: Total | E14: =IF('Pretty Picture'!X8=2,0,SUMIF(D11:D13,"yes",E11:E13)+E9) -> 232503
C17: Link to Quote:
C18: 22037004-026 RKA POA.pdf

Sheet Generator
C3: Generator | F3: (Scaled to Feb 2026)
C4: Generator Unit Size | D4: Vlookup | E4: Unit Price ($) | F4: Notes | I4: Yes
C5: 50KW Generator, Nat. gas + ATS | D5: 1 | E5: 30035 | F5: (Genset $21,300 Means 26 32 13.16 0520) + $8k ATS | I5: No
C6: 60KW Generator, Nat. gas + ATS | D6: 2 | E6: 51254 | F6: (Genset $42,000: Means 26 32 13.16 0600) + $8k ATS
C7: 80Kw Generator, Nat. Gas + ATS | D7: 3 | E7: 69421 | F7: (Genset $42,000: Means 26 32 13.16 0600) + $8K ATS
C8: 80Kw Generator, Nat. Gas + ATS | D8: 4 | E8: 69421 | F8: (Genset $42,000: Means 26 32 13.16 0600) + $8K ATS
C9: Chosen Price PFD | D9: ='Pretty Picture'!X4 -> 3 | E9: =VLOOKUP(D9,D5:E8,2,TRUE) -> 69421
C10: Optional | D10: Needed? | E10: Estimated Cost ($) | F10: Notes
C11: Field Commissioning | D11: Yes | E11: 8500 | F11: Default Yes
C12: Spare Parts | D12: Yes | E12: 7500 | F12: Default Yes
C14: Total | E14: =IF('Pretty Picture'!X10=2,0,SUMIF(D11:D13,"yes",E11:E13)+E9) -> 85421

Sheet Piping
C3: Piping / Mechanical | F3: (Scaled to Feb 2026)
C4: Piping Unit Size | D4: Vlookup | E4: Unit Price ($) | F4: Notes | I4: Yes
C5: 400 | D5: 1 | E5: =0.75*E6 -> 905208.75 | F5: 75% of 800 SCFM | I5: No
C6: 800 | D6: 2 | E6: 1206945 | F6: ARCO GMP
C7: 1200 | D7: 3 | E7: =E6 -> 1206945
C8: Chosen Price PFD | D8: ='Pretty Picture'!X4 -> 3 | E8: =VLOOKUP(D8,D5:E7,2,TRUE) -> 1206945
C9: Optional | D9: Needed? | E9: Estimated Cost ($) | F9: Notes
C10: Setting Equipment | D10: Yes | E10: 72019 | F10: ARCO GMP
C13: Total | E13: =IF('Pretty Picture'!X10=2,0,SUMIF(D10:D12,"yes",E10:E12)+E8)+H20 -> 1278964
C16: Piping / Mechanical Additional Equipment
C17: Equipment Cost | D17: Min | E17: Max | F17: Selected Factor | H17: Cost
C18: ='Pretty Picture'!V8 -> 0 | D18: 0.21 | E18: 0.36 | F18: 0.23 | H18: =C18*F18 -> 0
C19: ='Pretty Picture'!V9 -> 0 | D19: 0.21 | E19: 0.36 | F19: 0.23 | H19: =C19*F19 -> 0
C20: Total | H20: =SUM(H18:H19) -> 0

Sheet Engineering
C3: Engineering | I3: (Scaled to Feb 2026)
D4: QTY | E4: 400 | F4: 800 | G4: 1200 | H4: 1754 | I4: Notes
C5: Geotech | D5: inc. Development Budget
C6: Survey (Topo/Alta) | D6: inc. Development Budget
C7: BOP Design | E7: =367034 -> 367034 | F7: =452500 -> 452500 | G7: 593670 | I7: 400 SCFM AEI-Columbia Quote $358,050, GPSD ARCO Quote - 102.5 committed 350 on GMP, 1200 SCFM - Purpose $582,476
C8: BOP Construction Admin | E8: 193116 | F8: 193116 | G8: 193116 | I8: 400 SCFM AEI-Columbia Quote $188,390 (225 mi distance), 1200 SCFM Purpose -Persimmons $94,320 (45mi)
C9: 3rd Party Testing | E9: =83500*1.025 -> 85587.5 | F9: =E9*1.1 -> 94146.25 | G9: =F9*1.1 -> 103560.87 | I9: ARCO Milton 12.30 Quote $83,500
C10: As-Builts | E10: 10000 | F10: 10000 | G10: 10000
C11: Permitting Fees (Enviro) | D11: inc. Development Budget
C12: Total | E12: =SUM(E5:E11)+E19 -> 655737.5 | F12: =SUM(F5:F11)+E19 -> 749762.25 | G12: =SUM(G5:G11)+E19 -> 900346.88
C15: Engineering Additional Equipment
C16: Equipment Cost | D16: Factor | E16: Cost
C17: ='Pretty Picture'!V8 -> 0 | D17: 0.08 | E17: =C17*D17 -> 0
C18: ='Pretty Picture'!V9 -> 0 | D18: 0.08 | E18: =C18*D18 -> 0
C19: Total | E19: =SUM(E17:E18) -> 0

Sheet Inst. & Controls
C3: BOP Controls
D4: IT/OT | E4: BOP Hardware | F4: Make | G4: Model | H4: Quantity | I4: UOM | J4: Base Cost | K4: Estimated Cost | M4: Procurement Source
D5: IT | E5: Firewall | F5: Fortigate | G5: 90G | H5: 1 | I5: EA | J5: 8200 | K5: 8200 | M5: Burnham
D6: OT | E6: Firewall | F6: Fortigate | G6: 90G | H6: 1 | I6: EA | J6: 8200 | K6: 8200 | M6: Burnham
D7: IT | E7: 5G cellular failover SD-WAN router | F7: Fortigate | G7: FEX-511F | H7: 1 | I7: EA | J7: 2000 | K7: 2000 | M7: Burnham
D8: IT | E8: Managed Switches | F8: Ubiqiti | G8: USW Pro Max | H8: 4 | I8: EA | J8: 400 | K8: 1600 | M8: Burnham
D9: OT | E9: Core Switch | F9: Cisco | G9: Catalyst 9200 | H9: 2 | I9: EA | J9: 3500 | K9: 7000 | M9: Burnham
D10: IT | E10: WAPs | F10: Ubiqiti | G10: U7 Pro Indoor/Outdoor | H10: 5 | I10: EA | J10: 350 | K10: 1750 | M10: Burnham
D11: OT | E11: Managed Switches | F11: Allen-Bradley | G11: Stratix 5200 20 port | H11: 6 | I11: EA | J11: 10000 | K11: 60000 | M11: Burnham
D12: OT | E12: Fiber Tranceiver modules | F12: Allen-Bradley | G12: SFP1GSX | H12: 12 | I12: EA | J12: 450 | K12: 5400 | M12: Burnham
D13: IT/OT | E13: Miscellaneous electrical | F13: N/A | G13: N/A | H13: 1 | I13: EA | J13: 5000 | K13: 5000 | M13: Burnham
D14: IT/OT | E14: Industrial rack mounted UPS | F14: Vertiv | G14: Liebert GXT5 | H14: 1 | I14: EA | J14: 2000 | K14: 2000 | M14: Burnham
D15: IT/OT | E15: On-Premise data backup | F15: Synology | G15: 2423RP+ | H15: 1 | I15: EA | J15: 3000 | K15: 3000 | M15: Burnham
D16: IT/OT | E16: On-Premise hard drives | F16: Synology | G16: HAT5300 | H16: 12 | I16: EA | J16: 800 | K16: 9600 | M16: Burnham
... D27: OT | E27: Allen-Bradley software | F27: Rockwell Automation | G27: Studio 5000 | H27: 1 | I27: EA | J27: 20000 | K27: 20000 | M27: Burnham
D28: IT | E28: Installation | H28: 0.65 | I28: EA | J28: =SUM(K5:K27) -> 312350 | K28: =H28*J28 -> 203027.5
E29: Adjustment per 2025 GMP Pricing | K29: 160000
C30: Subtotal | K30: =SUM(K5:K29) -> 675377.5
C31: Field Technicians
E32: Prodeval Techs | H32: =2*40 -> 80 | I32: HR | J32: 250 | K32: =H32*J32 -> 20000
E33: Other Equipment Vendor Techs | H33: =2*40 -> 80 | I33: HR | J33: 250 | K33: =H33*J33 -> 20000
C35: Subtotal | K35: =SUM(K32:K34) -> 40000
C36: Instrumentation / Controls | K36: =K30+K35+H44 -> 715377.5
C40: Controls Additional Equipment
C41: Equipment Cost | D41: Min | E41: Max | F41: Factor | H41: Factored Cost
C42: ='Pretty Picture'!V8 -> 0 | D42: 0.18 | E42: 0.36 | F42: 0.26 | H42: =C42*F42 -> 0
C43: ='Pretty Picture'!V9 -> 0 | D43: 0.18 | E43: 0.36 | F43: 0.26 | H43: =C43*F43 -> 0
C44: Total | H44: =SUM(H42:H43) -> 0

Sheet CivStr
B3: Civil / Structural | I3: Base 400 SCFM | J3: Note - 800-1200 layout sizes are very similar
C4: Earthworks | D4: QTY | E4: UOM | F4: Addtl 800 | G4: Addtl 1200 | H4: Unit Cost | I4: Total | J4: Addtl 800 | K4: Addtl 1200 | L4: Notes
C5: Clear and Grub Site | D5: 1 | E5: ACRE | F5: 0.3 | G5: 0 | H5: 6000 | I5: =D5*H5 -> 6000 | J5: =F5*H5 -> 1800 | K5: =(G5)*H5 -> 0 | L5: Addtl 1200 is additional from 800 so both must be added
C6: Erosion Control | D6: 1 | E6: LS | H6: 15000 | I6: =D6*H6 -> 15000
C7: Strip & Stockpile Topsoil (1ft deep) | D7: 1 | E7: ACRE | F7: 0.3 | G7: 0 | H7: =(43650*1*5)/27 -> 8083.3333 | I7: =D7*H7 -> 8083.3333 | J7: =F7*H7 -> 2425 | K7: =(G7)*H7 -> 0
C8: Soil Remova/ Hauling | D8: 2000 | E8: CY | F8: 640 | G8: 0 | H8: 70 | I8: =D8*H8 -> 140000 | J8: =F8*H8 -> 44800 | K8: =(G8)*H8 -> 0
C9: Rough Grading | D9: 15000 | E9: CY | F9: 3000 | G9: 0 | H9: 12 | I9: =D9*H9 -> 180000 | J9: =F9*H9 -> 36000 | K9: =(G9)*H9 -> 0
C10: Fine Grading | D10: 40000 | E10: SF | F10: 1500 | G10: 0 | H10: 0.5 | I10: =D10*H10 -> 20000 | J10: =F10*H10 -> 750 | K10: =(G10)*H10 -> 0
C11: Structural Excavation (fnd/slab) | D11: 1 | E11: LS | F11: 0.2 | G11: 0 | H11: 5000 | I11: =D11*H11 -> 5000 | J11: =F11*H11 -> 1000 | K11: =(G11)*H11 -> 0
C12: Structural Backfill | D12: 1 | E12: LS | F12: 0.2 | G12: 0 | H12: 1500 | I12: =D12*H12 -> 1500 | J12: =F12*H12 -> 300 | K12: =(G12)*H12 -> 0
C13: Seed Site | D13: =D5*43650/27 -> 1616.6667 | E13: SF | F13: 320 | G13: 0 | H13: 2.35 | I13: =D13*H13 -> 3799.1667 | J13: =F13*H13 -> 752 | K13: =(G13)*H13 -> 0
C14: Survey (Construction Control) | I14: 51900 | J14: =62280-I14 -> 10380
C20: Earthworks Allowance | D20: 1 | E20: LS | F20: 0.2 | G20: 0 | H20: 150000 | I20: =D20*H20 -> 150000 | J20: =F20*H20 -> 30000
C23: Subtotal | I23: =SUM(I5:I22) -> 581282.5 | J23: =SUM(J5:J22) -> 128207 | K23: =SUM(K5:K22) -> 0
C24: Concrete | D24: QTY | E24: UOM | F24: Addtl 800 | G24: Addtl 1200 | H24: Cost | I24: Total | J24: Addtl 800 | K24: Addtl 1200 | L24: Notes
C25: Footers 10'x2'x4' | D25: 53.33 | E25: CY | F25: 35.47 | H25: 2000 | I25: =D25*H25 -> 106660 | J25: =H25*F25 -> 70940
C26: Generator Equip Pad- 5'x5'x8" | D26: 1 | E26: Ea | F26: 0 | H26: 1900 | I26: =D26*H26 -> 1900
C27: Transformer,SG Equip Pad- 5'x5'x8" | D27: 2 | E27: Ea | F27: 0 | H27: 1900 | I27: =D27*H27 -> 3800
C28: Compressor Foundation- 12' X 20' X 6" | D28: 4.4 | E28: CY | H28: 2000 | I28: =D28*H28 -> 8800
C29: Misc. Concrete (unknown site req) | I29: 50000 | J29: 50000
C31: Subtotal | I31: =SUM(I25:I30) -> 171160 | J31: =SUM(J25:J30) -> 120940 | K31: =SUM(K25:K30) -> 0
C32: Process Structural | F32: Addtl 800 | G32: Addtl 1200 | J32: Addtl 800 | K32: Addtl 1200 | L32: Notes
C33: Concrete Footing 1.5'x1.5'x2' | D33: 12 | E33: ea. | F33: 6 | G33: 0 | H33: 2000 | I33: =D33*H33 -> 24000 | J33: =F33*H33 -> 12000
C34: Pipe Support | D34: 12 | E34: Ea. | F34: 6 | H34: 2050 | I34: =H34*D34 -> 24600 | J34: =H34*F34 -> 12300
C37: Subtotal | I37: =SUM(I33:I36) -> 48600 | J37: =SUM(J33:J36) -> 24300 | K37: =SUM(K33:K36) -> 0
B38: Civil / Structural | H38: Subtotal | I38: =I37+I31+I23+G44 -> 801042.5 | J38: =J23+J31+J37+I38 -> 1074489.5 | K38: =K23+K31+K37+J38 -> 1074489.5
B40: Civil Additional Equipment
C41: Equipment Cost | D41: Min | E41: Max | F41: Factor | G41: Factored Cost
C42: ='Pretty Picture'!V8 -> 0 | D42: 0.12 | E42: 0.48 | F42: 0.18 | G42: =C42*F42 -> 0
C43: ='Pretty Picture'!V9 -> 0 | D43: 0.12 | E43: 0.48 | F43: 0.18 | G43: =C43*F43 -> 0
B44: Total | G44: =SUM(G42:G43) -> 0

Sheet Process Electrical
B2: Electrical | R2: Base 400 SCFM
C3: Electrical Ductbank | D3: Qty | E3: Unit | F3: Man Hrs. | G3: STD MH | H3: MH Adj | I3: Total MH | J3: Wage Rate | K3: Unit Mat | L3: Unit Sub | M3: Unit Equip | N3: Labor | O3: Material | P3: Sub Cont. | Q3: Equip | R3: Total | S3: Addtl 800 | T3: Addtl 1200
C4: grading for duct bank | D4: =(50*6*4.5)/27 -> 50 | E4: cy | F4: 4 | G4: =F4*D4 -> 200 | H4: 0 | I4: =G4*(H4+1) -> 200 | J4: 75.29 | K4: 18 | L4: 0 | M4: 0 | N4: =J4*I4 -> 15058 | O4: =K4*D4 -> 900 | P4: =L4*D4 -> 0 | Q4: =M4*D4 -> 0 | R4: =SUM(N4:Q4) -> 15958
C5: 4" of sand in bottom of duct bank | D5: =(50*0.333*4)/27 -> 2.4666667 | F5: 2 | G5: =F5*D5 -> 4.9333333 | H5: 0 | I5: =G5*(H5+1) -> 4.9333333 | J5: =$J$4 -> 75.29 | K5: 30 | L5: 0 | M5: 0 | N5: =J5*I5 -> 371.43067 | O5: =K5*D5 -> 74 | P5: =L5*D5 -> 0 | Q5: =M5*D5 -> 0 | R5: =SUM(N5:Q5) -> 445.43067
C6: concrete duct bank for 1600 amp feeders | D6: =(50*4*4)/27 -> 29.62963 | E6: cy | F6: 5 | G6: =F6*D6 -> 148.14815 | H6: 0 | I6: =G6*(H6+1) -> 148.14815 | J6: =$J$4 -> 75.29 | K6: 125 | L6: 1100 | M6: 0 | N6: =J6*I6 -> 11154.074 | O6: =K6*D6 -> 3703.7037 | P6: =L6*D6 -> 32592.593 | Q6: =M6*D6 -> 0 | R6: =SUM(N6:Q6) -> 47450.37
C7: conduit spacers | D7: 25 | E7: ea | F7: 0.5 | G7: =F7*D7 -> 12.5 | H7: 0 | I7: =G7*(H7+1) -> 12.5 | J7: =$J$4 -> 75.29 | K7: 2.5 | L7: 0 | M7: 0 | N7: =J7*I7 -> 941.125 | O7: =K7*D7 -> 62.5 | P7: =L7*D7 -> 0 | Q7: =M7*D7 -> 0 | R7: =SUM(N7:Q7) -> 1003.625
C9: Subtotal | I9: =SUM(I4:I8) -> 365.58148 | R9: =SUM(R4:R8) -> 64857.426
C10: Electrical Distribution Equipment | D10: Qty | E10: Unit | F10: Man Hrs. | G10: STD MH | H10: MH Adj | I10: Total MH | J10: Wage Rate | K10: Unit Mat | L10: Unit Sub | M10: Unit Equip | N10: Labor | O10: Material | P10: Sub Cont. | Q10: Equip | R10: Total
C11: 1600 amp switch gear 277/480vac 3 ph | D11: 1 | E11: ea | F11: 200 | G11: =F11*D11 -> 200 | H11: 0 | I11: =G11*(H11+1) -> 200 | J11: =$J$4 -> 75.29 | K11: 0 | L11: 0 | M11: 150000 | N11: =J11*I11 -> 15058 | O11: =K11*D11 -> 0 | P11: =L11*D11 -> 0 | Q11: =M11*D11 -> 150000 | R11: =SUM(N11:Q11) -> 165058
C12: 2 600 amps breaker | D12: 1 | E12: ea | F12: 20 | G12: =F12*D12 -> 20 | H12: 0 | I12: =G12*(H12+1) -> 20 | J12: =$J$4 -> 75.29 | K12: 0 | L12: 0 | M12: 25000 | N12: =J12*I12 -> 1505.8 | O12: =K12*D12 -> 0 | P12: =L12*D12 -> 0 | Q12: =M12*D12 -> 25000 | R12: =SUM(N12:Q12) -> 26505.8 | S12: =R12*2 -> 53011.6
C13: 1 400amp breaker | D13: 1 | E13: ea | F13: 20 | G13: =F13*D13 -> 20 | H13: 0 | I13: =G13*(H13+1) -> 20 | J13: =$J$4 -> 75.29 | K13: 0 | L13: 0 | M13: 20000 | N13: =J13*I13 -> 1505.8 | O13: =K13*D13 -> 0 | P13: =L13*D13 -> 0 | Q13: =M13*D13 -> 20000 | R13: =SUM(N13:Q13) -> 21505.8
C14: 1 100 amp breaker | D14: 1 | E14: ea | F14: 20 | G14: =F14*D14 -> 20 | H14: 0 | I14: =G14*(H14+1) -> 20 | J14: =$J$4 -> 75.29 | K14: 0 | L14: 0 | M14: 10000 | N14: =J14*I14 -> 1505.8 | O14: =K14*D14 -> 0 | P14: =L14*D14 -> 0 | Q14: =M14*D14 -> 10000 | R14: =SUM(N14:Q14) -> 11505.8
C15: 2 60 amp breakers | D15: 2 | E15: ea | F15: 20 | G15: =F15*D15 -> 40 | H15: 0 | I15: =G15*(H15+1) -> 40 | J15: =$J$4 -> 75.29 | K15: 0 | L15: 0 | M15: 5000 | N15: =J15*I15 -> 3011.6 | O15: =K15*D15 -> 0 | P15: =L15*D15 -> 0 | Q15: =M15*D15 -> 10000 | R15: =SUM(N15:Q15) -> 13011.6
C16: Genset - Install only | D16: 1 | E16: ea | F16: 200 | G16: =F16*D16 -> 200 | H16: 0 | I16: =G16*(H16+1) -> 200 | J16: =$J$4 -> 75.29 | K16: 0 | L16: 0 | M16: 0 | N16: =J16*I16 -> 15058 | O16: =K16*D16 -> 0 | P16: =L16*D16 -> 0 | Q16: =M16*D16 -> 0 | R16: =SUM(N16:Q16) -> 15058
C17: 30 KVA XFMR 277/480 3 ph | D17: 2 | E17: ea | F17: 20 | G17: =F17*D17 -> 40 | H17: 0 | I17: =G17*(H17+1) -> 40 | J17: =$J$4 -> 75.29 | K17: 1500 | L17: 0 | M17: 12000 | N17: =J17*I17 -> 3011.6 | O17: =K17*D17 -> 3000 | P17: =L17*D17 -> 0 | Q17: =M17*D17 -> 24000 | R17: =SUM(N17:Q17) -> 30011.6
C18: 600 amp fused disconnects | D18: 1 | E18: ea | F18: 20 | G18: =F18*D18 -> 20 | H18: 0 | I18: =G18*(H18+1) -> 20 | J18: =$J$4 -> 75.29 | K18: 0 | L18: 0 | M18: 7500 | N18: =J18*I18 -> 1505.8 | O18: =K18*D18 -> 0 | P18: =L18*D18 -> 0 | Q18: =M18*D18 -> 7500 | R18: =SUM(N18:Q18) -> 9005.8 | S18: =R18*2 -> 18011.6
C19: EMDP Panel 100 amp 277/480 3p 30 circuit | D19: 1 | E19: ea | F19: 20 | G19: =F19*D19 -> 20 | H19: 0 | I19: =G19*(H19+1) -> 20 | J19: =$J$4 -> 75.29 | K19: 0 | L19: 0 | M19: 2000 | N19: =J19*I19 -> 1505.8 | O19: =K19*D19 -> 0 | P19: =L19*D19 -> 0 | Q19: =M19*D19 -> 2000 | R19: =SUM(N19:Q19) -> 3505.8
C20: EMP Panel 100 amp 120/208 3p 30 circuit | D20: 1 | E20: ea | F20: 20 | G20: =F20*D20 -> 20 | H20: 0 | I20: =G20*(H20+1) -> 20 | J20: =$J$4 -> 75.29 | K20: 0 | L20: 0 | M20: 1200 | N20: =J20*I20 -> 1505.8 | O20: =K20*D20 -> 0 | P20: =L20*D20 -> 0 | Q20: =M20*D20 -> 1200 | R20: =SUM(N20:Q20) -> 2705.8
C21: 20 amp 3 ph breakers | D21: 4 | E21: ea | F21: 5 | G21: =F21*D21 -> 20 | H21: 0 | I21: =G21*(H21+1) -> 20 | J21: =$J$4 -> 75.29 | K21: 0 | L21: 0 | M21: 75 | N21: =J21*I21 -> 1505.8 | O21: =K21*D21 -> 0 | P21: =L21*D21 -> 0 | Q21: =M21*D21 -> 300 | R21: =SUM(N21:Q21) -> 1805.8
C22: 50 amp 3 ph breakers | D22: 1 | E22: ea | F22: 5 | G22: =F22*D22 -> 5 | H22: 0 | I22: =G22*(H22+1) -> 5 | J22: =$J$4 -> 75.29 | K22: 0 | L22: 0 | M22: 125 | N22: =J22*I22 -> 376.45 | O22: =K22*D22 -> 0 | P22: =L22*D22 -> 0 | Q22: =M22*D22 -> 125 | R22: =SUM(N22:Q22) -> 501.45
C23: 20 amp 1ph breakers | D23: 11 | E23: ea | F23: 1 | G23: =F23*D23 -> 11 | H23: 0 | I23: =G23*(H23+1) -> 11 | J23: =$J$4 -> 75.29 | K23: 0 | L23: 0 | M23: 50 | N23: =J23*I23 -> 828.19 | O23: =K23*D23 -> 0 | P23: =L23*D23 -> 0 | Q23: =M23*D23 -> 550 | R23: =SUM(N23:Q23) -> 1378.19
C24: 60amp fused disconnect for office panel | D24: 1 | E24: ea | F24: 5 | G24: =F24*D24 -> 5 | H24: 0 | I24: =G24*(H24+1) -> 5 | J24: =$J$4 -> 75.29 | K24: 50 | L24: 0 | M24: 250 | N24: =J24*I24 -> 376.45 | O24: =K24*D24 -> 50 | P24: =L24*D24 -> 0 | Q24: =M24*D24 -> 250 | R24: =SUM(N24:Q24) -> 676.45
C25: 100amp ATS for EMDP Panels | D25: 1 | E25: ea | F25: 20 | G25: =F25*D25 -> 20 | H25: 0 | I25: =G25*(H25+1) -> 20 | J25: =$J$4 -> 75.29 | K25: 1200 | L25: 0 | M25: 2500 | N25: =J25*I25 -> 1505.8 | O25: =K25*D25 -> 1200 | P25: =L25*D25 -> 0 | Q25: =M25*D25 -> 2500 | R25: =SUM(N25:Q25) -> 5205.8
C27: Subtotal | I27: =SUM(I11:I26) -> 661 | R27: =SUM(R11:R26) -> 307441.69 | S27: =SUM(S11:S26) -> 71023.2 | T27: =SUM(T11:T26) -> 0
C28: Cables / Conduits / Terminations | D28: Qty | E28: Unit | F28: Man Hrs. | G28: STD MH | H28: MH Adj | I28: Total MH | J28: Wage Rate | K28: Unit Mat | L28: Unit Sub | M28: Unit Equip | N28: Labor | O28: Material | P28: Sub Cont. | Q28: Equip | R28: Total
C29: 1600 amp feed from XFMR To Switch gear
C30: 500 mcm cu 4 parallel feeds 50ft run | D30: =3*4*75 -> 900 | E30: ft | F30: 1 | G30: =F30*D30 -> 900 | H30: 0 | I30: =G30*(H30+1) -> 900 | J30: =$J$4 -> 75.29 | K30: 15 | L30: 0 | M30: 0 | N30: =J30*I30 -> 67761 | O30: =K30*D30 -> 13500 | P30: =L30*D30 -> 0 | Q30: =M30*D30 -> 0 | R30: =SUM(N30:Q30) -> 81261
C31: 4/0 cu gnd conductors | D31: =4*75 -> 300 | E31: ft | F31: 0.75 | G31: =F31*D31 -> 225 | H31: 0 | I31: =G31*(H31+1) -> 225 | J31: =$J$4 -> 75.29 | K31: 7 | L31: 0 | M31: 0 | N31: =J31*I31 -> 16940.25 | O31: =K31*D31 -> 2100 | P31: =L31*D31 -> 0 | Q31: =M31*D31 -> 0 | R31: =SUM(N31:Q31) -> 19040.25
C32: 500 mcm terminations | D32: 24 | E32: ea | F32: 4 | G32: =F32*D32 -> 96 | H32: 0 | I32: =G32*(H32+1) -> 96 | J32: =$J$4 -> 75.29 | K32: 25 | L32: 0 | M32: 0 | N32: =J32*I32 -> 7227.84 | O32: =K32*D32 -> 600 | P32: =L32*D32 -> 0 | Q32: =M32*D32 -> 0 | R32: =SUM(N32:Q32) -> 7827.84
C33: 4" Rigid Conduit | D33: 200 | E33: ft | F33: 0.75 | G33: =F33*D33 -> 150 | H33: 0 | I33: =G33*(H33+1) -> 150 | J33: =$J$4 -> 75.29 | K33: 35 | L33: 0 | M33: 0 | N33: =J33*I33 -> 11293.5 | O33: =K33*D33 -> 7000 | P33: =L33*D33 -> 0 | Q33: =M33*D33 -> 0 | R33: =SUM(N33:Q33) -> 18293.5
C34: 90 deg bends | D34: 8 | E34: ea | F34: 1 | G34: =F34*D34 -> 8 | H34: 0 | I34: =G34*(H34+1) -> 8 | J34: =$J$4 -> 75.29 | K34: 200 | L34: 0 | M34: 0 | N34: =J34*I34 -> 602.32 | O34: =K34*D34 -> 1600 | P34: =L34*D34 -> 0 | Q34: =M34*D34 -> 0 | R34: =SUM(N34:Q34) -> 2202.32
C35: GND Bushings | D35: 8 | E35: ea | F35: 0.5 | G35: =F35*D35 -> 4 | H35: 0 | I35: =G35*(H35+1) -> 4 | J35: =$J$4 -> 75.29 | K35: 75 | L35: 0 | M35: 0 | N35: =J35*I35 -> 301.16 | O35: =K35*D35 -> 600 | P35: =L35*D35 -> 0 | Q35: =M35*D35 -> 0 | R35: =SUM(N35:Q35) -> 901.16
C36: 4/0 terminations | D36: 2 | E36: ea | F36: 0.5 | G36: =F36*D36 -> 1 | H36: 0 | I36: =G36*(H36+1) -> 1 | J36: =$J$4 -> 75.29 | K36: 2.5 | L36: 0 | M36: 0 | N36: =J36*I36 -> 75.29 | O36: =K36*D36 -> 5 | P36: =L36*D36 -> 0 | Q36: =M36*D36 -> 0 | R36: =SUM(N36:Q36) -> 80.29
C37: 300 amp feed from Switch gear to Prodeval Panel
C38: 350 mcm cu 250ft run | D38: 865 | E38: ft | F38: 0 | G38: =F38*D38 -> 0 | H38: 0 | I38: =G38*(H38+1) -> 0 | J38: =$J$4 -> 75.29 | K38: 12 | L38: 0 | M38: 0 | N38: =J38*I38 -> 0 | O38: =K38*D38 -> 10380 | P38: =L38*D38 -> 0 | Q38: =M38*D38 -> 0 | R38: =SUM(N38:Q38) -> 10380
C39: 4" conduit | D39: 250 | E39: ft | F39: 0.75 | G39: =F39*D39 -> 187.5 | H39: 0 | I39: =G39*(H39+1) -> 187.5 | J39: =$J$4 -> 75.29 | K39: 35 | L39: 0 | M39: 0 | N39: =J39*I39 -> 14116.875 | O39: =K39*D39 -> 8750 | P39: =L39*D39 -> 0 | Q39: =M39*D39 -> 0 | R39: =SUM(N39:Q39) -> 22866.875
C40: 90 deg bends | D40: 2 | E40: ea | F40: 1 | G40: =F40*D40 -> 2 | H40: 0 | I40: =G40*(H40+1) -> 2 | J40: =$J$4 -> 75.29 | K40: 75 | L40: 0 | M40: 0 | N40: =J40*I40 -> 150.58 | O40: =K40*D40 -> 150 | P40: =L40*D40 -> 0 | Q40: =M40*D40 -> 0 | R40: =SUM(N40:Q40) -> 300.58
C41: 4/0 GND | D41: 275 | E41: ft | F41: 0.75 | G41: =F41*D41 -> 206.25 | H41: 0 | I41: =G41*(H41+1) -> 206.25 | J41: =$J$4 -> 75.29 | K41: 7 | L41: 0 | M41: 0 | N41: =J41*I41 -> 15528.563 | O41: =K41*D41 -> 1925 | P41: =L41*D41 -> 0 | Q41: =M41*D41 -> 0 | R41: =SUM(N41:Q41) -> 17453.562
C42: supports | D42: 35 | E42: ea | F42: 2.5 | G42: =F42*D42 -> 87.5 | H42: 0 | I42: =G42*(H42+1) -> 87.5 | J42: =$J$4 -> 75.29 | K42: 30 | L42: 0 | M42: 0 | N42: =J42*I42 -> 6587.875 | O42: =K42*D42 -> 1050 | P42: =L42*D42 -> 0 | Q42: =M42*D42 -> 0 | R42: =SUM(N42:Q42) -> 7637.875
C43: 350 mcm terminations | D43: 6 | E43: ea | F43: 2 | G43: =F43*D43 -> 12 | H43: 0 | I43: =G43*(H43+1) -> 12 | J43: =$J$4 -> 75.29 | K43: 5 | L43: 0 | M43: 0 | N43: =J43*I43 -> 903.48 | O43: =K43*D43 -> 30 | P43: =L43*D43 -> 0 | Q43: =M43*D43 -> 0 | R43: =SUM(N43:Q43) -> 933.48
...

Sheet Non-Process
B2: Non-Process Infrastructure | I2: Base 400 SCFM
C3: Site Infrastructure | D3: QTY | E3: UOM | F3: Addtl 800 | G3: Addtl 1200 | H3: Unit Cost | I3: Total | J3: Addtl 800 | K3: Addtl 1200 | L3: Notes | M3: Additional Notes
C4: Office Buildng | D4: 1 | E4: ls | H4: 100000 | I4: =D4*H4 -> 100000 | J4: =F4*H4 -> 0 | K4: =G4*H4 -> 0 | L4: 1200 is addtl from 400 so do not add both 800 and 1200
C5: Signage | D5: 1 | E5: ls | H5: 7500 | I5: =D5*H5 -> 7500 | J5: =F5*H5 -> 0 | K5: =G5*H5 -> 0
C6: Specialties / Painting | D6: 1 | E6: ls | H6: 7500 | I6: =D6*H6 -> 7500 | J6: =F6*H6 -> 0 | K6: =G6*H6 -> 0
C7: Handrails / Misc Metal | D7: 1 | E7: ls | H7: 5000 | I7: =D7*H7 -> 5000 | J7: =F7*H7 -> 0 | K7: =G7*H7 -> 0
C8: Parking Lot / Hardscape | D8: 1 | E8: ls | J8: =F8*H8 -> 0 | K8: =G8*H8 -> 0
C9: Precast Bumpers | D9: 6 | E9: ea | H9: 79 | I9: =D9*H9 -> 474 | J9: =F9*H9 -> 0 | K9: =G9*H9 -> 0 | L9: RS Means 32 17 13.19 1000 wheel stops, precast conctete incl. dowels, 6"x10" x 6'
C10: Pavement Marking | D10: 5 | E10: stall | H10: 29.5 | I10: =D10*H10 -> 147.5 | J10: =F10*H10 -> 0 | K10: =G10*H10 -> 0 | L10: RS Means 32 17 23.14 0825 lines in pvmt, parking stall, small quantities
C11: Handicap Marking + Sign | D11: 1 | E11: stall | H11: =355+72.5 -> 427.5 | I11: =D11*H11 -> 427.5 | J11: =F11*H11 -> 0 | K11: =G11*H11 -> 0 | L11: RS Means 32 17 23.14 1200 handicap symbol, 1210 habdicpa parking sign and post
C12: Paving | D12: 4000 | E12: s.f. | H12: 5.3 | I12: =D12*H12 -> 21200 | J12: =F12*H12 -> 0 | K12: =G12*H12 -> 0 | L12: RS Means 32 12 16.44 0050 Ashpalt Paving, 4" binder course, 3" topping, 6" stone base
C13: Curb | D13: 100 | E13: l.f. | H13: 44 | I13: =D13*H13 -> 4400 | J13: =F13*H13 -> 0 | K13: =G13*H13 -> 0 | L13: RS Means 32 16 13 0435 Curb and Gutter, straight with 6" high curb and 6" thick gutter, wood forms
C14: Sidewalk | D14: 425 | E14: s.f. | F14: 100 | G14: 0 | H14: 8.1 | I14: =D14*H14 -> 3442.5 | J14: =F14*H14 -> 810 | K14: =G14*H14 -> 0 | L14: RS Means 32 06 10.10 0350 Concrete 3000 psi, CIP 6X6 WWF
C15: Light Pole Foundations | D15: 6 | E15: ea. | F15: 4 | H15: 1000 | I15: =D15*H15 -> 6000 | J15: =F15*H15 -> 4000 | K15: =G15*H15 -> 0
C16: Stoop | D16: 10 | E16: ea. | F16: 7 | H16: 200 | I16: =D16*H16 -> 2000 | J16: =F16*H16 -> 1400 | K16: =G16*H16 -> 0
C17: Bollards | D17: 4 | E17: ea | F17: 2 | G17: 0 | H17: 1200 | I17: =D17*H17 -> 4800 | J17: =F17*H17 -> 2400 | K17: =G17*H17 -> 0 | L17: RS Means 32 17 13.13 1400 - 8" diameter, filled concrete w/ paint | M17: 12.30.24 Milton Arco Estimate 50 bollards ( $150/ea + paint $150/ea + concrete $250/ea = $550 /ea
C18: Flagpole | D18: 1 | E18: ls | H18: 15000 | I18: =D18*H18 -> 15000 | J18: =F18*H18 -> 0 | K18: =G18*H18 -> 0
C19: Landscaping | D19: 1 | E19: ls | F19: 0.1 | G19: 0 | H19: 10000 | I19: =D19*H19 -> 10000 | J19: =F19*H19 -> 1000 | K19: =G19*H19 -> 0
C20: Fencing | D20: 460 | E20: l.f. | F20: 192 | G20: 0 | H20: 61 | I20: =D20*H20 -> 28060 | J20: =F20*H20 -> 11712 | K20: =G20*H20 -> 0 | L20: Means 32 31 11.10 8' H, 6ga. Wire 2 1/2" line post, galv steel in concrete | M20: 12.30.24 Milton Arco Estimate 421 L.F. $56.33/L.F.
C21: Vehicular Gate | D21: 1 | E21: ea | H21: 3300 | I21: =D21*H21 -> 3300 | J21: =F21*H21 -> 0 | K21: =G21*H21 -> 0 | L21: Means 32 31 13.20 3120 Double Swing Gate, inc. posts & hardware, in concrete 20ft opening | M21: 12.30.24 Milton Arco Estimate $10,000 per gate
C22: Pedestrian Gate | D22: 2 | E22: ea | H22: 535 | I22: =D22*H22 -> 1070 | J22: =F22*H22 -> 0 | K22: =G22*H22 -> 0 | L22: Means 32 31 13 1400 Gate for 6" high fence 1-5/8" frame 3' wide 2" line post in concrete | M22: 12.30.24 Milton Arco Estimate $2,000 per gate
C23: Storage Container | D23: 1 | E23: ea | H23: 6500 | I23: =D23*H23 -> 6500 | J23: =F23*H23 -> 0 | K23: =G23*H23 -> 0
C24: Stone / Rock Overlay | D24: 415 | E24: ton | F24: 50 | G24: 0 | H24: 23 | I24: =D24*H24 -> 9545 | J24: =F24*H24 -> 1150 | K24: =G24*H24 -> 0 | L24: ARCO Milton Estimate - 12.30.24
C26: Subtotal | I26: =SUM(I4:I25) -> 236366.5 | J26: =SUM(J4:J25) -> 22472 | K26: =SUM(K4:K25) -> 0
C27: Site Utilities | D27: QTY | E27: UOM | F27: Addtl 800 | G27: Addtl 1200 | H27: Cost | I27: Total | J27: Addtl 800 | K27: Addtl 1200 | L27: Notes | M27: Additional Notes
C28: Fire Suppression / Hydrant | J28: =F28*H28 -> 0 | K28: =G28*H28 -> 0
C29: Fire Hydrant 4" | D29: 1 | E29: ea | H29: 3950 | I29: =D29*H29 -> 3950 | J29: =F29*H29 -> 0 | K29: =G29*H29 -> 0 | L29: RS Means 33 14 19.30 1170
C30: 4" Water Line | D30: 250 | E30: lf | F30: 25 | G30: 0 | H30: 138 | I30: =D30*H30 -> 34500 | J30: =F30*H30 -> 3450 | K30: =G30*H30 -> 0 | L30: RS Means 33 14 13.15 2020 (Pipe, Class 50 Ducticle Iron)
C31: Nat Gas Supply | J31: =F31*H31 -> 0 | K31: =G31*H31 -> 0
C32: Nat Gas Metering | D32: 1 | E32: ls | H32: 10000 | I32: =D32*H32 -> 10000 | J32: =F32*H32 -> 0 | K32: =G32*H32 -> 0 | L32: ARCO Milton Estimate - 12.30.24
C33: Nat Gas Piping | D33: 325 | E33: l.f. | F33: 100 | G33: 0 | H33: 95 | I33: =D33*H33 -> 30875 | J33: =F33*H33 -> 9500 | K33: =G33*H33 -> 0 | L33: ARCO Milton Estimate - 12.30.24
C34: Septic Tank / System | J34: =F34*H34 -> 0 | K34: =G34*H34 -> 0
C35: 5000 Gallon, precast | D35: 1 | E35: ls | H35: 10000 | I35: =D35*H35 -> 10000 | J35: =F35*H35 -> 0 | K35: =G35*H35 -> 0 | L35: Tank $5000 RS Means 33 34 12 0200 + Excavation / Backfill $5000
C36: 4" Sanitary Line + Backfill | D36: 125 | E36: l.f. | F36: 50 | G36: 0 | H36: =94+22.5 -> 116.5 | I36: =D36*H36 -> 14562.5 | J36: =F36*H36 -> 5825 | K36: =G36*H36 -> 0 | L36: ARCO Milton Estimate - 12.30.24
C37: Domestic Water | J37: =F37*H37 -> 0 | K37: =G37*H37 -> 0
C38: Water Metering | D38: 1 | E38: ls | H38: 15500 | I38: =D38*H38 -> 15500 | J38: =F38*H38 -> 0 | K38: =G38*H38 -> 0 | L38: ARCO Milton Estimate - 12.30.24
C39: 2" Water Line | D39: 100 | E39: l.f. | F39: 100 | G39: 0 | H39: 77 | I39: =D39*H39 -> 7700 | J39: =F39*H39 -> 7700 | K39: =G39*H39 -> 0 | L39: ARCO Milton Estimate - 12.30.24
C40: Valves | D40: 4 | E40: ea | H40: 1750 | I40: =D40*H40 -> 7000 | J40: =F40*H40 -> 0 | K40: =G40*H40 -> 0 | L40: Mark ROM
C41: Storm Water Piping | D41: 1 | E41: ls | H41: 10000 | I41: =D41*H41 -> 10000 | J41: =F41*H41 -> 0 | K41: =G41*H41 -> 0
C43: Subtotal | I43: =SUM(I28:I42) -> 144087.5 | J43: =SUM(J28:J42) -> 26475 | K43: =SUM(K28:K42) -> 0
...

Sheet Sales Tax and Escalation
B2: 2024 Sales Tax Rates by State (July) | State & Local Sales Taxes | J2: Chosen State | K2: PPI Commodity data for Final demand-Construction for private capital investment, seasonally adjusted WPSFD431 | Y2: CPI All items in U.S. city average, all urban consumers, not seasonally adjusted CUUR0000SA0 (Adjusted by -116.33)
B3: State | D3: State Tax Rate | E3: State Tax Rank | F3: Avg. Local Tax Rate | G3: Combined Rate | H3: Combined Rank | I3: Max Local Tax Rate | J3: 37 | K3: Year | L3: Jan | M3: Feb | N3: Mar | O3: Apr | P3: May | Q3: Jun | R3: Jul | S3: Aug | T3: Sep | U3: Oct | V3: Nov | W3: Dec | Y3: Year | Z3: Jan | AA3: Feb | AB3: Mar | AC3: Apr | AD3: May | AE3: Jun | AF3: Jul | AG3: Aug | AH3: Sep | AI3: Oct | AJ3: Nov | AK3: Dec
B4: Alabama | C4: 1 | D4: 0.04 | E4: 40 | F4: 0.05289 | G4: 0.09289 | H4: 5 | I4: 0.075 | J4: Tax Exempt? | K4: 2009 | V4: 100 | W4: 99.9 | Y4: 2009 | Z4: 94.813 | AA4: 95.863 | AB4: 96.379 | AC4: 96.91 | AD4: 97.526 | AE4: 99.363 | AF4: 99.021 | AG4: 99.504 | AH4: 99.639 | AI4: 99.847 | AJ4: 100 | AK4: 99.619
B5: Alaska | C5: 2 | D5: 0 | E5: 46 | F5: 0.01821 | G5: 0.01821 | H5: 46 | I5: 0.0785 | J5: 1 | K5: 2010 | L5: 100 | M5: 100 | N5: 99.8 | O5: 100 | P5: 99.9 | Q5: 99.9 | R5: 100 | S5: 99.9 | T5: 99.9 | U5: 100.3 | V5: 100.1 | W5: 100.2 | Y5: 2010 | Z5: 100.357 | AA5: 100.411 | AB5: 101.301 | AC5: 101.679 | AD5: 101.848 | AE5: 101.635 | AF5: 101.681 | AG5: 101.982 | AH5: 102.109 | AI5: 102.381 | AJ5: 102.473 | AK5: 102.849
B6: Arizona | C6: 3 | D6: 0.056 | E6: 28 | F6: 0.02783 | G6: 0.08383 | H6: 12 | I6: 0.053 | K6: 2011 | L6: 100.6 | M6: 100.6 | N6: 100.6 | O6: 101.5 | P6: 101.4 | Q6: 101.4 | R6: 102.6 | S6: 102.6 | T6: 102.6 | U6: 104 | V6: 104.1 | W6: 104 | Y6: 2011 | Z6: 103.893 | AA6: 104.979 | AB6: 107.137 | AC6: 108.576 | AD6: 109.634 | AE6: 109.392 | AF6: 109.592 | AG6: 110.215 | AH6: 110.559 | AI6: 110.091 | AJ6: 109.9 | AK6: 109.342
B7: Arkansas | C7: 4 | D7: 0.065 | E7: 9 | F7: 0.02969 | G7: 0.09469 | H7: 3 | I7: 0.06125 | K7: 2012 | L7: 104.7 | M7: 104.7 | N7: 104.8 | O7: 105.3 | P7: 105.4 | Q7: 105.4 | R7: 105.4 | S7: 105.4 | T7: 105.3 | U7: 105.6 | V7: 105.5 | W7: 105.6 | Y7: 2012 | Z7: 110.335 | AA7: 111.333 | AB7: 113.062 | AC7: 113.755 | AD7: 113.485 | AE7: 113.148 | AF7: 112.774 | AG7: 114.049 | AH7: 115.077 | AI7: 114.987 | AJ7: 113.891 | AK7: 113.271
B8: California (a) | C8: 5 | D8: 0.0725 | E8: 1 | F8: 0.01552 | G8: 0.08802 | H8: 8 | I8: 0.0475 | K8: 2013 | L8: 106.2 | M8: 106.1 | N8: 106.1 | O8: 106.5 | P8: 106.7 | Q8: 106.7 | R8: 107.3 | S8: 107.3 | T8: 107.5 | U8: 108.9 | V8: 108.9 | W8: 109.1 | Y8: 2013 | Z8: 113.95 | AA8: 115.836 | AB8: 116.443 | AC8: 116.201 | AD8: 116.615 | AE8: 117.174 | AF8: 117.266 | AG8: 117.547 | AH8: 117.819 | AI8: 117.216 | AJ8: 116.739 | AK8: 116.719
B9: Colorado | C9: 6 | D9: 0.029 | E9: 45 | F9: 0.04907 | G9: 0.07807 | H9: 16 | I9: 0.083 | K9: 2014 | L9: 109.7 | M9: 109.7 | N9: 109.8 | O9: 110.1 | P9: 110.1 | Q9: 110.2 | R9: 110.6 | S9: 110.7 | T9: 110.7 | U9: 111.3 | V9: 111.2 | W9: 111.4 | Y9: 2014 | Z9: 117.586 | AA9: 118.451 | AB9: 119.963 | AC9: 120.742 | AD9: 121.57 | AE9: 122.013 | AF9: 121.92 | AG9: 121.522 | AH9: 121.701 | AI9: 121.103 | AJ9: 119.821 | AK9: 118.482
B10: Connecticut | C10: 7 | D10: 0.0635 | E10: 12 | F10: 0 | G10: 0.0635 | H10: 33 | I10: 0 | K10: 2015 | L10: 112 | M10: 112 | N10: 112 | O10: 111.9 | P10: 112 | Q10: 112 | R10: 112.7 | S10: 112.7 | T10: 112.7 | U10: 113.7 | V10: 113.6 | W10: 113.6 | Y10: 2015 | Z10: 117.377 | AA10: 118.392 | AB10: 119.789 | AC10: 120.269 | AD10: 121.475 | AE10: 122.308 | AF10: 122.324 | AG10: 121.986 | AH10: 121.615 | AI10: 121.508 | AJ10: 121.006 | AK10: 120.195
B11: Delaware | C11: 8 | D11: 0 | E11: 46 | F11: 0 | G11: 0 | H11: 47 | I11: 0 | K11: 2016 | L11: 113.3 | M11: 113.2 | N11: 113.1 | O11: 114.2 | P11: 114.2 | Q11: 114.2 | R11: 113.6 | S11: 113.6 | T11: 113.6 | U11: 114.6 | V11: 114.5 | W11: 114.5 | Y11: 2016 | Z11: 120.586 | AA11: 120.781 | AB11: 121.802 | AC11: 122.931 | AD11: 123.899 | AE11: 124.688 | AF11: 124.298 | AG11: 124.519 | AH11: 125.098 | AI11: 125.399 | AJ11: 125.023 | AK11: 125.102
B12: Florida | C12: 9 | D12: 0.06 | E12: 17 | F12: 0.01002 | G12: 0.07002 | H12: 24 | I12: 0.02 | K12: 2017 | L12: 114.8 | M12: 114.9 | N12: 114.9 | O12: 115.5 | P12: 115.6 | Q12: 115.7 | R12: 117.2 | S12: 117.2 | T12: 117.2 | U12: 117.9 | V12: 117.9 | W12: 118 | Y12: 2017 | Z12: 126.509 | AA12: 127.273 | AB12: 127.471 | AC12: 128.194 | AD12: 128.403 | AE12: 128.625 | AF12: 128.456 | AG12: 129.189 | AH12: 130.489 | AI12: 130.333 | AJ12: 130.339 | AK12: 130.194
B13: Georgia | C13: 10 | D13: 0.04 | E13: 40 | F13: 0.03423 | G13: 0.07423 | H13: 19 | I13: 0.05 | K13: 2018 | L13: 118.9 | M13: 119 | N13: 119 | O13: 120.4 | P13: 120.5 | Q13: 120.8 | R13: 121.4 | S13: 121.5 | T13: 121.6 | U13: 123.9 | V13: 124.2 | W13: 124.3 | Y13: 2018 | Z13: 131.537 | AA13: 132.661 | AB13: 133.224 | AC13: 134.216 | AD13: 135.258 | AE13: 135.659 | AF13: 135.676 | AG13: 135.816 | AH13: 136.109 | AI13: 136.555 | AJ13: 135.708 | AK13: 134.903
B14: Hawaii (b) | C14: 11 | D14: 0.04 | E14: 40 | F14: 0.005 | G14: 0.045 | H14: 45 | I14: 0.005 | K14: 2019 | L14: 125.2 | M14: 125.2 | N14: 125.3 | O14: 127 | P14: 127.1 | Q14: 127.1 | R14: 128.1 | S14: 128.1 | T14: 128.3 | U14: 128.8 | V14: 128.9 | W14: 129 | Y14: 2019 | Z14: 135.382 | AA14: 136.446 | AB14: 137.872 | AC14: 139.218 | AD14: 139.762 | AE14: 139.813 | AF14: 140.241 | AG14: 140.228 | AH14: 140.429 | AI14: 141.016 | AJ14: 140.878 | AK14: 140.644
B15: Idaho | C15: 12 | D15: 0.06 | E15: 17 | F15: 0.00027 | G15: 0.06027 | H15: 37 | I15: 0.03 | K15: 2020 | L15: 129.7 | M15: 129.9 | N15: 129.8 | O15: 130.5 | P15: 130.5 | Q15: 130.4 | R15: 131.1 | S15: 130.8 | T15: 130.6 | U15: 130.6 | V15: 130.7 | W15: 130.7 | Y15: 2020 | Z15: 141.641 | AA15: 142.348 | AB15: 141.785 | AC15: 140.059 | AD15: 140.064 | AE15: 141.467 | AF15: 142.771 | AG15: 143.588 | AH15: 143.95 | AI15: 144.058 | AJ15: 143.899 | AK15: 144.144
B16: Illinois | C16: 13 | D16: 0.0625 | E16: 13 | F16: 0.02621 | G16: 0.08871 | H16: 7 | I16: 0.0475 | K16: 2021 | L16: 131.1 | M16: 131.3 | N16: 131.9 | O16: 133.7 | P16: 134.6 | Q16: 134.7 | R16: 137.196 | S16: 137.556 | T16: 137.772 | U16: 147.209 | V16: 147.757 | W16: 148.195 | Y16: 2021 | Z16: 145.252 | AA16: 146.684 | AB16: 148.547 | AC16: 150.724 | AD16: 152.865 | AE16: 155.366 | AF16: 156.673 | AG16: 157.237 | AH16: 157.98 | AI16: 160.259 | AJ16: 161.618 | AK16: 162.472
B17: Indiana | C17: 14 | D17: 0.07 | E17: 2 | F17: 0 | G17: 0.07 | H17: 25 | I17: 0 | K17: 2022 | L17: 153.666 | M17: 154.632 | N17: 155.532 | O17: 161.477 | P17: 162.062 | Q17: 163.025 | R17: 172.019 | S17: 172.298 | T17: 172.658 | U17: 177.229 | V17: 177.358 | W17: 177.474 | Y17: 2022 | Z17: 164.818 | AA17: 167.386 | AB17: 171.174 | AC17: 172.779 | AD17: 175.966 | AE17: 179.981 | AF17: 179.946 | AG17: 179.841 | AH17: 180.478 | AI17: 181.682 | AJ17: 181.381 | AK17: 180.467
... B19: Kansas | C19: 16 | D19: 0.065 | E19: 9 | F19: 0.02276 | G19: 0.08776 | H19: 9 | I19: 0.0425 | K19: 2024 | L19: 178.761 | M19: 178.693 | N19: 178.907 | O19: 178.874 | P19: 178.997 | Q19: 179.66 | R19: 180.747 | S19: 180.675 | T19: 180.911 | U19: 180.411 | V19: 180.436 | W19: 180.75 | Y19: 2024 | Z19: 192.087 | AA19: 193.996 | AB19: 196.002 | AC19: 197.218 | AD19: 197.739 | AE19: 197.845 | AF19: 198.21 | AG19: 198.466 | AH19: 198.971 | AI19: 199.334 | AJ19: 199.163 | AK19: 199.275
B20: Kentucky | C20: 17 | D20: 0.06 | E20: 17 | F20: 0 | G20: 0.06 | H20: 38 | I20: 0 | K20: 2025 | L20: 181.291 | M20: 181.09 | Y20: 2025 | Z20: 201.341 | AA20: 202.752
B21: Louisiana | C21: 18 | D21: 0.0445 | E21: 37 | F21: 0.05115 | G21: 0.09565 | H21: 1 | I21: 0.07 | K21: 2026 | Y21: 2026
B22: Maine | C22: 19 | D22: 0.055 | E22: 29 | F22: 0 | G22: 0.055 | H22: 43 | I22: 0
B23: Maryland | C23: 20 | D23: 0.06 | E23: 17 | F23: 0 | G23: 0.06 | H23: 38 | I23: 0 | K23: P : Preliminary. All indexes are subject to monthly revisions up to four months after original publication.
B24: Massachusetts | C24: 21 | D24: 0.0625 | E24: 13 | F24: 0 | G24: 0.0625 | H24: 35 | I24: 0
B25: Michigan | C25: 22 | D25: 0.06 | E25: 17 | F25: 0 | G25: 0.06 | H25: 38 | I25: 0 | K25: Date | L25: Value | M25: Date | N25: Value
B26: Minnesota | C26: 23 | D26: 0.0688 | E26: 6 | F26: 0.01248 | G26: 0.08123 | H26: 15 | I26: 0.03 | K26: 40118 | L26: 100 | M26: 39814 | N26: 94.813
B27: Mississippi | C27: 24 | D27: 0.07 | E27: 2 | F27: 0.00062 | G27: 0.07062 | H27: 22 | I27: 0.01 | K27: 40148 | L27: 99.9 | M27: 39845 | N27: 95.863
B28: Missouri | C28: 25 | D28: 0.04225 | E28: 38 | F28: 0.04161 | G28: 0.08386 | H28: 11 | I28: 0.05875 | K28: 40179 | L28: 100 | M28: 39873 | N28: 96.379
B29: Montana (c) | C29: 26 | D29: 0 | E29: 46 | F29: 0 | G29: 0 | H29: 47 | I29: 0 | K29: 40210 | L29: 100 | M29: 39904 | N29: 96.91
B30: Nebraska | C30: 27 | D30: 0.055 | E30: 29 | F30: 0.01469 | G30: 0.06969 | H30: 28 | I30: 0.02 | K30: 40238 | L30: 99.8 | M30: 39934 | N30: 97.526
