Workbook
Name \F: #REF!
Name _DAT1: #REF!
Name _DAT10: #REF!
Name _DAT11: #REF!
Name _DAT12: #REF!
Name _DAT13: #REF!
Name _DAT14: #REF!
Name _DAT15: #REF!
Name _DAT16: #REF!
Name _DAT17: #REF!
Name _DAT2: #REF!
Name _DAT3: #REF!
Name _DAT4: #REF!
Name _DAT5: #REF!
Name _DAT6: #REF!
Name _DAT7: #REF!
Name _DAT8: #REF!
Name _DAT9: #REF!
Name BRM_Total: '[1]Reference NLA '!#REF!
Name Controls: '[1]Reference NLA '!#REF!
Name ConversionList: #REF!
Name CPI: #REF!
Name DATA1: #REF!
Name DATA10: #REF!
Name DATA11: #REF!
Name DATA12: #REF!
Name DATA13: #REF!
Name DATA14: #REF!
Name DATA15: #REF!
Name DATA16: #REF!
Name DATA17: #REF!
Name DATA2: #REF!
Name DATA3: #REF!
Name DATA4: #REF!
Name DATA5: #REF!
Name DATA6: #REF!
Name DATA7: #REF!
Name DATA8: #REF!
Name DATA9: #REF!
Name dfhdhdhdhfd: #REF!
Name Display_Week: #REF!
Name IRR_: #REF!
Name IRR_Base: [2]MODEL!$G$4
Name IRR_Base: [3]MODEL!$G$4
Name MMBtu: #REF!
Name Names: #REF!
Name Options: '[1]Reference NLA '!#REF!
Name price_sens: [2]MODEL!$G$157
Name price_sens: [3]MODEL!$G$157
Name Project_Start: #REF!
Name ProjIRR: [4]Model!$D$80
Name s: #REF!
Name sfdsfsfdsfsfsd: #REF!
Name TeCO2: #REF!
Name TEST0: #REF!
Name TESTHKEY: #REF!
Name TESTKEYS: #REF!
Name TESTVKEY: #REF!
Name Unit_Table: #REF!
Name vol_sens: [2]MODEL!$G$156

Sheet INPUTS
L1: Proposal over Proposal Changes
E3: {=INDEX($G3:$N3,1,$E$4)} -> 70/90 Tiered 1250/$2.82 BID 11.21 | G3: =H3 -> 70/90 Tiered 1250/$2.82 BID 11.21 | H3: =I3 -> 70/90 Tiered 1250/$2.82 BID 11.21 | I3: =J3 -> 70/90 Tiered 1250/$2.82 BID 11.21 | J3: =K3 -> 70/90 Tiered 1250/$2.82 BID 11.21 | K3: 70/90 Tiered 1250/$2.82 BID 11.21 | L3: [Open] | M3: [Open]
C4: Scenario Selection --> | E4: 5 | G4: 1 | H4: 2 | I4: 3 | J4: 4 | K4: 5 | L4: 6 | M4: 7
C6: CPI Escalator | E6: 0.025
C8: Year 1 Biogas | D8: scfm | E8: {=INDEX($G8:$N8,1,$E$4)} -> 950 | G8: 950 | H8: 950 | I8: 950 | J8: 950 | K8: 950
C9: Annual CAGR | E9: {=INDEX($G9:$N9,1,$E$4)} -> 0.02434 | G9: 0.02434 | H9: 0.02434 | I9: 0.02434 | J9: 0.02434 | K9: 0.02434
C10: Year 20 (result) | D10: scfm | E10: =Model!AA11 -> 1500.2447
C12: Uptime | E12: {=INDEX($G12:$N12,1,$E$4)} -> 0.98 | G12: 0.98 | H12: 0.98 | I12: 0.98 | J12: 0.98 | K12: 0.98
C13: Capture | E13: {=INDEX($G13:$N13,1,$E$4)} -> 0.97906432 | G13: 0.97906432 | H13: 0.97906432 | I13: 0.97906432 | J13: 0.97906432 | K13: 0.97906432
C14: Btu/scf | E14: {=INDEX($G14:$N14,1,$E$4)} -> 666.68382 | G14: 666.68382 | H14: 666.68382 | I14: 666.68382 | J14: 666.68382 | K14: 666.68382
C16: Use Ares Curve? | E16: {=INDEX($G16:$N16,1,$E$4)} -> 1 | G16: 1 | H16: 1 | I16: 1 | J16: 1 | K16: 1
C17: D3 RIN | D17: $/RIN | E17: {=INDEX($G17:$N17,1,$E$4)} -> 2.39 | G17: 2.39 | H17: 2.39 | I17: 2.39 | J17: 2.39 | K17: 2.39
C18: RIN price escalator | E18: {=INDEX($G18:$N18,1,$E$4)} -> 0.01 | G18: 0.01 | H18: 0.01 | I18: 0.01 | J18: 0.01 | K18: 0.01
C19: Brokerage | E19: {=INDEX($G19:$N19,1,$E$4)} -> 0.2 | G19: 0.2 | H19: 0.2 | I19: 0.2 | J19: 0.2 | K19: 0.2
C21: Used Gas Curve? | E21: {=INDEX($G21:$N21,1,$E$4)} -> 1 | G21: 1 | H21: 1 | I21: 1 | J21: 1 | K21: 1
C22: Nat. Gas Year 1 Price | D22: $/MMBtu | E22: {=INDEX($G22:$N22,1,$E$4)} -> 3.0390412 | G22: 3.0390412 | H22: 3.0390412 | I22: 3.0390412 | J22: 3.0390412 | K22: 3.0390412
C23: Nat. Gas Price escalator | E23: {=INDEX($G23:$N23,1,$E$4)} -> 0.03 | G23: 0.03 | H23: 0.03 | I23: 0.03 | J23: 0.03 | K23: 0.03
C24: Wheel/hub cost | D24: $/MMBtu | E24: 1 | S24: =+E32 -> 36835
S25: =+Model!E38 -> 53083.042
C26: Min. Royalty | D26: $K | E26: {=INDEX($G26:$N26,1,$E$4)} -> 1000 | G26: 1000 | H26: 1000 | I26: 1000 | J26: 1000 | K26: 1000 | S26: =-Model!E59 -> 12369.017
S27: =SUM(S24:S26) -> 102287.06
C28: Base Royalty % | E28: {=INDEX($G28:$N28,1,$E$4)} -> 0.7 | G28: 0.7 | H28: 0.7 | I28: 0.7 | J28: 0.7 | K28: 0.7 | S28: =+S27/20 -> 5114.353
C29: Bonus Royalty % | E29: {=INDEX($G29:$N29,1,$E$4)} -> 0.9 | G29: 0.9 | H29: 0.9 | I29: 0.9 | J29: 0.9 | K29: 0.9
C30: Tier 2 RIN Trigger | E30: {=INDEX($G30:$N30,1,$E$4)} -> 2.82 | G30: 2.82 | H30: 2.82 | I30: 2.82 | J30: 2.82 | K30: 2.82
C31: Tier 2 SCFM Trigger | E31: {=INDEX($G31:$N31,1,$E$4)} -> 1250 | G31: 1250 | H31: 1250 | I31: 1250 | J31: 1250 | K31: 1250
C32: Capital Cost Allowance | E32: {=INDEX($G32:$N32,1,$E$4)} -> 36835 | G32: 36835 | H32: 36835 | I32: 36835 | J32: 36835 | K32: 36835
C33: Capital Cost Financing Fee | E33: {=INDEX($G33:$N33,1,$E$4)} -> 9208.75 | G33: 9208.75 | H33: 9208.75 | I33: 9208.75 | J33: 9208.75 | K33: 9208.75
C34: Opex and Maintenance Allowance | E34: {=INDEX($G34:$N34,1,$E$4)} -> 51911.25 | G34: 51911.25 | H34: 51911.25 | I34: 51911.25 | J34: 51911.25 | K34: 51911.25
C36: NTP Date | E36: 46203
C37: COD Date | D37: =YEAR(E37) -> 2027 | E37: =EOMONTH(E36,16) -> 46691
C38: Mid-construct | E38: =MEDIAN(E36:E37) -> 46447
C41: RIN/MMBtu | E41: 11.727
G43: =+G34-0.25*$E32 -> 42702.5 | H43: =+H34-0.25*$E32 -> 42702.5 | I43: =+I34-0.25*$E32 -> 42702.5 | J43: =+J34-0.25*$E32 -> 42702.5

Sheet Financial Summary
C1: =+INPUTS!E4 -> 5
B3: Nashville, $MM except noted | E3: TOTAL | G3: 1 | H3: 2 | I3: 3 | J3: 4 | K3: 5 | M3: 20
B4: Biogas Production | D4: scfm | G4: =+Model!H11 -> 950 | H4: =+Model!I11 -> 973.123 | I4: =+Model!J11 -> 996.80881 | J4: =+Model!K11 -> 1021.0711 | K4: =+Model!L11 -> 1045.924 | M4: =+Model!AA11 -> 1500.2447
B5: RNG Production | D5: K MMBtu | E5: =Model!E17/10^3 -> 8105 | G5: =+Model!H17/10^3 -> 319.40093 | H5: =+Model!I17/10^3 -> 327.17515 | I5: =+Model!J17/10^3 -> 335.13859 | J5: =+Model!K17/10^3 -> 343.29587 | K5: =+Model!L17/10^3 -> 351.65169 | M5: =+Model!AA17/10^3 -> 504.39955
B7: RIN EAs Value | E7: =+Model!E28/10^3 -> 299.56481 | G7: =+Model!H28/10^3 -> 9.9706695 | H7: =+Model!I28/10^3 -> 10.404666 | I7: =+Model!J28/10^3 -> 10.970997 | J7: =+Model!K28/10^3 -> 11.739648 | K7: =+Model!L28/10^3 -> 12.281462 | M7: =+Model!AA28/10^3 -> 21.754387
B8: (-) RIN Brokerage | E8: =+Model!E29/10^3 -> -59.912961 | G8: =+Model!H29/10^3 -> -1.9941339 | H8: =+Model!I29/10^3 -> -2.0809333 | I8: =+Model!J29/10^3 -> -2.1941993 | J8: =+Model!K29/10^3 -> -2.3479297 | K8: =+Model!L29/10^3 -> -2.4562924 | M8: =+Model!AA29/10^3 -> -4.3508775
B9: (+) Nat. Gas Sales | E9: =+Model!E30/10^3 -> 34.481019 | G9: =+Model!H30/10^3 -> 1.0648827 | H9: =+Model!I30/10^3 -> 1.0695356 | I9: =+Model!J30/10^3 -> 1.1258897 | J9: =+Model!K30/10^3 -> 1.1851301 | K9: =+Model!L30/10^3 -> 1.2474025 | M9: =+Model!AA30/10^3 -> 2.6704954
B10: Total Offtake Revenue | D10: $MM | E10: =SUM(E7:E9) -> 274.13286 | G10: =SUM(G7:G9) -> 9.0414183 | H10: =SUM(H7:H9) -> 9.3932687 | I10: =SUM(I7:I9) -> 9.9026871 | J10: =SUM(J7:J9) -> 10.576849 | K10: =SUM(K7:K9) -> 11.072572 | L10: =SUM(L7:L9) -> 0 | M10: =SUM(M7:M9) -> 20.074005
D11: $/MMBtu | E11: =+E10*10^3/E$5 -> 33.822685 | G11: =+G10*10^3/G$5 -> 28.307426 | H11: =+H10*10^3/H$5 -> 28.710214 | I11: =+I10*10^3/I$5 -> 29.548036 | J11: =+J10*10^3/J$5 -> 30.809718 | K11: =+K10*10^3/K$5 -> 31.487328 | M11: =+M10*10^3/M$5 -> 39.797826
B13: Utilities | E13: =+Model!E34/10^3 -> 17.416658 | G13: =+Model!H34/10^3 -> 0.52701154 | H13: =+Model!I34/10^3 -> 0.55333497 | I13: =+Model!J34/10^3 -> 0.58097323 | J13: =+Model!K34/10^3 -> 0.60999197 | K13: =+Model!L34/10^3 -> 0.64046015 | M13: =+Model!AA34/10^3 -> 1.3304914
B14: (+) Consumables / R&M | E14: =+Model!E35/10^3 -> 8.9722175 | G14: =+Model!H35/10^3 -> 0.27149079 | H14: =+Model!I35/10^3 -> 0.28505135 | I14: =+Model!J35/10^3 -> 0.29928924 | J14: =+Model!K35/10^3 -> 0.31423829 | K14: =+Model!L35/10^3 -> 0.32993402 | M14: =+Model!AA35/10^3 -> 0.68540466
B15: (+) Asset Management | E15: =+Model!E36/10^3 -> 5.1089315 | G15: =+Model!H36/10^3 -> 0.2 | H15: =+Model!I36/10^3 -> 0.205 | I15: =+Model!J36/10^3 -> 0.210125 | J15: =+Model!K36/10^3 -> 0.21537812 | K15: =+Model!L36/10^3 -> 0.22076258 | M15: =+Model!AA36/10^3 -> 0.31973004
B16: (+) Fixed Expenses | E16: =+Model!E37/10^3 -> 21.585236 | G16: =+Model!H37/10^3 -> 0.845 | H16: =+Model!I37/10^3 -> 0.866125 | I16: =+Model!J37/10^3 -> 0.88777812 | J16: =+Model!K37/10^3 -> 0.90997258 | K16: =+Model!L37/10^3 -> 0.93272189 | M16: =+Model!AA37/10^3 -> 1.3508594
B17: Total Operating Expenses | D17: $MM | E17: =+Model!E38/10^3 -> 53.083042 | G17: =SUM(G13:G16) -> 1.8435023 | H17: =SUM(H13:H16) -> 1.9095113 | I17: =SUM(I13:I16) -> 1.9781656 | J17: =SUM(J13:J16) -> 2.049581 | K17: =SUM(K13:K16) -> 2.1238786 | M17: =SUM(M13:M16) -> 3.6864855
D18: $/MMBtu | E18: =+E17*10^3/E$5 -> 6.5494192 | G18: =+G17*10^3/G$5 -> 5.77175 | H18: =+H17*10^3/H$5 -> 5.836358 | I18: =+I17*10^3/I$5 -> 5.90253 | J18: =+J17*10^3/J$5 -> 5.9703048 | K18: =+K17*10^3/K$5 -> 6.0397226 | M18: =+M17*10^3/M$5 -> 7.3086614
B20: Royalty Calculation | D20: MWS Share
B21: Base | D21: =+Model!D46 -> 0.7 | G21: =+Model!H45/10^3 -> 4.1436683 | H21: =+Model!I45/10^3 -> 4.4955187 | I21: =+Model!J45/10^3 -> 5.0049371 | J21: =+Model!K45/10^3 -> 5.6790988 | K21: =+Model!L45/10^3 -> 6.1748221 | M21: =+Model!AA45/10^3 -> 15.176255
B22: Bonus | D22: 0.9 | G22: =+Model!H50/10^3 -> 0 | H22: =+Model!I50/10^3 -> 0 | I22: =+Model!J50/10^3 -> 0 | J22: =+Model!K50/10^3 -> 0 | K22: =+Model!L50/10^3 -> 0 | M22: =+Model!AA50/10^3 -> 0.50628781
B23: Total Royalty to MWS | D23: $MM | E23: =+Model!D52/10^3 -> 125.28608 | G23: =MAX(2,SUMPRODUCT(G21:G22,$D$21:$D$22)) -> 2.9005678 | H23: =MAX(2,SUMPRODUCT(H21:H22,$D$21:$D$22)) -> 3.1468631 | I23: =MAX(2,SUMPRODUCT(I21:I22,$D$21:$D$22)) -> 3.503456 | J23: =MAX(2,SUMPRODUCT(J21:J22,$D$21:$D$22)) -> 3.9753692 | K23: =MAX(2,SUMPRODUCT(K21:K22,$D$21:$D$22)) -> 4.3223754 | M23: =SUMPRODUCT(M21:M22,$D$21:$D$22) -> 11.079038
D24: $/MMBtu | E24: =+E23*10^3/E$5 -> 15.457875 | G24: =+G23*10^3/G$5 -> 9.0812753 | H24: =+H23*10^3/H$5 -> 9.6182826 | I24: =+I23*10^3/I$5 -> 10.453753 | J24: =+J23*10^3/J$5 -> 11.580009 | K24: =+K23*10^3/K$5 -> 12.291639 | M24: =+M23*10^3/M$5 -> 21.964805
B26: EBITDA | E26: =Model!E58/10^3 -> 95.763745 | G26: =+G10-G17-G23 -> 4.2973482 | H26: =+H10-H17-H23 -> 4.3368943 | I26: =+I10-I17-I23 -> 4.4210655 | J26: =+J10-J17-J23 -> 4.5518987 | K26: =+K10-K17-K23 -> 4.626318 | M26: =+Model!AA58/10^3 -> 5.2578533
B27: Capex | E27: =Model!E57/10^3 -> -36.835
B28: ITC Proceeds | E28: =Model!E60/10^3 -> 12.96592
B29: Mtce Capex | E29: =Model!E59/10^3 -> -12.369017
B31: IRR | E31: =+Model!D63 -> 0.1511144
B32: Build Multiple, net of ITC | E32: =-SUM(E27:E28)/I26 -> 5.3989428

Sheet Model
C3: NTP Date | E3: 46203
H6: {=_xlfn.SEQUENCE(1,20,0,1)} -> 0 | I6: 1 | J6: 2 | K6: 3 | L6: 4 | M6: 5 | N6: 6 | O6: 7 | P6: 8 | Q6: 9 | R6: 10 | S6: 11 | T6: 12 | U6: 13 | V6: 14 | W6: 15 | X6: 16 | Y6: 17 | Z6: 18 | AA6: 19
C7: Case | D7: =+INPUTS!E4 -> 5 | H7: =YEAR(H9) -> 2028 | I7: =YEAR(I9) -> 2029 | J7: =YEAR(J9) -> 2030 | K7: =YEAR(K9) -> 2031 | L7: =YEAR(L9) -> 2032 | M7: =YEAR(M9) -> 2033 | N7: =YEAR(N9) -> 2034 | O7: =YEAR(O9) -> 2035 | ... AA7: =YEAR(AA9) -> 2047
C8: IRR | D8: =+D63 -> 0.1511144 | H8: 1 | I8: =H8*(1+INPUTS!$E$6) -> 1.025 | J8: =I8*(1+INPUTS!$E$6) -> 1.050625 | K8: =J8*(1+INPUTS!$E$6) -> 1.0768906 | L8: =K8*(1+INPUTS!$E$6) -> 1.1038129 | M8: =L8*(1+INPUTS!$E$6) -> 1.1314082 | N8: =M8*(1+INPUTS!$E$6) -> 1.1596934 | O8: =N8*(1+INPUTS!$E$6) -> 1.1886858 | P8: =O8*(1+INPUTS!$E$6) -> 1.2184029 | ... AA8: =Z8*(1+INPUTS!$E$6) -> 1.5986502
G9: =+INPUTS!E38 -> 46447 | H9: =EOMONTH(INPUTS!E37,6) -> 46873 | I9: =EOMONTH(H9,12) -> 47238 | J9: =EOMONTH(I9,12) -> 47603 | K9: =EOMONTH(J9,12) -> 47968 | L9: =EOMONTH(K9,12) -> 48334 | M9: =EOMONTH(L9,12) -> 48699 | N9: =EOMONTH(M9,12) -> 49064 | O9: =EOMONTH(N9,12) -> 49429 | P9: =EOMONTH(O9,12) -> 49795 | ... AA9: =EOMONTH(Z9,12) -> 53812
C10: $ in '000, except noted | G10: Year 0 | H10: Year 1 | I10: Year 2 | J10: Year 3 | K10: Year 4 | L10: Year 5 | M10: Year 6 | N10: Year 7 | O10: Year 8 | P10: Year 9 | Q10: Year 10 | R10: Year 11 | S10: Year 12 | T10: Year 13 | U10: Year 14 | V10: Year 15 | W10: Year 16 | X10: Year 17 | Y10: Year 18 | Z10: Year 19 | AA10: Year 20
C11: Biogas | D11: scfm | H11: =INPUTS!E8 -> 950 | I11: =H11*(1+INPUTS!$E$9) -> 973.123 | J11: =I11*(1+INPUTS!$E$9) -> 996.80881 | K11: =J11*(1+INPUTS!$E$9) -> 1021.0711 | L11: =K11*(1+INPUTS!$E$9) -> 1045.924 | M11: =L11*(1+INPUTS!$E$9) -> 1071.3818 | N11: =M11*(1+INPUTS!$E$9) -> 1097.4592 | O11: =N11*(1+INPUTS!$E$9) -> 1124.1714 | P11: =O11*(1+INPUTS!$E$9) -> 1151.5337 | ... AA11: =Z11*(1+INPUTS!$E$9) -> 1500.2447
C12: Biogas | D12: scf/d | H12: =H11*(24*60) -> 1368000 | I12: =I11*(24*60) -> 1401297.1 | J12: =J11*(24*60) -> 1435404.7 | K12: =K11*(24*60) -> 1470342.4 | L12: =L11*(24*60) -> 1506130.6 | M12: =M11*(24*60) -> 1542789.8 | N12: =N11*(24*60) -> 1580341.3 | O12: =O11*(24*60) -> 1618806.8 | ... AA12: =AA11*(24*60) -> 2160352.4
C13: Theor. RNG | D13: MMBtu/d | E13: =INPUTS!$E$14 -> 666.68382 | H13: =$E$13*H12/10^6 -> 912.02347 | I13: =$E$13*I12/10^6 -> 934.22212 | J13: =$E$13*J12/10^6 -> 956.96108 | K13: =$E$13*K12/10^6 -> 980.25352 | L13: =$E$13*L12/10^6 -> 1004.1129 | M13: =$E$13*M12/10^6 -> 1028.553 | N13: =$E$13*N12/10^6 -> 1053.588 | O13: =$E$13*O12/10^6 -> 1079.2323 | ... AA13: =$E$13*AA12/10^6 -> 1440.272
C14: Theor. RNG | D14: MMBtu | E14: =SUM(H14:AA14) -> 8447257.2 | H14: =H13*365 -> 332888.57 | I14: =I13*365 -> 340991.07 | J14: =J13*365 -> 349290.8 | K14: =K13*365 -> 357792.53 | L14: =L13*365 -> 366501.2 | M14: =M13*365 -> 375421.84 | N14: =N13*365 -> 384559.61 | O14: =O13*365 -> 393919.79 | ... AA14: =AA13*365 -> 525699.29
C15: Uptime | H15: =INPUTS!$E$12 -> 0.98 | I15: =H15 -> 0.98 | J15: =I15 -> 0.98 | K15: =J15 -> 0.98 | L15: =K15 -> 0.98 | M15: =L15 -> 0.98 | N15: =M15 -> 0.98 | O15: =N15 -> 0.98 | P15: =O15 -> 0.98 | ... AA15: =Z15 -> 0.98
C16: Capture | D16: mult.--> | E16: 1 | H16: =INPUTS!$E$13 -> 0.97906432 | I16: =H16 -> 0.97906432 | J16: =I16 -> 0.97906432 | K16: =J16 -> 0.97906432 | L16: =K16 -> 0.97906432 | M16: =L16 -> 0.97906432 | N16: =M16 -> 0.97906432 | O16: =N16 -> 0.97906432 | P16: =O16 -> 0.97906432 | ... AA16: =Z16 -> 0.97906432
C17: Net RNG Production | D17: MMBtu | E17: =SUM(H17:AA17) -> 8105000 | H17: =PRODUCT(H14:H16)*$E$16 -> 319400.93 | I17: =PRODUCT(I14:I16)*$E$16 -> 327175.15 | J17: =PRODUCT(J14:J16)*$E$16 -> 335138.59 | K17: =PRODUCT(K14:K16)*$E$16 -> 343295.87 | L17: =PRODUCT(L14:L16)*$E$16 -> 351651.69 | M17: =PRODUCT(M14:M16)*$E$16 -> 360210.89 | N17: =PRODUCT(N14:N16)*$E$16 -> 368978.42 | O17: =PRODUCT(O14:O16)*$E$16 -> 377959.36 | ... AA17: =PRODUCT(AA14:AA16)*$E$16 -> 504399.55
B19: =INPUTS!E16 -> 1 | C19: Ares Curve D3 RIN | D19: adder--> | E19: 0 | H19: =_xlfn.XLOOKUP(H7,'RIN Curves'!$G$18:$G$44,'RIN Curves'!$H$18:$H$44)+$E$19 -> 2.6619581 | I19: =_xlfn.XLOOKUP(I7,'RIN Curves'!$G$18:$G$44,'RIN Curves'!$H$18:$H$44)+$E$19 -> 2.7118204 | J19: =_xlfn.XLOOKUP(J7,'RIN Curves'!$G$18:$G$44,'RIN Curves'!$H$18:$H$44)+$E$19 -> 2.7914813 | K19: =_xlfn.XLOOKUP(K7,'RIN Curves'!$G$18:$G$44,'RIN Curves'!$H$18:$H$44)+$E$19 -> 2.9160811 | L19: =_xlfn.XLOOKUP(L7,'RIN Curves'!$G$18:$G$44,'RIN Curves'!$H$18:$H$44)+$E$19 -> 2.9781765 | M19: =_xlfn.XLOOKUP(M7,'RIN Curves'!$G$18:$G$44,'RIN Curves'!$H$18:$H$44)+$E$19 -> 2.9101359 | N19: =_xlfn.XLOOKUP(N7,'RIN Curves'!$G$18:$G$44,'RIN Curves'!$H$18:$H$44)+$E$19 -> 2.8799224 | O19: =_xlfn.XLOOKUP(O7,'RIN Curves'!$G$18:$G$44,'RIN Curves'!$H$18:$H$44)+$E$19 -> 2.8742294 | ... AA19: =_xlfn.XLOOKUP(AA7,'RIN Curves'!$G$18:$G$44,'RIN Curves'!$H$18:$H$44)+$E$19 -> 3.6777758
C20: D3 RIN | D20: $/RIN | E20: =INPUTS!$E$17+$E$19 -> 2.39 | H20: =IF($B$19=0,E20,H19) -> 2.6619581 | I20: =IF($B$19=0,H20*(1+INPUTS!$E$18),I19) -> 2.7118204 | J20: =IF($B$19=0,I20*(1+INPUTS!$E$18),J19) -> 2.7914813 | K20: =IF($B$19=0,J20*(1+INPUTS!$E$18),K19) -> 2.9160811 | L20: =IF($B$19=0,K20*(1+INPUTS!$E$18),L19) -> 2.9781765 | M20: =IF($B$19=0,L20*(1+INPUTS!$E$18),M19) -> 2.9101359 | N20: =IF($B$19=0,M20*(1+INPUTS!$E$18),N19) -> 2.8799224 | O20: =IF($B$19=0,N20*(1+INPUTS!$E$18),O19) -> 2.8742294 | P20: =IF($B$19=0,O20*(1+INPUTS!$E$18),P19) -> 2.9338872 | ... AA20: =IF($B$19=0,Z20*(1+INPUTS!$E$18),AA19) -> 3.6777758
C21: D3 RIN | D21: $/MMBtu | H21: =H20*INPUTS!$E$41 -> 31.216783 | I21: =I20*INPUTS!$E$41 -> 31.801518 | J21: =J20*INPUTS!$E$41 -> 32.735701 | K21: =K20*INPUTS!$E$41 -> 34.196883 | L21: =L20*INPUTS!$E$41 -> 34.925076 | M21: =M20*INPUTS!$E$41 -> 34.127163 | N21: =N20*INPUTS!$E$41 -> 33.77285 | O21: =O20*INPUTS!$E$41 -> 33.706088 | ... AA21: =AA20*INPUTS!$E$41 -> 43.129276
B23: =+INPUTS!E21 -> 1 | C23: Nat. Gas Curve | H23: =_xlfn.XLOOKUP(H$7,HenryHub!$B$28:$B$52,HenryHub!$E$28:$E$52) -> 4.334 | I23: =_xlfn.XLOOKUP(I$7,HenryHub!$B$28:$B$52,HenryHub!$E$28:$E$52) -> 4.269 | J23: =_xlfn.XLOOKUP(J$7,HenryHub!$B$28:$B$52,HenryHub!$E$28:$E$52) -> 4.359475 | K23: =_xlfn.XLOOKUP(K$7,HenryHub!$B$28:$B$52,HenryHub!$E$28:$E$52) -> 4.4522119 | L23: =_xlfn.XLOOKUP(L$7,HenryHub!$B$28:$B$52,HenryHub!$E$28:$E$52) -> 4.5472672 | M23: =_xlfn.XLOOKUP(M$7,HenryHub!$B$28:$B$52,HenryHub!$E$28:$E$52) -> 4.6446989 | N23: =_xlfn.XLOOKUP(N$7,HenryHub!$B$28:$B$52,HenryHub!$E$28:$E$52) -> 4.7445663 | O23: =_xlfn.XLOOKUP(O$7,HenryHub!$B$28:$B$52,HenryHub!$E$28:$E$52) -> 4.8469305 | ... AA23: =_xlfn.XLOOKUP(AA$7,HenryHub!$B$28:$B$52,HenryHub!$E$28:$E$52) -> 6.2944049
C24: Nat. Gas | D24: $/MMBtu | E24: =INPUTS!E23 -> 0.03 | H24: =IF($B$23=1,H23,INPUTS!$E$22*(1+$E$24)^H6) -> 4.334 | I24: =IF($B$23=1,I23,INPUTS!$E$22*(1+$E$24)^I6) -> 4.269 | J24: =IF($B$23=1,J23,INPUTS!$E$22*(1+$E$24)^J6) -> 4.359475 | K24: =IF($B$23=1,K23,INPUTS!$E$22*(1+$E$24)^K6) -> 4.4522119 | L24: =IF($B$23=1,L23,INPUTS!$E$22*(1+$E$24)^L6) -> 4.5472672 | M24: =IF($B$23=1,M23,INPUTS!$E$22*(1+$E$24)^M6) -> 4.6446989 | N24: =IF($B$23=1,N23,INPUTS!$E$22*(1+$E$24)^N6) -> 4.7445663 | O24: =IF($B$23=1,O23,INPUTS!$E$22*(1+$E$24)^O6) -> 4.8469305 | ... AA24: =IF($B$23=1,AA23,INPUTS!$E$22*(1+$E$24)^AA6) -> 6.2944049
C25: (-) Wheel/hub cost | D25: $/MMBtu | H25: =-INPUTS!$E$24 -> -1 | I25: =H25 -> -1 | J25: =I25 -> -1 | K25: =J25 -> -1 | L25: =K25 -> -1 | M25: =L25 -> -1 | N25: =M25 -> -1 | O25: =N25 -> -1 | P25: =O25 -> -1 | ... AA25: =Z25 -> -1
C27: Offtake Revenue | E27: =E28+E30 -> 334045.83
C28: RIN Value | E28: =+SUM(H28:AA28) -> 299564.81 | H28: =+H21*H$17/10^3 -> 9970.6695 | I28: =+I21*I$17/10^3 -> 10404.666 | J28: =+J21*J$17/10^3 -> 10970.997 | K28: =+K21*K$17/10^3 -> 11739.648 | L28: =+L21*L$17/10^3 -> 12281.462 | M28: =+M21*M$17/10^3 -> 12292.976 | N28: =+N21*N$17/10^3 -> 12461.453 | O28: =+O21*O$17/10^3 -> 12739.531 | ... AA28: =+AA21*AA$17/10^3 -> 21754.387
B29: =INPUTS!E19 -> 0.2 | C29: (-) RIN Brokerage | E29: =+SUM(H29:AA29) -> -59912.961 | H29: =-$B$29*H28 -> -1994.1339 | I29: =-$B$29*I28 -> -2080.9333 | J29: =-$B$29*J28 -> -2194.1993 | K29: =-$B$29*K28 -> -2347.9297 | L29: =-$B$29*L28 -> -2456.2924 | M29: =-$B$29*M28 -> -2458.5952 | N29: =-$B$29*N28 -> -2492.2906 | O29: =-$B$29*O28 -> -2547.9062 | ... AA29: =-$B$29*AA28 -> -4350.8775
C30: (+) Nat Gas Value | E30: =+SUM(H30:AA30) -> 34481.019 | H30: =SUM(H24:H25)*H17/10^3 -> 1064.8827 | I30: =SUM(I24:I25)*I17/10^3 -> 1069.5356 | J30: =SUM(J24:J25)*J17/10^3 -> 1125.8897 | K30: =SUM(K24:K25)*K17/10^3 -> 1185.1301 | L30: =SUM(L24:L25)*L17/10^3 -> 1247.4025 | M30: =SUM(M24:M25)*M17/10^3 -> 1312.8602 | N30: =SUM(N24:N25)*N17/10^3 -> 1381.6642 | O30: =SUM(O24:O25)*O17/10^3 -> 1453.9834 | ... AA30: =SUM(AA24:AA25)*AA17/10^3 -> 2670.4954
C31: Net Offtake Revenue | E31: =+SUM(H31:AA31) -> 274132.86 | H31: =SUM(H28:H30) -> 9041.4183 | I31: =SUM(I28:I30) -> 9393.2687 | J31: =SUM(J28:J30) -> 9902.6871 | K31: =SUM(K28:K30) -> 10576.849 | L31: =SUM(L28:L30) -> 11072.572 | M31: =SUM(M28:M30) -> 11147.241 | N31: =SUM(N28:N30) -> 11350.826 | O31: =SUM(O28:O30) -> 11645.608 | ... AA31: =SUM(AA28:AA30) -> 20074.005
C33: Operating Expenses
B34: 1.65 | C34: Utilities | E34: =SUM(H34:AA34) -> 17416.658 | H34: =+$B34*H$8*H$17/10^3 -> 527.01154 | I34: =+$B$34*I8*I17/10^3 -> 553.33497 | J34: =+$B$34*J8*J17/10^3 -> 580.97323 | K34: =+$B$34*K8*K17/10^3 -> 609.99197 | L34: =+$B$34*L8*L17/10^3 -> 640.46015 | M34: =+$B$34*M8*M17/10^3 -> 672.45017 | N34: =+$B$34*N8*N17/10^3 -> 706.03805 | O34: =+$B$34*O8*O17/10^3 -> 741.30359 | P34: =+$B$34*P8*P17/10^3 -> 778.3306 | ... AA34: =+$B$34*AA8*AA17/10^3 -> 1330.4914
B35: 0.85 | C35: (+) Consumables / R&M | E35: =SUM(H35:AA35) -> 8972.2175 | H35: =+$B35*H$8*H$17/10^3 -> 271.49079 | I35: =+$B35*I$8*I$17/10^3 -> 285.05135 | J35: =+$B35*J$8*J$17/10^3 -> 299.28924 | K35: =+$B35*K$8*K$17/10^3 -> 314.23829 | L35: =+$B35*L$8*L$17/10^3 -> 329.93402 | M35: =+$B35*M$8*M$17/10^3 -> 346.41373 | N35: =+$B35*N$8*N$17/10^3 -> 363.71657 | O35: =+$B35*O$8*O$17/10^3 -> 381.88367 | ... AA35: =+$B35*AA$8*AA$17/10^3 -> 685.40466
B36: 200 | C36: (+) Asset Management | E36: =SUM(H36:AA36) -> 5108.9315 | H36: =+$B36*H$8 -> 200 | I36: =+$B36*I$8 -> 205 | J36: =+$B36*J$8 -> 210.125 | K36: =+$B36*K$8 -> 215.37812 | L36: =+$B36*L$8 -> 220.76258 | M36: =+$B36*M$8 -> 226.28164 | N36: =+$B36*N$8 -> 231.93868 | O36: =+$B36*O$8 -> 237.73715 | ... AA36: =+$B36*AA$8 -> 319.73004
B37: 845 | C37: (+) Fixed Expenses | E37: =SUM(H37:AA37) -> 21585.236 | H37: =+$B37*H$8 -> 845 | I37: =+$B37*I$8 -> 866.125 | J37: =+$B37*J$8 -> 887.77812 | K37: =+$B37*K$8 -> 909.97258 | L37: =+$B37*L$8 -> 932.72189 | M37: =+$B37*M$8 -> 956.03994 | N37: =+$B37*N$8 -> 979.94094 | O37: =+$B37*O$8 -> 1004.4395 | ... AA37: =+$B37*AA$8 -> 1350.8594
C38: TOTAL | E38: =SUM(H38:AA38) -> 53083.042 | H38: =SUM(H34:H37) -> 1843.5023 | I38: =SUM(I34:I37) -> 1909.5113 | J38: =SUM(J34:J37) -> 1978.1656 | K38: =SUM(K34:K37) -> 2049.581 | L38: =SUM(L34:L37) -> 2123.8786 | M38: =SUM(M34:M37) -> 2201.1855 | N38: =SUM(N34:N37) -> 2281.6342 | O38: =SUM(O34:O37) -> 2365.3639 | ... AA38: =SUM(AA34:AA37) -> 3686.4855
E39: =E38*1000/E17 -> 6.5494192 | H39: =H38*1000/H17 -> 5.77175 | I39: =I38*1000/I17 -> 5.836358 | J39: =J38*1000/J17 -> 5.90253 | K39: =K38*1000/K17 -> 5.9703048 | L39: =L38*1000/L17 -> 6.0397226 | M39: =M38*1000/M17 -> 6.1108244 | N39: =N38*1000/N17 -> 6.1836522 | O39: =O38*1000/O17 -> 6.2582493 | ... AA39: =AA38*1000/AA17 -> 7.3086614
C40: Royalty Calculation
C41: Offtake Revenue, net of brokerage | E41: =SUM(H41:AA41) -> 274132.86 | H41: =+H31 -> 9041.4183 | I41: =+I31 -> 9393.2687 | J41: =+J31 -> 9902.6871 | K41: =+K31 -> 10576.849 | L41: =+L31 -> 11072.572 | M41: =+M31 -> 11147.241 | N41: =+N31 -> 11350.826 | O41: =+O31 -> 11645.608 | ... AA41: =+AA31 -> 20074.005
C42: (-) Capex Allowance | D42: =+INPUTS!E32 -> 36835 | H42: =-$D$42/20 -> -1841.75 | I42: =-$D$42/20 -> -1841.75 | J42: =-$D$42/20 -> -1841.75 | K42: =-$D$42/20 -> -1841.75 | L42: =-$D$42/20 -> -1841.75 | M42: =-$D$42/20 -> -1841.75 | N42: =-$D$42/20 -> -1841.75 | O42: =-$D$42/20 -> -1841.75 | ... AA42: =-$D$42/20 -> -1841.75
C43: (-) Capital Cost Financing Fee | D43: =+INPUTS!E33 -> 9208.75 | H43: =-$D$43/20 -> -460.4375 | I43: =-$D$43/20 -> -460.4375 | J43: =-$D$43/20 -> -460.4375 | K43: =-$D$43/20 -> -460.4375 | L43: =-$D$43/20 -> -460.4375 | M43: =-$D$43/20 -> -460.4375 | N43: =-$D$43/20 -> -460.4375 | O43: =-$D$43/20 -> -460.4375 | ... AA43: =-$D$43/20 -> -460.4375
C44: (-) Opex and Maintenance Allowance | D44: =+INPUTS!E34 -> 51911.25 | H44: =-$D$44/20 -> -2595.5625 | I44: =-$D$44/20 -> -2595.5625 | J44: =-$D$44/20 -> -2595.5625 | K44: =-$D$44/20 -> -2595.5625 | L44: =-$D$44/20 -> -2595.5625 | M44: =-$D$44/20 -> -2595.5625 | N44: =-$D$44/20 -> -2595.5625 | O44: =-$D$44/20 -> -2595.5625 | ... AA44: =-$D$44/20 -> -2595.5625
C45: Net Avail. For Royalty | D45: =+SUM(D42:D44) -> 97955 | H45: =SUM(H41:H44) -> 4143.6683 | I45: =SUM(I41:I44) -> 4495.5187 | J45: =SUM(J41:J44) -> 5004.9371 | K45: =SUM(K41:K44) -> 5679.0988 | L45: =SUM(L41:L44) -> 6174.8221 | M45: =SUM(M41:M44) -> 6249.4909 | N45: =SUM(N41:N44) -> 6453.0765 | O45: =SUM(O41:O44) -> 6747.8584 | ... AA45: =SUM(AA41:AA44) -> 15176.255
C46: (x) % Base Royalty | D46: =+INPUTS!$E$28 -> 0.7 | E46: =+INPUTS!E26 -> 1000 | H46: =+$D$46 -> 0.7 | I46: =+$D$46 -> 0.7 | J46: =+$D$46 -> 0.7 | K46: =+$D$46 -> 0.7 | L46: =+$D$46 -> 0.7 | M46: =+$D$46 -> 0.7 | N46: =+$D$46 -> 0.7 | O46: =+$D$46 -> 0.7 | ... AA46: =+$D$46 -> 0.7
C47: Minimum or Base Royalty Amount | D47: =SUM(H47:AA47) -> 123324.51 | H47: =+MAX($E$46,H46*H45) -> 2900.5678 | I47: =+MAX($E$46,I46*I45) -> 3146.8631 | J47: =+MAX($E$46,J46*J45) -> 3503.456 | K47: =+MAX($E$46,K46*K45) -> 3975.3692 | L47: =+MAX($E$46,L46*L45) -> 4322.3754 | M47: =+MAX($E$46,M46*M45) -> 4374.6436 | N47: =+MAX($E$46,N46*N45) -> 4517.1535 | O47: =+MAX($E$46,O46*O45) -> 4723.5009 | ... AA47: =+MAX($E$46,AA46*AA45) -> 10623.379
C49: Eligible for Bonus Royalty | D49: =+INPUTS!E31 -> 1250 | E49: =+INPUTS!$E$30 -> 2.82 | H49: =IF(AND(H$11>$D$49,H$19>$E$49),1,0) -> 0 | I49: =IF(AND(I$11>$D$49,I$19>$E$49),1,0) -> 0 | J49: =IF(AND(J$11>$D$49,J$19>$E$49),1,0) -> 0 | K49: =IF(AND(K$11>$D$49,K$19>$E$49),1,0) -> 0 | L49: =IF(AND(L$11>$D$49,L$19>$E$49),1,0) -> 0 | M49: =IF(AND(M$11>$D$49,M$19>$E$49),1,0) -> 0 | N49: =IF(AND(N$11>$D$49,N$19>$E$49),1,0) -> 0 | O49: =IF(AND(O$11>$D$49,O$19>$E$49),1,0) -> 0 | ... AA49: =IF(AND(AA$11>$D$49,AA$19>$E$49),1,0) -> 1
...

Sheet Analysis
D1: =+Model!G9 -> 46447 | E1: =+Model!H9 -> 46873 | F1: =+Model!I9 -> 47238 | G1: =+Model!J9 -> 47603 | H1: =+Model!K9 -> 47968 | I1: =+Model!L9 -> 48334 | J1: =+Model!M9 -> 48699 | K1: =+Model!N9 -> 49064 | ... X1: =+Model!AA9 -> 53812
D2: 0 | E2: 1 | F2: 2 | G2: 3 | H2: 4 | I2: 5 | J2: 6 | K2: 7 | L2: 8 | M2: 9 | N2: 10 | O2: 11 | P2: 12 | Q2: 13 | R2: 14 | S2: 15 | T2: 16 | U2: 17 | V2: 18 | W2: 19 | X2: 20
C3: Bonus? | E3: =+Model!H49 -> 0 | F3: =+Model!I49 -> 0 | G3: =+Model!J49 -> 0 | H3: =+Model!K49 -> 0 | I3: =+Model!L49 -> 0 | J3: =+Model!M49 -> 0 | K3: =+Model!N49 -> 0 | L3: =+Model!O49 -> 0 | ... X3: =+Model!AA49 -> 1
C5: Biogas, scfm | E5: =+Model!H11 -> 950 | F5: =+Model!I11 -> 973.123 | G5: =+Model!J11 -> 996.80881 | H5: =+Model!K11 -> 1021.0711 | I5: =+Model!L11 -> 1045.924 | J5: =+Model!M11 -> 1071.3818 | K5: =+Model!N11 -> 1097.4592 | L5: =+Model!O11 -> 1124.1714 | ... X5: =+Model!AA11 -> 1500.2447
C6: RNG Production, MMBtu | E6: =+Model!H17 -> 319400.93 | F6: =+Model!I17 -> 327175.15 | G6: =+Model!J17 -> 335138.59 | H6: =+Model!K17 -> 343295.87 | I6: =+Model!L17 -> 351651.69 | J6: =+Model!M17 -> 360210.89 | K6: =+Model!N17 -> 368978.42 | L6: =+Model!O17 -> 377959.36 | ... X6: =+Model!AA17 -> 504399.55
B8: x | C8: Gross Offtake Revenue | E8: =+Model!H31 -> 9041.4183 | F8: =+Model!I31 -> 9393.2687 | G8: =+Model!J31 -> 9902.6871 | H8: =+Model!K31 -> 10576.849 | I8: =+Model!L31 -> 11072.572 | J8: =+Model!M31 -> 11147.241 | K8: =+Model!N31 -> 11350.826 | L8: =+Model!O31 -> 11645.608 | ... X8: =+Model!AA31 -> 20074.005
C10: (-) Capex Allowance | E10: =-Model!H42 -> 1841.75 | F10: =-Model!I42 -> 1841.75 | G10: =-Model!J42 -> 1841.75 | H10: =-Model!K42 -> 1841.75 | I10: =-Model!L42 -> 1841.75 | J10: =-Model!M42 -> 1841.75 | K10: =-Model!N42 -> 1841.75 | L10: =-Model!O42 -> 1841.75 | ... X10: =-Model!AA42 -> 1841.75
C11: (-) Capital Cost Financing Fee | D11: 0.5 | E11: =+$D$11*E10 -> 920.875 | F11: =+$D$11*F10 -> 920.875 | G11: =+$D$11*G10 -> 920.875 | H11: =+$D$11*H10 -> 920.875 | I11: =+$D$11*I10 -> 920.875 | J11: =+$D$11*J10 -> 920.875 | K11: =+$D$11*K10 -> 920.875 | L11: =+$D$11*L10 -> 920.875 | ... X11: =+$D$11*X10 -> 920.875 | Z11: =+D11/20 -> 0.025
B12: 1 | C12: (-) Opex and Maintenance Allowance | D12: 2595.5625 | E12: =CHOOSE($B$12,MIN($D$12,E25),$D$12,E$25) -> 1843.5023 | F12: =CHOOSE($B$12,MIN($D$12,F25),$D$12,F$25) -> 1909.5113 | G12: =CHOOSE($B$12,MIN($D$12,G25),$D$12,G$25) -> 1978.1656 | H12: =CHOOSE($B$12,MIN($D$12,H25),$D$12,H$25) -> 2049.581 | I12: =CHOOSE($B$12,MIN($D$12,I25),$D$12,I$25) -> 2123.8786 | J12: =CHOOSE($B$12,MIN($D$12,J25),$D$12,J$25) -> 2201.1855 | K12: =CHOOSE($B$12,MIN($D$12,K25),$D$12,K$25) -> 2281.6342 | L12: =CHOOSE($B$12,MIN($D$12,L25),$D$12,L$25) -> 2365.3639 | ... X12: =CHOOSE($B$12,MIN($D$12,X25),$D$12,X$25) -> 2595.5625
C13: Allowances TOTAL | E13: =SUM(E10:E12) -> 4606.1273 | F13: =SUM(F10:F12) -> 4672.1363 | G13: =SUM(G10:G12) -> 4740.7906 | H13: =SUM(H10:H12) -> 4812.206 | I13: =SUM(I10:I12) -> 4886.5036 | J13: =SUM(J10:J12) -> 4963.8105 | K13: =SUM(K10:K12) -> 5044.2592 | L13: =SUM(L10:L12) -> 5127.9889 | ... X13: =SUM(X10:X12) -> 5358.1875
C15: Net Offtake Revenue | E15: =+E8-E13 -> 4435.291 | F15: =+F8-F13 -> 4721.1323 | G15: =+G8-G13 -> 5161.8965 | H15: =+H8-H13 -> 5764.6429 | I15: =+I8-I13 -> 6186.0684 | J15: =+J8-J13 -> 6183.4304 | K15: =+K8-K13 -> 6306.5672 | L15: =+L8-L13 -> 6517.6195 | ... X15: =+X8-X13 -> 14715.818
C17: Base Royalty | D17: 0.7 | E17: =$D17*E15 -> 3104.7037 | F17: =$D17*F15 -> 3304.7926 | G17: =$D17*G15 -> 3613.3276 | H17: =$D17*H15 -> 4035.25 | I17: =$D17*I15 -> 4330.2479 | J17: =$D17*J15 -> 4328.4013 | K17: =$D17*K15 -> 4414.5971 | L17: =$D17*L15 -> 4562.3337 | ... X17: =$D17*X15 -> 10301.073
C18: Bonus Royalty | D18: =90%-D17 -> 0.2 | E18: =E3*E15*$D$18*((E5-1250)/E5) -> 0 | F18: =F3*F15*$D$18*((F5-1250)/F5) -> 0 | G18: =G3*G15*$D$18*((G5-1250)/G5) -> 0 | H18: =H3*H15*$D$18*((H5-1250)/H5) -> 0 | I18: =I3*I15*$D$18*((I5-1250)/I5) -> 0 | J18: =J3*J15*$D$18*((J5-1250)/J5) -> 0 | K18: =K3*K15*$D$18*((K5-1250)/K5) -> 0 | L18: =L3*L15*$D$18*((L5-1250)/L5) -> 0 | ... X18: =X3*X15*$D$18*((X5-1250)/X5) -> 490.92738
B19: x | C19: Total Royalty | E19: =SUM(E17:E18) -> 3104.7037 | F19: =SUM(F17:F18) -> 3304.7926 | G19: =SUM(G17:G18) -> 3613.3276 | H19: =SUM(H17:H18) -> 4035.25 | I19: =SUM(I17:I18) -> 4330.2479 | J19: =SUM(J17:J18) -> 4328.4013 | K19: =SUM(K17:K18) -> 4414.5971 | L19: =SUM(L17:L18) -> 4562.3337 | ... X19: =SUM(X17:X18) -> 10792
C21: Utilities | E21: =+Model!H34 -> 527.01154 | F21: =+Model!I34 -> 553.33497 | G21: =+Model!J34 -> 580.97323 | H21: =+Model!K34 -> 609.99197 | I21: =+Model!L34 -> 640.46015 | J21: =+Model!M34 -> 672.45017 | K21: =+Model!N34 -> 706.03805 | L21: =+Model!O34 -> 741.30359 | ... X21: =+Model!AA34 -> 1330.4914
C22: (+) Consumables / R&M | E22: =+Model!H35 -> 271.49079 | F22: =+Model!I35 -> 285.05135 | G22: =+Model!J35 -> 299.28924 | H22: =+Model!K35 -> 314.23829 | I22: =+Model!L35 -> 329.93402 | J22: =+Model!M35 -> 346.41373 | K22: =+Model!N35 -> 363.71657 | L22: =+Model!O35 -> 381.88367 | ... X22: =+Model!AA35 -> 685.40466
C23: (+) Asset Management | D23: =SUM(E23:X24)/SUM(E25:X25) -> 0.50287561 | E23: =+Model!H36 -> 200 | F23: =+Model!I36 -> 205 | G23: =+Model!J36 -> 210.125 | H23: =+Model!K36 -> 215.37812 | I23: =+Model!L36 -> 220.76258 | J23: =+Model!M36 -> 226.28164 | K23: =+Model!N36 -> 231.93868 | L23: =+Model!O36 -> 237.73715 | ... X23: =+Model!AA36 -> 319.73004
C24: (+) Fixed Expenses | E24: =+Model!H37 -> 845 | F24: =+Model!I37 -> 866.125 | G24: =+Model!J37 -> 887.77812 | H24: =+Model!K37 -> 909.97258 | I24: =+Model!L37 -> 932.72189 | J24: =+Model!M37 -> 956.03994 | K24: =+Model!N37 -> 979.94094 | L24: =+Model!O37 -> 1004.4395 | ... X24: =+Model!AA37 -> 1350.8594
B25: x | C25: TOTAL Opex | E25: =SUM(E21:E24) -> 1843.5023 | F25: =SUM(F21:F24) -> 1909.5113 | G25: =SUM(G21:G24) -> 1978.1656 | H25: =SUM(H21:H24) -> 2049.581 | I25: =SUM(I21:I24) -> 2123.8786 | J25: =SUM(J21:J24) -> 2201.1855 | K25: =SUM(K21:K24) -> 2281.6342 | L25: =SUM(L21:L24) -> 2365.3639 | ... X25: =SUM(X21:X24) -> 3686.4855
C27: EBITDA | E27: =+E8-E19-E25 -> 4093.2123 | F27: =+F8-F19-F25 -> 4178.9647 | G27: =+G8-G19-G25 -> 4311.194 | H27: =+H8-H19-H25 -> 4492.0179 | I27: =+I8-I19-I25 -> 4618.4455 | J27: =+J8-J19-J25 -> 4617.6541 | K27: =+K8-K19-K25 -> 4654.5952 | L27: =+L8-L19-L25 -> 4717.9109 | ... X27: =+X8-X19-X25 -> 5595.52
C28: Capex | D28: =+Model!G57 -> -31309.75 | E28: =+Model!H57 -> -5525.25 | F28: =+Model!I57 -> 0 | G28: =+Model!J57 -> 0 | H28: =+Model!K57 -> 0 | I28: =+Model!L57 -> 0 | J28: =+Model!M57 -> 0 | K28: =+Model!N57 -> 0 | ... X28: =+Model!AA57 -> 0
C29: ITC | D29: =+Model!G60 -> 0 | E29: =+Model!H60 -> 12965.92 | F29: =+Model!I60 -> 0 | G29: =+Model!J60 -> 0 | H29: =+Model!K60 -> 0 | I29: =+Model!L60 -> 0 | J29: =+Model!M60 -> 0 | K29: =+Model!N60 -> 0 | ... X29: =+Model!AA60 -> 0
C30: MTC Capex | E30: =Model!H59 -> 0 | F30: =Model!I59 -> 0 | G30: =Model!J59 -> -552.525 | H30: =Model!K59 -> -566.33812 | I30: =Model!L59 -> -580.49658 | J30: =Model!M59 -> -595.00899 | K30: =Model!N59 -> -609.88422 | L30: =Model!O59 -> -625.13132 | ... X30: =Model!AA59 -> -840.73213
C31: UL Cash Flow | D31: =SUM(D27:D30) -> -31309.75 | E31: =SUM(E27:E30) -> 11533.882 | F31: =SUM(F27:F30) -> 4178.9647 | G31: =SUM(G27:G30) -> 3758.669 | H31: =SUM(H27:H30) -> 3925.6797 | I31: =SUM(I27:I30) -> 4037.9489 | J31: =SUM(J27:J30) -> 4022.6451 | K31: =SUM(K27:K30) -> 4044.711 | ... X31: =SUM(X27:X30) -> 4754.7878
C33: UL IRR | D33: =+XIRR(D31:X31,$D$1:$X$1) -> 0.15261858
E35: =+$D$12-E25 -> 752.06017 | F35: =+$D$12-F25 -> 686.05118 | G35: =+$D$12-G25 -> 617.39691 | H35: =+$D$12-H25 -> 545.98154 | I35: =+$D$12-I25 -> 471.68386 | J35: =+$D$12-J25 -> 394.37702 | K35: =+$D$12-K25 -> 313.92825 | L35: =+$D$12-L25 -> 230.19862 | ... X35: =+$D$12-X25 -> -1090.923

Sheet Model (3)
C3: NTP Date | E3: 46203
H7: =YEAR(H9) -> 2028 | I7: =YEAR(I9) -> 2029 | J7: =YEAR(J9) -> 2030 | K7: =YEAR(K9) -> 2031 | L7: =YEAR(L9) -> 2032 | M7: =YEAR(M9) -> 2033 | N7: =YEAR(N9) -> 2034 | O7: =YEAR(O9) -> 2035 | ... AA7: =YEAR(AA9) -> 2047
H8: 1 | I8: =H8*(1+INPUTS!$E$6) -> 1.025 | J8: =I8*(1+INPUTS!$E$6) -> 1.050625 | K8: =J8*(1+INPUTS!$E$6) -> 1.0768906 | L8: =K8*(1+INPUTS!$E$6) -> 1.1038129 | M8: =L8*(1+INPUTS!$E$6) -> 1.1314082 | N8: =M8*(1+INPUTS!$E$6) -> 1.1596934 | O8: =N8*(1+INPUTS!$E$6) -> 1.1886858 | P8: =O8*(1+INPUTS!$E$6) -> 1.2184029 | ... AA8: =Z8*(1+INPUTS!$E$6) -> 1.5986502
G9: =+INPUTS!E38 -> 46447 | H9: =EOMONTH(INPUTS!E37,6) -> 46873 | I9: =EOMONTH(H9,12) -> 47238 | J9: =EOMONTH(I9,12) -> 47603 | K9: =EOMONTH(J9,12) -> 47968 | L9: =EOMONTH(K9,12) -> 48334 | M9: =EOMONTH(L9,12) -> 48699 | N9: =EOMONTH(M9,12) -> 49064 | O9: =EOMONTH(N9,12) -> 49429 | P9: =EOMONTH(O9,12) -> 49795 | ... AA9: =EOMONTH(Z9,12) -> 53812
C10: $ in '000, except noted | G10: Year 0 | H10: Year 1 | I10: Year 2 | J10: Year 3 | K10: Year 4 | L10: Year 5 | M10: Year 6 | N10: Year 7 | O10: Year 8 | P10: Year 9 | Q10: Year 10 | R10: Year 11 | S10: Year 12 | T10: Year 13 | U10: Year 14 | V10: Year 15 | W10: Year 16 | X10: Year 17 | Y10: Year 18 | Z10: Year 19 | AA10: Year 20
C11: Biogas | D11: scfm | H11: =INPUTS!E8 -> 950 | I11: =H11*(1+INPUTS!$E$9) -> 973.123 | J11: =I11*(1+INPUTS!$E$9) -> 996.80881 | K11: =J11*(1+INPUTS!$E$9) -> 1021.0711 | L11: =K11*(1+INPUTS!$E$9) -> 1045.924 | M11: =L11*(1+INPUTS!$E$9) -> 1071.3818 | N11: =M11*(1+INPUTS!$E$9) -> 1097.4592 | O11: =N11*(1+INPUTS!$E$9) -> 1124.1714 | P11: =O11*(1+INPUTS!$E$9) -> 1151.5337 | ... AA11: =Z11*(1+INPUTS!$E$9) -> 1500.2447
C12: Biogas | D12: scf/d | H12: =H11*(24*60) -> 1368000 | I12: =I11*(24*60) -> 1401297.1 | J12: =J11*(24*60) -> 1435404.7 | K12: =K11*(24*60) -> 1470342.4 | L12: =L11*(24*60) -> 1506130.6 | M12: =M11*(24*60) -> 1542789.8 | N12: =N11*(24*60) -> 1580341.3 | O12: =O11*(24*60) -> 1618806.8 | ... AA12: =AA11*(24*60) -> 2160352.4
C13: Theor. RNG | D13: MMBtu/d | E13: =INPUTS!$E$14 -> 666.68382 | H13: =$E$13*H12/10^6 -> 912.02347 | I13: =$E$13*I12/10^6 -> 934.22212 | J13: =$E$13*J12/10^6 -> 956.96108 | K13: =$E$13*K12/10^6 -> 980.25352 | L13: =$E$13*L12/10^6 -> 1004.1129 | M13: =$E$13*M12/10^6 -> 1028.553 | N13: =$E$13*N12/10^6 -> 1053.588 | O13: =$E$13*O12/10^6 -> 1079.2323 | ... AA13: =$E$13*AA12/10^6 -> 1440.272
C14: Theor. RNG | D14: MMBtu | E14: =SUM(H14:AA14) -> 8447257.2 | H14: =H13*365 -> 332888.57 | I14: =I13*365 -> 340991.07 | J14: =J13*365 -> 349290.8 | K14: =K13*365 -> 357792.53 | L14: =L13*365 -> 366501.2 | M14: =M13*365 -> 375421.84 | N14: =N13*365 -> 384559.61 | O14: =O13*365 -> 393919.79 | ... AA14: =AA13*365 -> 525699.29
C15: Uptime | H15: =INPUTS!$E$12 -> 0.98 | I15: =H15 -> 0.98 | J15: =I15 -> 0.98 | K15: =J15 -> 0.98 | L15: =K15 -> 0.98 | M15: =L15 -> 0.98 | N15: =M15 -> 0.98 | O15: =N15 -> 0.98 | P15: =O15 -> 0.98 | ... AA15: =Z15 -> 0.98
C16: Capture | D16: mult.--> | E16: 1 | H16: =INPUTS!$E$13 -> 0.97906432 | I16: =H16 -> 0.97906432 | J16: =I16 -> 0.97906432 | K16: =J16 -> 0.97906432 | L16: =K16 -> 0.97906432 | M16: =L16 -> 0.97906432 | N16: =M16 -> 0.97906432 | O16: =N16 -> 0.97906432 | P16: =O16 -> 0.97906432 | ... AA16: =Z16 -> 0.97906432
C17: Net RNG Production | D17: MMBtu | E17: =SUM(H17:AA17) -> 8105000 | H17: =PRODUCT(H14:H16)*$E$16 -> 319400.93 | I17: =PRODUCT(I14:I16)*$E$16 -> 327175.15 | J17: =PRODUCT(J14:J16)*$E$16 -> 335138.59 | K17: =PRODUCT(K14:K16)*$E$16 -> 343295.87 | L17: =PRODUCT(L14:L16)*$E$16 -> 351651.69 | M17: =PRODUCT(M14:M16)*$E$16 -> 360210.89 | N17: =PRODUCT(N14:N16)*$E$16 -> 368978.42 | O17: =PRODUCT(O14:O16)*$E$16 -> 377959.36 | ... AA17: =PRODUCT(AA14:AA16)*$E$16 -> 504399.55
C19: Ares Curve D3 RIN | D19: adder--> | E19: 0 | H19: =_xlfn.XLOOKUP(H7,'RIN Curves'!$G$18:$G$44,'RIN Curves'!$H$18:$H$44) -> 2.6619581 | I19: =_xlfn.XLOOKUP(I7,'RIN Curves'!$G$18:$G$44,'RIN Curves'!$H$18:$H$44) -> 2.7118204 | J19: =_xlfn.XLOOKUP(J7,'RIN Curves'!$G$18:$G$44,'RIN Curves'!$H$18:$H$44) -> 2.7914813 | K19: =_xlfn.XLOOKUP(K7,'RIN Curves'!$G$18:$G$44,'RIN Curves'!$H$18:$H$44) -> 2.9160811 | L19: =_xlfn.XLOOKUP(L7,'RIN Curves'!$G$18:$G$44,'RIN Curves'!$H$18:$H$44) -> 2.9781765 | M19: =_xlfn.XLOOKUP(M7,'RIN Curves'!$G$18:$G$44,'RIN Curves'!$H$18:$H$44) -> 2.9101359 | N19: =_xlfn.XLOOKUP(N7,'RIN Curves'!$G$18:$G$44,'RIN Curves'!$H$18:$H$44) -> 2.8799224 | O19: =_xlfn.XLOOKUP(O7,'RIN Curves'!$G$18:$G$44,'RIN Curves'!$H$18:$H$44) -> 2.8742294 | ... AA19: =_xlfn.XLOOKUP(AA7,'RIN Curves'!$G$18:$G$44,'RIN Curves'!$H$18:$H$44) -> 3.6777758
B20: =INPUTS!E16 -> 1 | C20: D3 RIN | D20: $/RIN | E20: =INPUTS!$E$17+$E$19 -> 2.39 | H20: =IF($B$20=0,E20,H19) -> 2.6619581 | I20: =IF($B$20=0,H20*(1+INPUTS!$E$18),I19) -> 2.7118204 | J20: =IF($B$20=0,I20*(1+INPUTS!$E$18),J19) -> 2.7914813 | K20: =IF($B$20=0,J20*(1+INPUTS!$E$18),K19) -> 2.9160811 | L20: =IF($B$20=0,K20*(1+INPUTS!$E$18),L19) -> 2.9781765 | M20: =IF($B$20=0,L20*(1+INPUTS!$E$18),M19) -> 2.9101359 | N20: =IF($B$20=0,M20*(1+INPUTS!$E$18),N19) -> 2.8799224 | O20: =IF($B$20=0,N20*(1+INPUTS!$E$18),O19) -> 2.8742294 | P20: =IF($B$20=0,O20*(1+INPUTS!$E$18),P19) -> 2.9338872 | ... AA20: =IF($B$20=0,Z20*(1+INPUTS!$E$18),AA19) -> 3.6777758
C21: D3 RIN | D21: $/MMBtu | H21: =H20*INPUTS!$E$41 -> 31.216783 | I21: =I20*INPUTS!$E$41 -> 31.801518 | J21: =J20*INPUTS!$E$41 -> 32.735701 | K21: =K20*INPUTS!$E$41 -> 34.196883 | L21: =L20*INPUTS!$E$41 -> 34.925076 | M21: =M20*INPUTS!$E$41 -> 34.127163 | N21: =N20*INPUTS!$E$41 -> 33.77285 | O21: =O20*INPUTS!$E$41 -> 33.706088 | ... AA21: =AA20*INPUTS!$E$41 -> 43.129276
C23: Nat. Gas | D23: $/MMBtu | E23: =INPUTS!E23 -> 0.03 | H23: =INPUTS!E22 -> 3.0390412 | I23: =+H23*(1+$E$23) -> 3.1302124 | J23: =+I23*(1+$E$23) -> 3.2241188 | K23: =+J23*(1+$E$23) -> 3.3208423 | L23: =+K23*(1+$E$23) -> 3.4204676 | M23: =+L23*(1+$E$23) -> 3.5230816 | N23: =+M23*(1+$E$23) -> 3.6287741 | O23: =+N23*(1+$E$23) -> 3.7376373 | P23: =+O23*(1+$E$23) -> 3.8497664 | ... AA23: =+Z23*(1+$E$23) -> 5.3289771
C24: (-) Wheel/hub cost | D24: $/MMBtu | H24: =-INPUTS!$E$24 -> -1 | I24: =H24 -> -1 | J24: =I24 -> -1 | K24: =J24 -> -1 | L24: =K24 -> -1 | M24: =L24 -> -1 | N24: =M24 -> -1 | O24: =N24 -> -1 | P24: =O24 -> -1 | ... AA24: =Z24 -> -1
C27: Offtake Revenue | E27: =E28+E30 -> 325330.87
C28: RIN Value | E28: =+SUM(H28:AA28) -> 299564.81 | H28: =+H21*H$17/10^3 -> 9970.6695 | I28: =+I21*I$17/10^3 -> 10404.666 | J28: =+J21*J$17/10^3 -> 10970.997 | K28: =+K21*K$17/10^3 -> 11739.648 | L28: =+L21*L$17/10^3 -> 12281.462 | M28: =+M21*M$17/10^3 -> 12292.976 | N28: =+N21*N$17/10^3 -> 12461.453 | O28: =+O21*O$17/10^3 -> 12739.531 | ... AA28: =+AA21*AA$17/10^3 -> 21754.387
B29: =INPUTS!E19 -> 0.2 | C29: (-) RIN Brokerage | E29: =+SUM(H29:AA29) -> -59912.961 | H29: =-$B$29*H28 -> -1994.1339 | I29: =-$B$29*I28 -> -2080.9333 | J29: =-$B$29*J28 -> -2194.1993 | K29: =-$B$29*K28 -> -2347.9297 | L29: =-$B$29*L28 -> -2456.2924 | M29: =-$B$29*M28 -> -2458.5952 | N29: =-$B$29*N28 -> -2492.2906 | O29: =-$B$29*O28 -> -2547.9062 | ... AA29: =-$B$29*AA28 -> -4350.8775
C30: (+) Nat Gas Value | E30: =+SUM(H30:AA30) -> 25766.061 | H30: =SUM(H23:H24)*H17/10^3 -> 651.27165 | I30: =SUM(I23:I24)*I17/10^3 -> 696.95256 | J30: =SUM(J23:J24)*J17/10^3 -> 745.38804 | K30: =SUM(K23:K24)*K17/10^3 -> 796.73558 | L30: =SUM(L23:L24)*L17/10^3 -> 851.16152 | M30: =SUM(M23:M24)*M17/10^3 -> 908.84148 | N30: =SUM(N23:N24)*N17/10^3 -> 969.96092 | O30: =SUM(O23:O24)*O17/10^3 -> 1034.7156 | ... AA30: =SUM(AA23:AA24)*AA17/10^3 -> 2183.5341
C31: Net Offtake Revenue | E31: =+SUM(H31:AA31) -> 265417.91 | H31: =SUM(H28:H30) -> 8627.8072 | I31: =SUM(I28:I30) -> 9020.6856 | J31: =SUM(J28:J30) -> 9522.1854 | K31: =SUM(K28:K30) -> 10188.454 | L31: =SUM(L28:L30) -> 10676.331 | M31: =SUM(M28:M30) -> 10743.222 | N31: =SUM(N28:N30) -> 10939.123 | O31: =SUM(O28:O30) -> 11226.341 | ... AA31: =SUM(AA28:AA30) -> 19587.044
C33: Operating Expenses
B34: 1.65 | C34: Utilities | E34: =SUM(H34:AA34) -> 17416.658 | H34: =+$B34*H$8*H$17/10^3 -> 527.01154 | I34: =+$B$34*I8*I17/10^3 -> 553.33497 | J34: =+$B$34*J8*J17/10^3 -> 580.97323 | K34: =+$B$34*K8*K17/10^3 -> 609.99197 | L34: =+$B$34*L8*L17/10^3 -> 640.46015 | M34: =+$B$34*M8*M17/10^3 -> 672.45017 | N34: =+$B$34*N8*N17/10^3 -> 706.03805 | O34: =+$B$34*O8*O17/10^3 -> 741.30359 | P34: =+$B$34*P8*P17/10^3 -> 778.3306 | ... AA34: =+$B$34*AA8*AA17/10^3 -> 1330.4914
B35: 0.8 | C35: (+) Consumables / R&M | E35: =SUM(H35:AA35) -> 8444.44 | H35: =+$B35*H$8*H$17/10^3 -> 255.52075 | I35: =+$B35*I$8*I$17/10^3 -> 268.28362 | J35: =+$B35*J$8*J$17/10^3 -> 281.68399 | K35: =+$B35*K$8*K$17/10^3 -> 295.75368 | L35: =+$B35*L$8*L$17/10^3 -> 310.52613 | M35: =+$B35*M$8*M$17/10^3 -> 326.03645 | N35: =+$B35*N$8*N$17/10^3 -> 342.32148 | O35: =+$B35*O$8*O$17/10^3 -> 359.41992 | ... AA35: =+$B35*AA$8*AA$17/10^3 -> 645.08674
B36: 200 | C36: (+) Asset Management | E36: =SUM(H36:AA36) -> 5108.9315 | H36: =+$B36*H$8 -> 200 | I36: =+$B36*I$8 -> 205 | J36: =+$B36*J$8 -> 210.125 | K36: =+$B36*K$8 -> 215.37812 | L36: =+$B36*L$8 -> 220.76258 | M36: =+$B36*M$8 -> 226.28164 | N36: =+$B36*N$8 -> 231.93868 | O36: =+$B36*O$8 -> 237.73715 | ... AA36: =+$B36*AA$8 -> 319.73004
B37: 850 | C37: (+) Fixed Expenses | E37: =SUM(H37:AA37) -> 21712.959 | H37: =+$B37*H$8 -> 850 | I37: =+$B37*I$8 -> 871.25 | J37: =+$B37*J$8 -> 893.03125 | K37: =+$B37*K$8 -> 915.35703 | L37: =+$B37*L$8 -> 938.24096 | M37: =+$B37*M$8 -> 961.69698 | N37: =+$B37*N$8 -> 985.73941 | O37: =+$B37*O$8 -> 1010.3829 | ... AA37: =+$B37*AA$8 -> 1358.8527
C38: TOTAL | E38: =SUM(H38:AA38) -> 52682.988 | H38: =SUM(H34:H37) -> 1832.5323 | I38: =SUM(I34:I37) -> 1897.8686 | J38: =SUM(J34:J37) -> 1965.8135 | K38: =SUM(K34:K37) -> 2036.4808 | L38: =SUM(L34:L37) -> 2109.9898 | M38: =SUM(M34:M37) -> 2186.4652 | N38: =SUM(N34:N37) -> 2266.0376 | O38: =SUM(O34:O37) -> 2348.8436 | ... AA38: =SUM(AA34:AA37) -> 3654.1608
E39: =E38*1000/E17 -> 6.5000602 | H39: =H38*1000/H17 -> 5.7374043 | I39: =I38*1000/I17 -> 5.8007724 | J39: =J38*1000/J17 -> 5.8656732 | K39: =K38*1000/K17 -> 5.9321448 | L39: =L38*1000/L17 -> 6.0002266 | M39: =M38*1000/M17 -> 6.0699587 | N39: =N38*1000/N17 -> 6.1413825 | O39: =O38*1000/O17 -> 6.21454 | ... AA39: =AA38*1000/AA17 -> 7.244576
C40: Royalty Calculation
C41: Offtake Revenue, net of brokerage | E41: =SUM(H41:AA41) -> 265417.91 | H41: =+H31 -> 8627.8072 | I41: =+I31 -> 9020.6856 | J41: =+J31 -> 9522.1854 | K41: =+K31 -> 10188.454 | L41: =+L31 -> 10676.331 | M41: =+M31 -> 10743.222 | N41: =+N31 -> 10939.123 | O41: =+O31 -> 11226.341 | ... AA41: =+AA31 -> 19587.044
C42: (-) Capex Allowance | D42: =+INPUTS!$E$32 -> 36835 | H42: =-$D$42/20 -> -1841.75 | I42: =-$D$42/20 -> -1841.75 | J42: =-$D$42/20 -> -1841.75 | K42: =-$D$42/20 -> -1841.75 | L42: =-$D$42/20 -> -1841.75 | M42: =-$D$42/20 -> -1841.75 | N42: =-$D$42/20 -> -1841.75 | O42: =-$D$42/20 -> -1841.75 | ... AA42: =-$D$42/20 -> -1841.75
C43: (-) Opex and Maintenance Allowance | D43: =+INPUTS!S25+INPUTS!S26 -> 65452.06 | H43: =-$D$43/20 -> -3272.603 | I43: =-$D$43/20 -> -3272.603 | J43: =-$D$43/20 -> -3272.603 | K43: =-$D$43/20 -> -3272.603 | L43: =-$D$43/20 -> -3272.603 | M43: =-$D$43/20 -> -3272.603 | N43: =-$D$43/20 -> -3272.603 | O43: =-$D$43/20 -> -3272.603 | ... AA43: =-$D$43/20 -> -3272.603
C44: Net Avail. For Royalty | H44: =SUM(H41:H43) -> 3513.4543 | I44: =SUM(I41:I43) -> 3906.3327 | J44: =SUM(J41:J43) -> 4407.8324 | K44: =SUM(K41:K43) -> 5074.1014 | L44: =SUM(L41:L43) -> 5561.9781 | M44: =SUM(M41:M43) -> 5628.8692 | N44: =SUM(N41:N43) -> 5824.7702 | O44: =SUM(O41:O43) -> 6111.9877 | ... AA44: =SUM(AA41:AA43) -> 14472.691
C45: (x) % Royalty | D45: 0.7 | E45: 2000 | H45: =$D$45 -> 0.7 | I45: =$D$45 -> 0.7 | J45: =$D$45 -> 0.7 | K45: =$D$45 -> 0.7 | L45: =$D$45 -> 0.7 | M45: =$D$45 -> 0.7 | N45: =$D$45 -> 0.7 | O45: =$D$45 -> 0.7 | ... AA45: =$D$45 -> 0.7
C46: Royalty Amount (a) | D46: =SUM(H46:AA46) -> 114191.59 | H46: =MAX($E$45,H44*H45) -> 2459.418 | I46: =MAX($E$45,I44*I45) -> 2734.4329 | J46: =MAX($E$45,J44*J45) -> 3085.4827 | K46: =MAX($E$45,K44*K45) -> 3551.871 | L46: =MAX($E$45,L44*L45) -> 3893.3847 | M46: =MAX($E$45,M44*M45) -> 3940.2084 | N46: =MAX($E$45,N44*N45) -> 4077.3392 | O46: =MAX($E$45,O44*O45) -> 4278.3914 | ... AA46: =MAX($E$45,AA44*AA45) -> 10130.884
B48: IRR Calc Below:
C49: Cash Flow | D49: mult.
B50: =+INPUTS!E32/10^3*$D$50 -> 36.835 | C50: Capex | D50: 1 | E50: =SUM(G50:AA50) -> -36835 | G50: =-B50*85%*10^3 -> -31309.75 | H50: =-B50*10^3-G50 -> -5525.25
C51: (+) EBITDA | E51: =SUM(G51:AA51) -> 98543.325 | H51: =+H31-SUM(H38,H46) -> 4335.857 | I51: =+I31-SUM(I38,I46) -> 4388.3842 | J51: =+J31-SUM(J38,J46) -> 4470.8892 | K51: =+K31-SUM(K38,K46) -> 4600.1026 | L51: =+L31-SUM(L38,L46) -> 4672.9566 | M51: =+M31-SUM(M38,M46) -> 4616.5485 | N51: =+N31-SUM(N38,N46) -> 4595.7464 | O51: =+O31-SUM(O38,O46) -> 4599.1057 | ... AA51: =+AA31-SUM(AA38,AA46) -> 5801.9995
...

Sheet Table1
E2: Generic | F2: Case 1 | G2: Case 4
C3: RNG Production | E3: 300 | F3: 330 | G3: 405.4 | P3: From | Q3: To | R3: City % | S3: Burnham %
C4: RIN Price | E4: 2.29 | F4: =+F5/11.727 -> 2.5181206 | G4: 2.82 | O4: 90% MWS Share | P4: =+Q5+1 -> #REF! | R4: 0.9 | S4: =1-R4 -> 0.1
C5: RIN EA | E5: =E4*11.727 -> 26.85483 | F5: 29.53 | G5: =G4*11.727 -> 33.07014 | O5: 70% MWS Share | P5: =Q6+1 -> 5899.75 | Q5: =+Model!#REF! -> #REF! | R5: 0.7 | S5: =1-R5 -> 0.3
C6: Nat Gas | E6: 3.3 | F6: 3.3 | G6: 5.13 | O6: Fixed Royalty to MWS | P6: =Q7+1 -> 4898.75 | Q6: =+P6+INPUTS!$E$26 -> 5898.75 | R6: 1 | S6: =1-R6 -> 0
C7: Brokerage | E7: =-20%*E5 -> -5.370966 | F7: =-20%*F5 -> -5.906 | G7: =-20%*G5 -> -6.614028 | O7: Burnham Allow. (Capex and OMM) | P7: 0 | Q7: =-SUM(Model!H42:H44) -> 4897.75 | R7: 0 | S7: =1-R7 -> 1
C8: Offtake Revenue | E8: =SUM(E5:E7)*E3 -> 7435.1592 | F8: =SUM(F5:F7)*F3 -> 8884.92 | G8: =SUM(G5:G7)*G3 -> 12805.01
H9: Annual Revenue Sharing ($K) | Z9: 20-Yr RNG Production, K MMBtu
Z10: =+Model!O90 -> 7294.5 | AA10: =+Model!P90 -> 8105 | AB10: =+Model!Q90 -> 8915.5 | AC10: =+Model!R90 -> 9939.5155
I11: Annual RNG Production, K MMBtu | Y11: =+Model!M92 -> 0 | Z11: =+Model!O92 -> 81.415722 | AA11: =+Model!P92 -> 98.148792 | AB11: =+Model!Q92 -> 114.88186 | AC11: =+Model!R92 -> 136.02304
H12: =MAX(2000,E8) -> 7435.1592 | I12: 175 | J12: =I12+25 -> 200 | K12: =J12+25 -> 225 | L12: =K12+25 -> 250 | M12: =L12+25 -> 275 | N12: =M12+25 -> 300 | O12: =N12+25 -> 325 | P12: =O12+25 -> 350 | Q12: =P12+25 -> 375 | ... V12: =U12+25 -> 500 | Y12: =+Model!M93 -> 0 | Z12: =+Model!O93 -> 93.70334 | AA12: =+Model!P93 -> 111.81388 | AB12: =+Model!Q93 -> 129.92441 | AC12: =+Model!R93 -> 152.80593
G13: EA, $/RIN | H13: 1.6 | I13: 3204.348 | J13: 3662.112 | K13: 4119.876 | L13: 4577.64 | M13: 5035.404 | N13: 5493.168 | O13: 5950.932 | P13: 6408.696 | Q13: 6866.46 | R13: 7324.224 | S13: 7781.988 | T13: 8239.752 | U13: 8697.516 | V13: 9155.28 | Y13: =+Model!M94 -> 0 | Z13: =+Model!O94 -> 105.82832 | AA13: =+Model!P94 -> 125.28608 | AB13: =+Model!Q94 -> 144.74383 | AC13: =+Model!R94 -> 169.32748
H14: =H13+0.1 -> 1.7 | I14: 3368.526 | J14: 3849.744 | K14: 4330.962 | L14: 4812.18 | M14: 5293.398 | N14: 5774.616 | O14: 6255.834 | P14: 6737.052 | Q14: 7218.27 | R14: 7699.488 | S14: 8180.706 | T14: 8661.924 | U14: 9143.142 | V14: 9624.36 | Y14: =+Model!M95 -> 0 | Z14: =+Model!O95 -> 117.9533 | AA14: =+Model!P95 -> 138.75828 | AB14: =+Model!Q95 -> 159.56325 | AC14: =+Model!R95 -> 185.84903
H15: =H14+0.1 -> 1.8 | I15: 3532.704 | J15: 4037.376 | K15: 4542.048 | L15: 5046.72 | M15: 5551.392 | N15: 6056.064 | O15: 6560.736 | P15: 7065.408 | Q15: 7570.08 | R15: 8074.752 | S15: 8579.424 | T15: 9084.096 | U15: 9588.768 | V15: 10093.44 | Y15: =+Model!M96 -> 0 | Z15: =+Model!O96 -> 128.6404 | AA15: =+Model!P96 -> 150.63283 | AB15: =+Model!Q96 -> 172.62526 | AC15: =+Model!R96 -> 200.41131
H16: =H15+0.1 -> 1.9 | I16: 3696.882 | J16: 4225.008 | K16: 4753.134 | L16: 5281.26 | M16: 5809.386 | N16: 6337.512 | O16: 6865.638 | P16: 7393.764 | Q16: 7921.89 | R16: 8450.016 | S16: 8978.142 | T16: 9506.268 | U16: 10034.394 | V16: 10562.52 | Y16: =+Model!M97 -> 0 | Z16: =+Model!O97 -> 142.20326 | AA16: =+Model!P97 -> 165.70268 | AB16: =+Model!Q97 -> 189.20209 | AC16: =+Model!R97 -> 218.89212
H17: =H16+0.1 -> 2 | I17: 3861.06 | J17: 4412.64 | K17: 4964.22 | L17: 5515.8 | M17: 6067.38 | N17: 6618.96 | O17: 7170.54 | P17: 7722.12 | Q17: 8273.7 | R17: 8825.28 | S17: 9376.86 | T17: 9928.44 | U17: 10480.02 | V17: 11031.6
H18: =H17+0.1 -> 2.1 | I18: 4025.238 | J18: 4600.272 | K18: 5175.306 | L18: 5750.34 | M18: 6325.374 | N18: 6900.408 | O18: 7475.442 | P18: 8050.476 | Q18: 8625.51 | R18: 9200.544 | S18: 9775.578 | T18: 10350.612 | U18: 10925.646 | V18: 11500.68
H19: =H18+0.1 -> 2.2 | I19: 4189.416 | J19: 4787.904 | K19: 5386.392 | L19: 5984.88 | M19: 6583.368 | N19: 7181.856 | O19: 7780.344 | P19: 8378.832 | Q19: 8977.32 | R19: 9575.808 | S19: 10174.296 | T19: 10772.784 | U19: 11371.272 | V19: 11969.76 | AA19: =+AA13/20 -> 6.2643038
H20: =H19+0.1 -> 2.3 | I20: 4353.594 | J20: 4975.536 | K20: 5597.478 | L20: 6219.42 | M20: 6841.362 | N20: 7463.304 | O20: 8085.246 | P20: 8707.188 | Q20: 9329.13 | R20: 9951.072 | S20: 10573.014 | T20: 11194.956 | U20: 11816.898 | V20: 12438.84
H21: =H20+0.1 -> 2.4 | I21: 4517.772 | J21: 5163.168 | K21: 5808.564 | L21: 6453.96 | M21: 7099.356 | N21: 7744.752 | O21: 8390.148 | P21: 9035.544 | Q21: 9680.94 | R21: 10326.336 | S21: 10971.732 | T21: 11617.128 | U21: 12262.524 | V21: 12907.92
H22: =H21+0.1 -> 2.5 | I22: 4681.95 | J22: 5350.8 | K22: 6019.65 | L22: 6688.5 | M22: 7357.35 | N22: 8026.2 | O22: 8695.05 | P22: 9363.9 | Q22: 10032.75 | R22: 10701.6 | S22: 11370.45 | T22: 12039.3 | U22: 12708.15 | V22: 13377
H23: =H22+0.1 -> 2.6 | I23: 4846.128 | J23: 5538.432 | K23: 6230.736 | L23: 6923.04 | M23: 7615.344 | N23: 8307.648 | O23: 8999.952 | P23: 9692.256 | Q23: 10384.56 | R23: 11076.864 | S23: 11769.168 | T23: 12461.472 | U23: 13153.776 | V23: 13846.08
H24: =H23+0.1 -> 2.7 | I24: 5010.306 | J24: 5726.064 | K24: 6441.822 | L24: 7157.58 | M24: 7873.338 | N24: 8589.096 | O24: 9304.854 | P24: 10020.612 | Q24: 10736.37 | R24: 11452.128 | S24: 12167.886 | T24: 12883.644 | U24: 13599.402 | V24: 14315.16
H25: =H24+0.1 -> 2.8 | I25: 5174.484 | J25: 5913.696 | K25: 6652.908 | L25: 7392.12 | M25: 8131.332 | N25: 8870.544 | O25: 9609.756 | P25: 10348.968 | Q25: 11088.18 | R25: 11827.392 | S25: 12566.604 | T25: 13305.816 | U25: 14045.028 | V25: 14784.24
H26: =H25+0.1 -> 2.9 | I26: 5338.662 | J26: 6101.328 | K26: 6863.994 | L26: 7626.66 | M26: 8389.326 | N26: 9151.992 | O26: 9914.658 | P26: 10677.324 | Q26: 11439.99 | R26: 12202.656 | S26: 12965.322 | T26: 13727.988 | U26: 14490.654 | V26: 15253.32
H27: =H26+0.1 -> 3 | I27: 5502.84 | J27: 6288.96 | K27: 7075.08 | L27: 7861.2 | M27: 8647.32 | N27: 9433.44 | O27: 10219.56 | P27: 11005.68 | Q27: 11791.8 | R27: 12577.92 | S27: 13364.04 | T27: 14150.16 | U27: 14936.28 | V27: 15722.4
H28: =H27+0.1 -> 3.1 | I28: 5667.018 | J28: 6476.592 | K28: 7286.166 | L28: 8095.74 | M28: 8905.314 | N28: 9714.888 | O28: 10524.462 | P28: 11334.036 | Q28: 12143.61 | R28: 12953.184 | S28: 13762.758 | T28: 14572.332 | U28: 15381.906 | V28: 16191.48
H29: =H28+0.1 -> 3.2 | I29: 5831.196 | J29: 6664.224 | K29: 7497.252 | L29: 8330.28 | M29: 9163.308 | N29: 9996.336 | O29: 10829.364 | P29: 11662.392 | Q29: 12495.42 | R29: 13328.448 | S29: 14161.476 | T29: 14994.504 | U29: 15827.532 | V29: 16660.56
H30: =H29+0.1 -> 3.3 | I30: 5995.374 | J30: 6851.856 | K30: 7708.338 | L30: 8564.82 | M30: 9421.302 | N30: 10277.784 | O30: 11134.266 | P30: 11990.748 | Q30: 12847.23 | R30: 13703.712 | S30: 14560.194 | T30: 15416.676 | U30: 16273.158 | V30: 17129.64
H31: =H30+0.1 -> 3.4 | I31: 6159.552 | J31: 7039.488 | K31: 7919.424 | L31: 8799.36 | M31: 9679.296 | N31: 10559.232 | O31: 11439.168 | P31: 12319.104 | Q31: 13199.04 | R31: 14078.976 | S31: 14958.912 | T31: 15838.848 | U31: 16718.784 | V31: 17598.72
... H33: =H32+0.1 -> 3.6 | I33: 6487.908 | J33: 7414.752 | K33: 8341.596 | L33: 9268.44 | M33: 10195.284 | N33: 11122.128 | O33: 12048.972 | P33: 12975.816 | Q33: 13902.66 | R33: 14829.504 | S33: 15756.348 | T33: 16683.192 | U33: 17610.036 | V33: 18536.88
E42: Royalty Calculation ($ in '000) | H42: {=_xlfn.SEQUENCE(1,20,1,1)} -> 1 | I42: 2 | J42: 3 | K42: 4 | L42: 5 | M42: 6 | N42: 7 | O42: 8 | P42: 9 | Q42: 10 | R42: 11 | S42: 12 | T42: 13 | U42: 14 | V42: 15 | W42: 16 | X42: 17 | Y42: 18 | Z42: 19 | AA42: 20 | AB42: TOTAL
E44: Biogas, scfm | H44: =+Model!H11 -> 950 | I44: =+Model!I11 -> 973.123 | J44: =+Model!J11 -> 996.80881 | K44: =+Model!K11 -> 1021.0711 | L44: =+Model!L11 -> 1045.924 | M44: =+Model!M11 -> 1071.3818 | N44: =+Model!N11 -> 1097.4592 | O44: =+Model!O11 -> 1124.1714 | ... AA44: =+Model!AA11 -> 1500.2447 | AB44: =AVERAGE(H44:AA44) -> 1205.3424
E45: RNG Production, K MMBtu | H45: =+Model!H17/1000 -> 319.40093 | I45: =+Model!I17/1000 -> 327.17515 | J45: =+Model!J17/1000 -> 335.13859 | K45: =+Model!K17/1000 -> 343.29587 | L45: =+Model!L17/1000 -> 351.65169 | M45: =+Model!M17/1000 -> 360.21089 | N45: =+Model!N17/1000 -> 368.97842 | O45: =+Model!O17/1000 -> 377.95936 | ... AA45: =+Model!AA17/1000 -> 504.39955 | AB45: =SUM(H45:AA45) -> 8105
E46: D3 RIN Price, $/RIN | H46: =+Model!H20 -> 2.6619581 | I46: =+Model!I20 -> 2.7118204 | J46: =+Model!J20 -> 2.7914813 | K46: =+Model!K20 -> 2.9160811 | L46: =+Model!L20 -> 2.9781765 | M46: =+Model!M20 -> 2.9101359 | N46: =+Model!N20 -> 2.8799224 | O46: =+Model!O20 -> 2.8742294 | ... AA46: =+Model!AA20 -> 3.6777758 | AB46: =AVERAGE(H46:AA46) -> 3.1120546
E48: EA RIN Sale | H48: =+Model!H28/1000 -> 9.9706695 | I48: =+Model!I28/1000 -> 10.404666 | J48: =+Model!J28/1000 -> 10.970997 | K48: =+Model!K28/1000 -> 11.739648 | L48: =+Model!L28/1000 -> 12.281462 | M48: =+Model!M28/1000 -> 12.292976 | N48: =+Model!N28/1000 -> 12.461453 | O48: =+Model!O28/1000 -> 12.739531 | ... AA48: =+Model!AA28/1000 -> 21.754387 | AB48: =SUM(H48:AA48) -> 299.56481
E49: (-) RIN Managament | H49: =+Model!H29/1000 -> -1.9941339 | I49: =+Model!I29/1000 -> -2.0809333 | J49: =+Model!J29/1000 -> -2.1941993 | K49: =+Model!K29/1000 -> -2.3479297 | L49: =+Model!L29/1000 -> -2.4562924 | M49: =+Model!M29/1000 -> -2.4585952 | N49: =+Model!N29/1000 -> -2.4922906 | O49: =+Model!O29/1000 -> -2.5479062 | ... AA49: =+Model!AA29/1000 -> -4.3508775 | AB49: =SUM(H49:AA49) -> -59.912961
E50: (+) Nat. Gas Sale | H50: =+Model!H30/1000 -> 1.0648827 | I50: =+Model!I30/1000 -> 1.0695356 | J50: =+Model!J30/1000 -> 1.1258897 | K50: =+Model!K30/1000 -> 1.1851301 | L50: =+Model!L30/1000 -> 1.2474025 | M50: =+Model!M30/1000 -> 1.3128602 | N50: =+Model!N30/1000 -> 1.3816642 | O50: =+Model!O30/1000 -> 1.4539834 | ... AA50: =+Model!AA30/1000 -> 2.6704954 | AB50: =SUM(H50:AA50) -> 34.481019
E51: =+Model!C41 -> Offtake Revenue, net of brokerage | H51: =+Model!H41/10^3 -> 9.0414183 | I51: =+Model!I41/10^3 -> 9.3932687 | J51: =+Model!J41/10^3 -> 9.9026871 | K51: =+Model!K41/10^3 -> 10.576849 | L51: =+Model!L41/10^3 -> 11.072572 | M51: =+Model!M41/10^3 -> 11.147241 | N51: =+Model!N41/10^3 -> 11.350826 | O51: =+Model!O41/10^3 -> 11.645608 | ... AA51: =+Model!AA41/10^3 -> 20.074005 | AB51: =SUM(H51:AA51) -> 274.13286
E52: =+Model!C42 -> (-) Capex Allowance | H52: =+Model!H42/10^3 -> -1.84175 | I52: =+Model!I42/10^3 -> -1.84175 | J52: =+Model!J42/10^3 -> -1.84175 | K52: =+Model!K42/10^3 -> -1.84175 | L52: =+Model!L42/10^3 -> -1.84175 | M52: =+Model!M42/10^3 -> -1.84175 | N52: =+Model!N42/10^3 -> -1.84175 | O52: =+Model!O42/10^3 -> -1.84175 | ... AA52: =+Model!AA42/10^3 -> -1.84175 | AB52: =SUM(H52:AA52) -> -36.835
...

Sheet data-->

Sheet Bid Forms
B1: Revised Bid Form - NOT OUR PROPOSAL | H1: Original Bid Form
B3: Company Name: | D3: Burnham RNG, LLC
B4: Line Item Number | C4: Description | E4: Unit | F4: Extended amount
B5: 1 | C5: 20- year Evaluative Value of the sale of RNG and EAs | D5: 219100000 | E5: $ | F5: =D5 -> 219100000 | I5: =170.5/0.8 -> 213.125
B6: 2 | C6: Capital Cost Allowance | D6: =+INPUTS!S24*1000 -> 36835000 | E6: $ | F6: =D6 -> 36835000
B7: 3 | C7: Capital Cost Financing Fee | D7: 0 | E7: % | F7: =D6*D7 -> 0
B8: 4 | C8: 20-year Allowance for Operations and Maintenance | D8: =+ROUND(SUM(INPUTS!S25:S26)/100,0)*10^5-F7 -> 65500000 | E8: $ | F8: =D8 -> 65500000
B9: 5 | C9: 20-year Allowance for RIN Management | D9: 0.2 | E9: % | F9: =F5*D9 -> 43820000
B10: 6 | C10: 20 year Evaluative Net Proceeds | D10: =D5-F6-F7-F8-F9 -> 72945000 | E10: $ | F10: =D10 -> 72945000
B11: 7 | C11: Percentage of Net Proceeds offered for Royalty Payments | D11: =+D12/D10 -> #REF! | E11: % | F11: =F10*D11 -> #REF!
B12: 8 | C12: 20-year value of Fixed Royalty Payments | D12: =+ROUND(Model!#REF!/100,0)*10^5 -> #REF! | E12: $ | F12: 40000000
B13: 9 | C13: 20-year value of Variable Royalty Payment (cannot be less than zero). | F13: =IF((F10*D11-F12)<0,0,(F10*D11-F12)) -> #REF!
B14: Total Evaluative Contract Value to Metro Water Services | E14: =F12+F13 -> #REF!
B15: This form is for evaluation of proposals. Actual Variable Royalty Payment will be determined using actual Capital Cost, Actual O&M Cost, actual Third Party Fees, and actual value of sales of RNG and Environment Attributes.
B16: Basis for 20 year evaluative value. These amounts are for evaluative purposes only and are not guaranteed by MWS nor Burnham RNG, LLC. 6,605,287 DTH of Biogas. 850 cfm year 0 increasing 2.5%/year upto 1,500 cfm year 20 600 BTU/CF Biogas 90% uptime of RNG Facility 97% capture of Methane by RNG Facility $2.39/rin year 0 and escalated 1% per year $3.20/DTH less $1.00/DTH wheel tax year 0. Methane value escalated at 3%/year.
B21: Company Name: | D21: Burnham RNG, LLC
B22: Line Item Number | C22: Description | E22: Unit | F22: Extended amount
B23: 1 | C23: 20- year Evaluative Value of the sale of RNG and EAs | D23: 219100000 | E23: $ | F23: =D23 -> 219100000 | I23: RIN EA | J23: =+Model!E28 -> 299564.81
B24: 2 | C24: Capital Cost Allowance | D24: =+D6 -> 36835000 | E24: $ | F24: =D24 -> 36835000 | I24: Nat. Gas | J24: =+Model!E30 -> 34481.019
B25: 3 | C25: Capital Cost Financing Fee | D25: 0.25 | E25: % | F25: =D24*D25 -> 9208750 | I25: RIN Brokerage | J25: =0.2*J23 -> 59912.961
B26: 4 | C26: 20-year Allowance for Operations and Maintenance | D26: =61120000-F25 -> 51911250 | E26: $ | F26: =D26 -> 51911250 | H26: =+F26/1000 -> 51911.25
B27: 5 | C27: 20-year Allowance for RIN Management | D27: 0.2 | E27: % | F27: =+J25*1000 -> 59912961
B28: 6 | C28: 20 year Evaluative Net Proceeds | D28: =D23-F24-F25-F26-F27 -> 61232039 | E28: $ | F28: =D28 -> 61232039
B29: 7 | C29: Percentage of Net Proceeds offered for Royalty Payments | D29: 0.7 | E29: % | F29: =F28*D29 -> 42862427
B30: 8 | C30: 20-year value of Fixed Royalty Payments | D30: =+D28*D29 -> 42862427 | E30: $ | F30: 40000000
B31: 9 | C31: 20-year value of Variable Royalty Payment ( > 0 ) | F31: =IF((F28*D29-F30)<0,0,(F28*D29-F30)) -> 2862427.1
B32: Total Evaluative Contract Value to Metro Water Services | E32: =F30+F31 -> 42862427
